Workbook

Sheet IPD Patient & Services
A1: Patient ID | B1: Encounter ID | C1: Patient Name | D1: DOB | E1: Gender | F1: Payer | G1: Member ID | H1: Admission Date | I1: Admission Time | J1: Discharge Date | K1: Discharge Time | L1: Length of Stay (Days) | M1: Admission Type | N1: Patient Class | O1: Facility | P1: Unit / Ward | Q1: Room / Bed | R1: Attending Provider | S1: Primary ICD-10-CM | T1: Primary Diagnosis | U1: Secondary ICD-10-CM | V1: MS-DRG | W1: MS-DRG Description | X1: Present on Admission | Y1: Discharge Disposition | Z1: Services / Facilities Used | AA1: Key CPT / HCPCS | AB1: Allergies | AC1: Prior Authorization | AD1: Estimated Total Charges ($) | AE1: Data Status
A2: IPD-0001 | B2: ENC-IP-2026-00001 | C2: Olivia Carter | D2: 19929 | E2: Female | F2: Aetna Commercial | G2: MBR69539580 | H2: 46026 | I2: 08:30 | J2: 46031 | K2: 14:15 | L2: 5 | M2: Emergency | N2: Inpatient | O2: NuuCare Demo Medical Center | P2: Medical Ward | Q2: MED-101B | R2: Dr. Amelia Rhodes | S2: J18.9 | T2: Pneumonia, unspecified organism | U2: I10 | V2: 193 | W2: Simple pneumonia & pleurisy w MCC | X2: Y | Y2: Home | Z2: Medical Ward; Chest X-ray; respiratory therapy; CBC; CMP; blood culture; pharmacy; room and board; physician services | AA2: 99223; 99233; 71046; 94640 | AB2: Penicillin | AC2: Not Required - Emergency | AD2: =SUMIF('IPD Charge Lines'!$C:$C,B2,'IPD Charge Lines'!$P:$P) -> 8241.6 | AE2: SYNTHETIC DEMO DATA
A3: IPD-0002 | B3: ENC-IP-2026-00002 | C3: Liam Brooks | D3: 25816 | E3: Male | F3: Blue Cross PPO | G3: MBR80706871 | H3: 46034 | I3: 08:30 | J3: 46036 | K3: 14:15 | L3: 2 | M3: Emergency | N3: Inpatient | O3: NuuCare Demo Medical Center | P3: Telemetry | Q3: TEL-102C | R3: Dr. Noah Patel | S3: I50.23 | T3: Acute on chronic systolic heart failure | U3: E78.5 | V3: 291 | W3: Heart failure & shock w MCC | X3: Y | Y3: Home with Home Health | Z3: Telemetry; Telemetry; echocardiogram; ECG; BNP; chest X-ray; pharmacy; room and board; physician services | AA3: 99223; 99233; 93306; 93010 | AB3: Sulfa drugs | AC3: Not Required - Emergency | AD3: =SUMIF('IPD Charge Lines'!$C:$C,B3,'IPD Charge Lines'!$P:$P) -> 5120.5 | AE3: SYNTHETIC DEMO DATA
A4: IPD-0003 | B4: ENC-IP-2026-00003 | C4: Emma Bennett | D4: 35657 | E4: Female | F4: UnitedHealthcare | G4: MBR63240335 | H4: 46042 | I4: 08:30 | J4: 46047 | K4: 14:15 | L4: 5 | M4: Emergency | N4: Inpatient | O4: NuuCare Demo Medical Center | P4: Surgical Ward | Q4: SUR-103A | R4: Dr. Ethan Clarke | S4: K35.80 | T4: Unspecified acute appendicitis | U4: E78.5 | V4: 343 | W4: Appendectomy w/o complicated principal dx w/o CC/MCC | X4: Y | Y4: Skilled Nursing Facility | Z4: Surgical Ward; Laparoscopic appendectomy; anesthesia; CBC; CT abdomen; pharmacy; room and board; physician services | AA4: 99223; 44970; 00840 | AB4: Latex | AC4: Not Required - Emergency | AD4: =SUMIF('IPD Charge Lines'!$C:$C,B4,'IPD Charge Lines'!$P:$P) -> 19400 | AE4: SYNTHETIC DEMO DATA
A5: IPD-0004 | B5: ENC-IP-2026-00004 | C5: Noah Reed | D5: 22830 | E5: Male | F5: Medicare | G5: MBR17999608 | H5: 46050 | I5: 08:30 | J5: 46056 | K5: 14:15 | L5: 6 | M5: Emergency | N5: Inpatient | O5: NuuCare Demo Medical Center | P5: Medical Ward | Q5: MED-104B | R5: Dr. Sophia Miller | S5: N39.0 | T5: Urinary tract infection, site not specified | U5: J45.909 | V5: 689 | W5: Kidney & urinary tract infections w MCC | X5: Y | Y5: Inpatient Rehabilitation | Z5: Medical Ward; Urine culture; CBC; CMP; IV antibiotics; pharmacy; room and board; physician services | AA5: 99223; 99233; 87086; 85025 | AB5: NSAIDs | AC5: Not Required - Emergency | AD5: =SUMIF('IPD Charge Lines'!$C:$C,B5,'IPD Charge Lines'!$P:$P) -> 10587.6 | AE5: SYNTHETIC DEMO DATA
A6: IPD-0005 | B6: ENC-IP-2026-00005 | C6: Ava Parker | D6: 37628 | E6: Female | F6: Medicaid | G6: MBR52841958 | H6: 46058 | I6: 08:30 | J6: 46061 | K6: 14:15 | L6: 3 | M6: Elective | N6: Inpatient | O6: NuuCare Demo Medical Center | P6: Orthopedic Ward | Q6: ORT-105C | R6: Dr. Liam Wilson | S6: M17.11 | T6: Unilateral primary osteoarthritis, right knee | U6: N18.3 | V6: 470 | W6: Major hip & knee joint replacement w/o MCC | X6: N | Y6: Transfer to Acute Facility | Z6: Orthopedic Ward; Total knee arthroplasty; anesthesia; X-ray; physical therapy; pharmacy; room and board; physician services | AA6: 27447; 01402; 73560; 97116 | AB6: NKDA | AC6: Required - Approved | AD6: =SUMIF('IPD Charge Lines'!$C:$C,B6,'IPD Charge Lines'!$P:$P) -> 16489.2 | AE6: SYNTHETIC DEMO DATA
A7: IPD-0006 | B7: ENC-IP-2026-00006 | C7: Ethan Hayes | D7: 23145 | E7: Male | F7: Cigna Commercial | G7: MBR97059111 | H7: 46066 | I7: 08:30 | J7: 46071 | K7: 14:15 | L7: 5 | M7: Emergency | N7: Inpatient | O7: NuuCare Demo Medical Center | P7: Cardiac ICU | Q7: CAR-106A | R7: Dr. Mia Reynolds | S7: I21.4 | T7: Non-ST elevation myocardial infarction | U7: D64.9 | V7: 280 | W7: Acute myocardial infarction, discharged alive w MCC | X7: Y | Y7: Home | Z7: Cardiac ICU; Cardiac catheterization; coronary stent; ECG; troponin; ICU monitoring; pharmacy; room and board; physician services | AA7: 99223; 93458; 92928; 93010 | AB7: Penicillin | AC7: Not Required - Emergency | AD7: =SUMIF('IPD Charge Lines'!$C:$C,B7,'IPD Charge Lines'!$P:$P) -> 36029.4 | AE7: SYNTHETIC DEMO DATA
A8: IPD-0007 | B8: ENC-IP-2026-00007 | C8: Sophia Collins | D8: 34711 | E8: Female | F8: Self-Pay | G8: MBR12085708 | H8: 46074 | I8: 08:30 | J8: 46082 | K8: 14:15 | L8: 8 | M8: Urgent | N8: Inpatient | O8: NuuCare Demo Medical Center | P8: Medical Ward | Q8: MED-107B | R8: Dr. Amelia Rhodes | S8: E11.621 | T8: Type 2 diabetes mellitus with foot ulcer | U8: E11.9 | V8: 638 | W8: Diabetes w CC | X8: Y | Y8: Home with Home Health | Z8: Medical Ward; Wound debridement; vascular study; HbA1c; wound care; pharmacy; room and board; physician services | AA8: 99223; 97597; 93922; 83036 | AB8: Sulfa drugs | AC8: Pending Review | AD8: =SUMIF('IPD Charge Lines'!$C:$C,B8,'IPD Charge Lines'!$P:$P) -> 11082.6 | AE8: SYNTHETIC DEMO DATA
A9: IPD-0008 | B9: ENC-IP-2026-00008 | C9: Mason Morgan | D9: 31917 | E9: Male | F9: Aetna Commercial | G9: MBR87609287 | H9: 46082 | I9: 08:30 | J9: 46090 | K9: 14:15 | L9: 8 | M9: Emergency | N9: Inpatient | O9: NuuCare Demo Medical Center | P9: Orthopedic Ward | Q9: ORT-108C | R9: Dr. Noah Patel | S9: S72.001A | T9: Fracture of unspecified part of neck of right femur | V9: 480 | W9: Hip & femur procedures except major joint w MCC | X9: Y | Y9: Skilled Nursing Facility | Z9: Orthopedic Ward; Hip fixation; anesthesia; X-ray; physical therapy; pharmacy; room and board; physician services | AA9: 27236; 01210; 73502; 97116 | AB9: Latex | AC9: Not Required - Emergency | AD9: =SUMIF('IPD Charge Lines'!$C:$C,B9,'IPD Charge Lines'!$P:$P) -> 23452.8 | AE9: SYNTHETIC DEMO DATA
A10: IPD-0009 | B10: ENC-IP-2026-00009 | C10: Isabella Cooper | D10: 29395 | E10: Female | F10: Blue Cross PPO | G10: MBR92538679 | H10: 46090 | I10: 08:30 | J10: 46095 | K10: 14:15 | L10: 5 | M10: Emergency | N10: Inpatient | O10: NuuCare Demo Medical Center | P10: Surgical Ward | Q10: SUR-109A | R10: Dr. Ethan Clarke | S10: K80.00 | T10: Calculus of gallbladder with acute cholecystitis without obstruction | U10: Z79.4 | V10: 418 | W10: Laparoscopic cholecystectomy w/o CDE w CC | X10: Y | Y10: Inpatient Rehabilitation | Z10: Surgical Ward; Laparoscopic cholecystectomy; anesthesia; ultrasound; CMP; pharmacy; room and board; physician services | AA10: 47562; 00790; 76705; 80053 | AB10: NSAIDs | AC10: Not Required - Emergency | AD10: =SUMIF('IPD Charge Lines'!$C:$C,B10,'IPD Charge Lines'!$P:$P) -> 18012.4 | AE10: SYNTHETIC DEMO DATA
A11: IPD-0010 | B11: ENC-IP-2026-00010 | C11: Lucas Foster | D11: 29776 | E11: Male | F11: UnitedHealthcare | G11: MBR56032838 | H11: 46098 | I11: 08:30 | J11: 46101 | K11: 14:15 | L11: 3 | M11: Emergency | N11: Inpatient | O11: NuuCare Demo Medical Center | P11: Pulmonary Ward | Q11: PUL-110B | R11: Dr. Sophia Miller | S11: J44.1 | T11: Chronic obstructive pulmonary disease with acute exacerbation | U11: D64.9 | V11: 190 | W11: COPD w MCC | X11: N | Y11: Transfer to Acute Facility | Z11: Pulmonary Ward; Nebulization; oxygen; chest X-ray; ABG; respiratory therapy; pharmacy; room and board; physician services | AA11: 99223; 99233; 94640; 71046 | AB11: NKDA | AC11: Not Required - Emergency | AD11: =SUMIF('IPD Charge Lines'!$C:$C,B11,'IPD Charge Lines'!$P:$P) -> 5805 | AE11: SYNTHETIC DEMO DATA
A12: IPD-0011 | B12: ENC-IP-2026-00011 | C12: Mia Bailey | D12: 29117 | E12: Female | F12: Medicare | G12: MBR32619500 | H12: 46106 | I12: 08:30 | J12: 46113 | K12: 14:15 | L12: 7 | M12: Emergency | N12: Inpatient | O12: NuuCare Demo Medical Center | P12: Medical ICU | Q12: MED-111C | R12: Dr. Liam Wilson | S12: A41.9 | T12: Sepsis, unspecified organism | U12: Z79.4 | V12: 871 | W12: Septicemia or severe sepsis w/o MV >96 hours w MCC | X12: Y | Y12: Home | Z12: Medical ICU; ICU care; blood culture; lactate; broad-spectrum antibiotics; pharmacy; room and board; physician services | AA12: 99223; 99291; 87040; 83605 | AB12: Penicillin | AC12: Not Required - Emergency | AD12: =SUMIF('IPD Charge Lines'!$C:$C,B12,'IPD Charge Lines'!$P:$P) -> 30023.7 | AE12: SYNTHETIC DEMO DATA
A13: IPD-0012 | B13: ENC-IP-2026-00012 | C13: Logan Ward | D13: 26551 | E13: Male | F13: Medicaid | G13: MBR28371920 | H13: 46114 | I13: 08:30 | J13: 46121 | K13: 14:15 | L13: 7 | M13: Emergency | N13: Inpatient | O13: NuuCare Demo Medical Center | P13: Neuro ICU | Q13: NEU-112A | R13: Dr. Mia Reynolds | S13: I63.9 | T13: Cerebral infarction, unspecified | U13: N18.3 | V13: 064 | W13: Intracranial hemorrhage or cerebral infarction w MCC | X13: Y | Y13: Home with Home Health | Z13: Neuro ICU; CT head; MRI brain; rehabilitation; swallow evaluation; pharmacy; room and board; physician services | AA13: 99223; 70450; 70551; 97110 | AB13: Sulfa drugs | AC13: Not Required - Emergency | AD13: =SUMIF('IPD Charge Lines'!$C:$C,B13,'IPD Charge Lines'!$P:$P) -> 36124.4 | AE13: SYNTHETIC DEMO DATA
A14: IPD-0013 | B14: ENC-IP-2026-00013 | C14: Amelia Murphy | D14: 21488 | E14: Female | F14: Cigna Commercial | G14: MBR29184914 | H14: 46122 | I14: 08:30 | J14: 46127 | K14: 14:15 | L14: 5 | M14: Emergency | N14: Inpatient | O14: NuuCare Demo Medical Center | P14: Medical Ward | Q14: MED-113B | R14: Dr. Amelia Rhodes | S14: N17.9 | T14: Acute kidney failure, unspecified | U14: I10 | V14: 682 | W14: Renal failure w MCC | X14: Y | Y14: Skilled Nursing Facility | Z14: Medical Ward; Hemodialysis; renal ultrasound; BMP; nephrology consult; pharmacy; room and board; physician services | AA14: 99223; 90935; 76770; 80048 | AB14: Latex | AC14: Not Required - Emergency | AD14: =SUMIF('IPD Charge Lines'!$C:$C,B14,'IPD Charge Lines'!$P:$P) -> 10297.9 | AE14: SYNTHETIC DEMO DATA
A15: IPD-0014 | B15: ENC-IP-2026-00014 | C15: James Price | D15: 37989 | E15: Male | F15: Self-Pay | G15: MBR49768414 | H15: 46130 | I15: 08:30 | J15: 46135 | K15: 14:15 | L15: 5 | M15: Emergency | N15: Inpatient | O15: NuuCare Demo Medical Center | P15: Medical Ward | Q15: MED-114C | R15: Dr. Noah Patel | S15: K92.2 | T15: Gastrointestinal hemorrhage, unspecified | U15: D64.9 | V15: 377 | W15: GI hemorrhage w MCC | X15: Y | Y15: Inpatient Rehabilitation | Z15: Medical Ward; Upper GI endoscopy; anesthesia; CBC; transfusion monitoring; pharmacy; room and board; physician services | AA15: 99223; 43235; 00731; 85027 | AB15: NSAIDs | AC15: Not Required - Emergency | AD15: =SUMIF('IPD Charge Lines'!$C:$C,B15,'IPD Charge Lines'!$P:$P) -> 8314.3 | AE15: SYNTHETIC DEMO DATA
A16: IPD-0015 | B16: ENC-IP-2026-00015 | C16: Harper Bell | D16: 24709 | E16: Female | F16: Aetna Commercial | G16: MBR90967101 | H16: 46138 | I16: 08:30 | J16: 46148 | K16: 14:15 | L16: 10 | M16: Emergency | N16: Inpatient | O16: NuuCare Demo Medical Center | P16: Medical ICU | Q16: MED-115A | R16: Dr. Ethan Clarke | S16: J96.01 | T16: Acute respiratory failure with hypoxia | U16: Z79.4 | V16: 189 | W16: Pulmonary edema & respiratory failure | X16: N | Y16: Transfer to Acute Facility | Z16: Medical ICU; ICU care; non-invasive ventilation; ABG; chest X-ray; pharmacy; room and board; physician services | AA16: 99223; 99291; 94660; 82803 | AB16: NKDA | AC16: Not Required - Emergency | AD16: =SUMIF('IPD Charge Lines'!$C:$C,B16,'IPD Charge Lines'!$P:$P) -> 39609.6 | AE16: SYNTHETIC DEMO DATA
A17: IPD-0016 | B17: ENC-IP-2026-00016 | C17: Benjamin Ross | D17: 36437 | E17: Male | F17: Blue Cross PPO | G17: MBR39471527 | H17: 46146 | I17: 08:30 | J17: 46152 | K17: 14:15 | L17: 6 | M17: Urgent | N17: Inpatient | O17: NuuCare Demo Medical Center | P17: Medical Ward | Q17: MED-116B | R17: Dr. Sophia Miller | S17: L03.116 | T17: Cellulitis of left lower limb | U17: D64.9 | V17: 603 | W17: Cellulitis w/o MCC | X17: Y | Y17: Home | Z17: Medical Ward; Venous ultrasound; CBC; IV antibiotics; wound assessment; pharmacy; room and board; physician services | AA17: 99223; 99233; 93971; 85025 | AB17: Penicillin | AC17: Pending Review | AD17: =SUMIF('IPD Charge Lines'!$C:$C,B17,'IPD Charge Lines'!$P:$P) -> 9172.8 | AE17: SYNTHETIC DEMO DATA
A18: IPD-0017 | B18: ENC-IP-2026-00017 | C18: Evelyn Gray | D18: 24776 | E18: Female | F18: UnitedHealthcare | G18: MBR96388296 | H18: 46154 | I18: 08:30 | J18: 46159 | K18: 14:15 | L18: 5 | M18: Emergency | N18: Inpatient | O18: NuuCare Demo Medical Center | P18: Neurology Ward | Q18: NEU-117C | R18: Dr. Liam Wilson | S18: G40.909 | T18: Epilepsy, unspecified, not intractable, without status epilepticus | U18: Z79.4 | V18: 101 | W18: Seizures w/o MCC | X18: Y | Y18: Home with Home Health | Z18: Neurology Ward; EEG; MRI brain; CMP; neurology consult; pharmacy; room and board; physician services | AA18: 99223; 95816; 70551; 80053 | AB18: Sulfa drugs | AC18: Not Required - Emergency | AD18: =SUMIF('IPD Charge Lines'!$C:$C,B18,'IPD Charge Lines'!$P:$P) -> 9875 | AE18: SYNTHETIC DEMO DATA
A19: IPD-0018 | B19: ENC-IP-2026-00018 | C19: Elijah Wood | D19: 35406 | E19: Female | F19: Medicare | G19: MBR54542871 | H19: 46162 | I19: 08:30 | J19: 46170 | K19: 14:15 | L19: 8 | M19: Elective | N19: Inpatient | O19: NuuCare Demo Medical Center | P19: Labor & Delivery | Q19: LAB-118A | R19: Dr. Mia Reynolds | S19: O80 | T19: Encounter for full-term uncomplicated delivery | V19: 775 | W19: Vaginal delivery w/o complicating diagnoses | X19: Y | Y19: Skilled Nursing Facility | Z19: Labor & Delivery; Vaginal delivery; epidural; fetal monitoring; CBC; pharmacy; room and board; physician services | AA19: 59400; 01967; 59025; 85027 | AB19: Latex | AC19: Required - Approved | AD19: =SUMIF('IPD Charge Lines'!$C:$C,B19,'IPD Charge Lines'!$P:$P) -> 16513.8 | AE19: SYNTHETIC DEMO DATA
A20: IPD-0019 | B20: ENC-IP-2026-00019 | C20: Abigail Hughes | D20: 45879 | E20: Female | F20: Medicaid | G20: MBR28555947 | H20: 46170 | I20: 08:30 | J20: 46175 | K20: 14:15 | L20: 5 | M20: Emergency | N20: Inpatient | O20: NuuCare Demo Medical Center | P20: NICU | Q20: NIC-119B | R20: Dr. Amelia Rhodes | S20: P07.30 | T20: Preterm newborn, unspecified weeks of gestation | U20: J45.909 | V20: 791 | W20: Prematurity w major problems | X20: Y | Y20: Inpatient Rehabilitation | Z20: NICU; NICU care; chest X-ray; ABG; CBC; feeding support; pharmacy; room and board; physician services | AA20: 99468; 71045; 82803; 85025 | AB20: NSAIDs | AC20: Not Required - Emergency | AD20: =SUMIF('IPD Charge Lines'!$C:$C,B20,'IPD Charge Lines'!$P:$P) -> 23540.4 | AE20: SYNTHETIC DEMO DATA
A21: IPD-0020 | B21: ENC-IP-2026-00020 | C21: Henry Kelly | D21: 20387 | E21: Male | F21: Cigna Commercial | G21: MBR73293796 | H21: 46178 | I21: 08:30 | J21: 46180 | K21: 14:15 | L21: 2 | M21: Urgent | N21: Inpatient | O21: NuuCare Demo Medical Center | P21: Behavioral Health | Q21: BEH-120C | R21: Dr. Noah Patel | S21: F32.2 | T21: Major depressive disorder, single episode, severe without psychotic features | U21: E78.5 | V21: 881 | W21: Depressive neuroses | X21: N | Y21: Transfer to Acute Facility | Z21: Behavioral Health; Psychiatric evaluation; psychotherapy; toxicology screen; safety monitoring; pharmacy; room and board; physician services | AA21: 99223; 90832; 90791; 80307 | AB21: NKDA | AC21: Pending Review | AD21: =SUMIF('IPD Charge Lines'!$C:$C,B21,'IPD Charge Lines'!$P:$P) -> 3784.2 | AE21: SYNTHETIC DEMO DATA
A22: IPD-0021 | B22: ENC-IP-2026-00021 | C22: Emily Sanders | D22: 37188 | E22: Female | F22: Self-Pay | G22: MBR41056801 | H22: 46186 | I22: 08:30 | J22: 46189 | K22: 14:15 | L22: 3 | M22: Emergency | N22: Inpatient | O22: NuuCare Demo Medical Center | P22: Surgical Ward | Q22: SUR-121A | R22: Dr. Ethan Clarke | S22: K56.609 | T22: Unspecified intestinal obstruction, unspecified whether partial or complete | U22: J45.909 | V22: 331 | W22: Major small & large bowel procedures w/o CC/MCC | X22: Y | Y22: Home | Z22: Surgical Ward; Bowel resection; anesthesia; CT abdomen/pelvis; CBC; pharmacy; room and board; physician services | AA22: 99223; 44120; 00790; 74177 | AB22: Penicillin | AC22: Not Required - Emergency | AD22: =SUMIF('IPD Charge Lines'!$C:$C,B22,'IPD Charge Lines'!$P:$P) -> 15735.6 | AE22: SYNTHETIC DEMO DATA
A23: IPD-0022 | B23: ENC-IP-2026-00022 | C23: Alexander Powell | D23: 26623 | E23: Male | F23: Aetna Commercial | G23: MBR85505095 | H23: 46194 | I23: 08:30 | J23: 46201 | K23: 14:15 | L23: 7 | M23: Urgent | N23: Observation-to-Inpatient | O23: NuuCare Demo Medical Center | P23: Telemetry | Q23: TEL-122B | R23: Dr. Sophia Miller | S23: I10 | T23: Essential (primary) hypertension | U23: Z79.4 | V23: 305 | W23: Hypertension w/o MCC | X23: Y | Y23: Home with Home Health | Z23: Telemetry; Telemetry; ECG; BMP; medication management; pharmacy; room and board; physician services | AA23: 99223; 99233; 93010; 80048 | AB23: Sulfa drugs | AC23: Pending Review | AD23: =SUMIF('IPD Charge Lines'!$C:$C,B23,'IPD Charge Lines'!$P:$P) -> 12912 | AE23: SYNTHETIC DEMO DATA
A24: IPD-0023 | B24: ENC-IP-2026-00023 | C24: Ella Long | D24: 35741 | E24: Female | F24: Blue Cross PPO | G24: MBR70774793 | H24: 46202 | I24: 08:30 | J24: 46205 | K24: 14:15 | L24: 3 | M24: Emergency | N24: Inpatient | O24: NuuCare Demo Medical Center | P24: Medical Ward | Q24: MED-123C | R24: Dr. Liam Wilson | S24: D57.00 | T24: Hb-SS disease with crisis, unspecified | V24: 812 | W24: Red blood cell disorders w/o MCC | X24: Y | Y24: Skilled Nursing Facility | Z24: Medical Ward; Pain management; reticulocyte count; IV hydration; CBC; pharmacy; room and board; physician services | AA24: 99223; 99233; 85045; 96374 | AB24: Latex | AC24: Not Required - Emergency | AD24: =SUMIF('IPD Charge Lines'!$C:$C,B24,'IPD Charge Lines'!$P:$P) -> 4718.7 | AE24: SYNTHETIC DEMO DATA
A25: IPD-0024 | B25: ENC-IP-2026-00024 | C25: Daniel Perry | D25: 35187 | E25: Male | F25: UnitedHealthcare | G25: MBR85307960 | H25: 46210 | I25: 08:30 | J25: 46218 | K25: 14:15 | L25: 8 | M25: Elective | N25: Inpatient | O25: NuuCare Demo Medical Center | P25: Oncology Surgical Ward | Q25: ONC-124A | R25: Dr. Mia Reynolds | S25: C18.9 | T25: Malignant neoplasm of colon, unspecified | U25: E11.9 | V25: 329 | W25: Major small & large bowel procedures w MCC | X25: Y | Y25: Inpatient Rehabilitation | Z25: Oncology Surgical Ward; Colectomy; anesthesia; CT chest; surgical pathology; pharmacy; room and board; physician services | AA25: 44140; 00790; 71260; 88309 | AB25: NSAIDs | AC25: Required - Approved | AD25: =SUMIF('IPD Charge Lines'!$C:$C,B25,'IPD Charge Lines'!$P:$P) -> 25770 | AE25: SYNTHETIC DEMO DATA
A26: IPD-0025 | B26: ENC-IP-2026-00025 | C26: Scarlett Cook | D26: 30482 | E26: Female | F26: Medicare | G26: MBR23438574 | H26: 46218 | I26: 08:30 | J26: 46223 | K26: 14:15 | L26: 5 | M26: Urgent | N26: Inpatient | O26: NuuCare Demo Medical Center | P26: Orthopedic Ward | Q26: ORT-125B | R26: Dr. Amelia Rhodes | S26: T84.54XA | T26: Infection and inflammatory reaction due to internal left knee prosthesis | U26: D64.9 | V26: 856 | W26: Postoperative or post-traumatic infections w O.R. procedure w MCC | X26: N | Y26: Transfer to Acute Facility | Z26: Orthopedic Ward; Revision knee arthroplasty; anesthesia; wound culture; X-ray; pharmacy; room and board; physician services | AA26: 27487; 01402; 87070; 73560 | AB26: NKDA | AC26: Pending Review | AD26: =SUMIF('IPD Charge Lines'!$C:$C,B26,'IPD Charge Lines'!$P:$P) -> 18803.7 | AE26: SYNTHETIC DEMO DATA

Sheet IPD Charge Lines
A1: Charge Line ID | B1: Patient ID | C1: Encounter ID | D1: Service Date | E1: Facility | F1: Department / Cost Center | G1: Service Category | H1: Service Description | I1: Revenue Code | J1: CPT / HCPCS | K1: ICD-10-CM Pointer | L1: NDC / Drug Reference | M1: Quantity | N1: Unit | O1: Unit Charge ($) | P1: Line Charge ($) | Q1: Payer Responsibility (%) | R1: Estimated Payer Amount ($) | S1: Estimated Patient Amount ($) | T1: Charge Status | U1: Scrub Flag | V1: Scrub Note
A2: CL-000001 | B2: IPD-0001 | C2: ENC-IP-2026-00001 | D2: 46026 | E2: NuuCare Demo Medical Center | F2: Medical Ward | G2: Room & Board | H2: Room & Board | I2: 0120 | K2: J18.9 | M2: 5 | N2: day | O2: 624 | P2: =M2*O2 -> 3120 | Q2: 0.8 | R2: =P2*Q2 -> 2496 | S2: =P2-R2 -> 624 | T2: Posted | U2: PASS
A3: CL-000002 | B3: IPD-0001 | C3: ENC-IP-2026-00001 | D3: 46026 | E3: NuuCare Demo Medical Center | F3: Hospitalist | G3: Professional | H3: Professional Fees | I3: 0981 | J3: 99223 | K3: J18.9 | M3: 1 | N3: service | O3: 297.6 | P3: =M3*O3 -> 297.6 | Q3: 0.8 | R3: =P3*Q3 -> 238.08 | S3: =P3-R3 -> 59.52 | T3: Posted | U3: PASS
A4: CL-000003 | B4: IPD-0001 | C4: ENC-IP-2026-00001 | D4: 46027 | E4: NuuCare Demo Medical Center | F4: Hospitalist | G4: Professional | H4: Professional Fees | I4: 0981 | J4: 99233 | K4: J18.9 | M4: 4 | N4: visit | O4: 177.6 | P4: =M4*O4 -> 710.4 | Q4: 0.8 | R4: =P4*Q4 -> 568.32 | S4: =P4-R4 -> 142.08 | T4: Posted | U4: PASS
A5: CL-000004 | B5: IPD-0001 | C5: ENC-IP-2026-00001 | D5: 46026 | E5: NuuCare Demo Medical Center | F5: Laboratory | G5: Laboratory | H5: Laboratory | I5: 0300 | J5: 85025 | K5: J18.9 | M5: 1 | N5: test | O5: 91.2 | P5: =M5*O5 -> 91.2 | Q5: 0.8 | R5: =P5*Q5 -> 72.96 | S5: =P5-R5 -> 18.24 | T5: Posted | U5: PASS
A6: CL-000005 | B6: IPD-0001 | C6: ENC-IP-2026-00001 | D6: 46026 | E6: NuuCare Demo Medical Center | F6: Laboratory | G6: Laboratory | H6: Laboratory - Chemistry | I6: 0301 | J6: 80053 | K6: J18.9 | M6: 1 | N6: panel | O6: 124.8 | P6: =M6*O6 -> 124.8 | Q6: 0.8 | R6: =P6*Q6 -> 99.84 | S6: =P6-R6 -> 24.96 | T6: Posted | U6: PASS
A7: CL-000006 | B7: IPD-0001 | C7: ENC-IP-2026-00001 | D7: 46026 | E7: NuuCare Demo Medical Center | F7: Pharmacy | G7: Pharmacy | H7: Pharmacy | I7: 0250 | K7: J18.9 | M7: 5 | N7: day | O7: 403.2 | P7: =M7*O7 -> 2016 | Q7: 0.8 | R7: =P7*Q7 -> 1612.8 | S7: =P7-R7 -> 403.2 | T7: Posted | U7: PASS
A8: CL-000007 | B8: IPD-0001 | C8: ENC-IP-2026-00001 | D8: 46026 | E8: NuuCare Demo Medical Center | F8: Nursing | G8: Supplies | H8: Medical/Surgical Supplies | I8: 0270 | K8: J18.9 | M8: 2 | N8: bundle | O8: 336 | P8: =M8*O8 -> 672 | Q8: 0.8 | R8: =P8*Q8 -> 537.6 | S8: =P8-R8 -> 134.4 | T8: Posted | U8: PASS
A9: CL-000008 | B9: IPD-0001 | C9: ENC-IP-2026-00001 | D9: 46026 | E9: NuuCare Demo Medical Center | F9: Radiology | G9: Imaging | H9: Radiology - Chest X-ray | I9: 0324 | J9: 71046 | K9: J18.9 | M9: 1 | N9: study | O9: 201.6 | P9: =M9*O9 -> 201.6 | Q9: 0.8 | R9: =P9*Q9 -> 161.28 | S9: =P9-R9 -> 40.32 | T9: Posted | U9: PASS
A10: CL-000009 | B10: IPD-0001 | C10: ENC-IP-2026-00001 | D10: 46026 | E10: NuuCare Demo Medical Center | F10: Respiratory Therapy | G10: Therapy | H10: Respiratory Services | I10: 0410 | J10: 94640 | K10: J18.9 | M10: 5 | N10: session | O10: 201.6 | P10: =M10*O10 -> 1008 | Q10: 0.8 | R10: =P10*Q10 -> 806.4 | S10: =P10-R10 -> 201.6 | T10: Posted | U10: PASS
A11: CL-000010 | B11: IPD-0002 | C11: ENC-IP-2026-00002 | D11: 46034 | E11: NuuCare Demo Medical Center | F11: Telemetry | G11: Room & Board | H11: Intensive Care - Intermediate ICU | I11: 0206 | K11: I50.23 | M11: 2 | N11: day | O11: 1029 | P11: =M11*O11 -> 2058 | Q11: 0.8 | R11: =P11*Q11 -> 1646.4 | S11: =P11-R11 -> 411.6 | T11: Posted | U11: PASS
A12: CL-000011 | B12: IPD-0002 | C12: ENC-IP-2026-00002 | D12: 46034 | E12: NuuCare Demo Medical Center | F12: Hospitalist | G12: Professional | H12: Professional Fees | I12: 0981 | J12: 99223 | K12: I50.23 | M12: 1 | N12: service | O12: 303.8 | P12: =M12*O12 -> 303.8 | Q12: 0.8 | R12: =P12*Q12 -> 243.04 | S12: =P12-R12 -> 60.76 | T12: Posted | U12: PASS
A13: CL-000012 | B13: IPD-0002 | C13: ENC-IP-2026-00002 | D13: 46035 | E13: NuuCare Demo Medical Center | F13: Hospitalist | G13: Professional | H13: Professional Fees | I13: 0981 | J13: 99233 | K13: I50.23 | M13: 1 | N13: visit | O13: 181.3 | P13: =M13*O13 -> 181.3 | Q13: 0.8 | R13: =P13*Q13 -> 145.04 | S13: =P13-R13 -> 36.26 | T13: Posted | U13: PASS
A14: CL-000013 | B14: IPD-0002 | C14: ENC-IP-2026-00002 | D14: 46034 | E14: NuuCare Demo Medical Center | F14: Laboratory | G14: Laboratory | H14: Laboratory | I14: 0300 | J14: 85025 | K14: I50.23 | M14: 1 | N14: test | O14: 93.1 | P14: =M14*O14 -> 93.1 | Q14: 0.8 | R14: =P14*Q14 -> 74.48 | S14: =P14-R14 -> 18.62 | T14: Posted | U14: PASS
A15: CL-000014 | B15: IPD-0002 | C15: ENC-IP-2026-00002 | D15: 46034 | E15: NuuCare Demo Medical Center | F15: Laboratory | G15: Laboratory | H15: Laboratory - Chemistry | I15: 0301 | J15: 80053 | K15: I50.23 | M15: 1 | N15: panel | O15: 127.4 | P15: =M15*O15 -> 127.4 | Q15: 0.8 | R15: =P15*Q15 -> 101.92 | S15: =P15-R15 -> 25.48 | T15: Posted | U15: PASS
A16: CL-000015 | B16: IPD-0002 | C16: ENC-IP-2026-00002 | D16: 46034 | E16: NuuCare Demo Medical Center | F16: Pharmacy | G16: Pharmacy | H16: Pharmacy | I16: 0250 | K16: I50.23 | M16: 2 | N16: day | O16: 411.6 | P16: =M16*O16 -> 823.2 | Q16: 0.8 | R16: =P16*Q16 -> 658.56 | S16: =P16-R16 -> 164.64 | T16: Posted | U16: PASS
A17: CL-000016 | B17: IPD-0002 | C17: ENC-IP-2026-00002 | D17: 46034 | E17: NuuCare Demo Medical Center | F17: Nursing | G17: Supplies | H17: Medical/Surgical Supplies | I17: 0270 | K17: I50.23 | M17: 1 | N17: bundle | O17: 343 | P17: =M17*O17 -> 343 | Q17: 0.8 | R17: =P17*Q17 -> 274.4 | S17: =P17-R17 -> 68.6 | T17: Posted | U17: PASS
A18: CL-000017 | B18: IPD-0002 | C18: ENC-IP-2026-00002 | D18: 46034 | E18: NuuCare Demo Medical Center | F18: Radiology | G18: Imaging | H18: Radiology - Chest X-ray | I18: 0324 | J18: 71046 | K18: I50.23 | M18: 1 | N18: study | O18: 205.8 | P18: =M18*O18 -> 205.8 | Q18: 0.8 | R18: =P18*Q18 -> 164.64 | S18: =P18-R18 -> 41.16 | T18: Posted | U18: PASS
A19: CL-000018 | B19: IPD-0002 | C19: ENC-IP-2026-00002 | D19: 46034 | E19: NuuCare Demo Medical Center | F19: Cardiology | G19: Diagnostic | H19: EKG/ECG | I19: 0730 | J19: 93010 | K19: I50.23 | M19: 1 | N19: study | O19: 112.7 | P19: =M19*O19 -> 112.7 | Q19: 0.8 | R19: =P19*Q19 -> 90.16 | S19: =P19-R19 -> 22.54 | T19: Posted | U19: PASS
A20: CL-000019 | B20: IPD-0002 | C20: ENC-IP-2026-00002 | D20: 46035 | E20: NuuCare Demo Medical Center | F20: Cardiology | G20: Diagnostic | H20: Cardiology - Echocardiology | I20: 0483 | J20: 93306 | K20: I50.23 | M20: 1 | N20: study | O20: 872.2 | P20: =M20*O20 -> 872.2 | Q20: 0.8 | R20: =P20*Q20 -> 697.76 | S20: =P20-R20 -> 174.44 | T20: Posted | U20: PASS
A21: CL-000020 | B21: IPD-0003 | C21: ENC-IP-2026-00003 | D21: 46042 | E21: NuuCare Demo Medical Center | F21: Surgical Ward | G21: Room & Board | H21: Room & Board | I21: 0120 | K21: K35.80 | M21: 5 | N21: day | O21: 725 | P21: =M21*O21 -> 3625 | Q21: 0.8 | R21: =P21*Q21 -> 2900 | S21: =P21-R21 -> 725 | T21: Posted | U21: PASS
A22: CL-000021 | B22: IPD-0003 | C22: ENC-IP-2026-00003 | D22: 46042 | E22: NuuCare Demo Medical Center | F22: Hospitalist | G22: Professional | H22: Professional Fees | I22: 0981 | J22: 99223 | K22: K35.80 | M22: 1 | N22: service | O22: 310 | P22: =M22*O22 -> 310 | Q22: 0.8 | R22: =P22*Q22 -> 248 | S22: =P22-R22 -> 62 | T22: Posted | U22: PASS
A23: CL-000022 | B23: IPD-0003 | C23: ENC-IP-2026-00003 | D23: 46043 | E23: NuuCare Demo Medical Center | F23: Hospitalist | G23: Professional | H23: Professional Fees | I23: 0981 | J23: 99233 | K23: K35.80 | M23: 4 | N23: visit | O23: 185 | P23: =M23*O23 -> 740 | Q23: 0.8 | R23: =P23*Q23 -> 592 | S23: =P23-R23 -> 148 | T23: Posted | U23: PASS
A24: CL-000023 | B24: IPD-0003 | C24: ENC-IP-2026-00003 | D24: 46042 | E24: NuuCare Demo Medical Center | F24: Laboratory | G24: Laboratory | H24: Laboratory | I24: 0300 | J24: 85025 | K24: K35.80 | M24: 1 | N24: test | O24: 95 | P24: =M24*O24 -> 95 | Q24: 0.8 | R24: =P24*Q24 -> 76 | S24: =P24-R24 -> 19 | T24: Posted | U24: PASS
A25: CL-000024 | B25: IPD-0003 | C25: ENC-IP-2026-00003 | D25: 46042 | E25: NuuCare Demo Medical Center | F25: Laboratory | G25: Laboratory | H25: Laboratory - Chemistry | I25: 0301 | J25: 80053 | K25: K35.80 | M25: 1 | N25: panel | O25: 130 | P25: =M25*O25 -> 130 | Q25: 0.8 | R25: =P25*Q25 -> 104 | S25: =P25-R25 -> 26 | T25: Posted | U25: PASS
A26: CL-000025 | B26: IPD-0003 | C26: ENC-IP-2026-00003 | D26: 46042 | E26: NuuCare Demo Medical Center | F26: Pharmacy | G26: Pharmacy | H26: Pharmacy | I26: 0250 | K26: K35.80 | M26: 5 | N26: day | O26: 420 | P26: =M26*O26 -> 2100 | Q26: 0.8 | R26: =P26*Q26 -> 1680 | S26: =P26-R26 -> 420 | T26: Posted | U26: PASS
A27: CL-000026 | B27: IPD-0003 | C27: ENC-IP-2026-00003 | D27: 46042 | E27: NuuCare Demo Medical Center | F27: Nursing | G27: Supplies | H27: Medical/Surgical Supplies | I27: 0270 | K27: K35.80 | M27: 2 | N27: bundle | O27: 350 | P27: =M27*O27 -> 700 | Q27: 0.8 | R27: =P27*Q27 -> 560 | S27: =P27-R27 -> 140 | T27: Posted | U27: PASS
A28: CL-000027 | B28: IPD-0003 | C28: ENC-IP-2026-00003 | D28: 46042 | E28: NuuCare Demo Medical Center | F28: Radiology | G28: Imaging | H28: CT Scan | I28: 0350 | J28: 74177 | K28: K35.80 | M28: 1 | N28: study | O28: 1450 | P28: =M28*O28 -> 1450 | Q28: 0.8 | R28: =P28*Q28 -> 1160 | S28: =P28-R28 -> 290 | T28: Posted | U28: PASS
A29: CL-000028 | B29: IPD-0003 | C29: ENC-IP-2026-00003 | D29: 46043 | E29: NuuCare Demo Medical Center | F29: Operating Room | G29: Procedure | H29: Operating Room Services | I29: 0360 | J29: 99223 | K29: K35.80 | M29: 1 | N29: case | O29: 3200 | P29: =M29*O29 -> 3200 | Q29: 0.8 | R29: =P29*Q29 -> 2560 | S29: =P29-R29 -> 640 | T29: Posted | U29: PASS
A30: CL-000029 | B30: IPD-0003 | C30: ENC-IP-2026-00003 | D30: 46043 | E30: NuuCare Demo Medical Center | F30: Anesthesiology | G30: Anesthesia | H30: Anesthesia | I30: 0370 | J30: 44970 | K30: K35.80 | M30: 1 | N30: case | O30: 1250 | P30: =M30*O30 -> 1250 | Q30: 0.8 | R30: =P30*Q30 -> 1000 | S30: =P30-R30 -> 250 | T30: Posted | U30: PASS
A31: CL-000030 | B31: IPD-0003 | C31: ENC-IP-2026-00003 | D31: 46043 | E31: NuuCare Demo Medical Center | F31: Central Supply | G31: Implant/Supply | H31: Medical/Surgical Supplies - Other Implants | I31: 0278 | K31: K35.80 | M31: 1 | N31: item | O31: 5800 | P31: =M31*O31 -> 5800 | Q31: 0.8 | R31: =P31*Q31 -> 4640 | S31: =P31-R31 -> 1160 | T31: Posted | U31: PASS
A32: CL-000031 | B32: IPD-0004 | C32: ENC-IP-2026-00004 | D32: 46050 | E32: NuuCare Demo Medical Center | F32: Medical Ward | G32: Room & Board | H32: Room & Board | I32: 0120 | K32: N39.0 | M32: 6 | N32: day | O32: 663 | P32: =M32*O32 -> 3978 | Q32: 0.85 | R32: =P32*Q32 -> 3381.3 | S32: =P32-R32 -> 596.7 | T32: Posted | U32: PASS
A33: CL-000032 | B33: IPD-0004 | C33: ENC-IP-2026-00004 | D33: 46050 | E33: NuuCare Demo Medical Center | F33: Hospitalist | G33: Professional | H33: Professional Fees | I33: 0981 | J33: 99223 | K33: N39.0 | M33: 1 | N33: service | O33: 316.2 | P33: =M33*O33 -> 316.2 | Q33: 0.85 | R33: =P33*Q33 -> 268.77 | S33: =P33-R33 -> 47.43 | T33: Posted | U33: PASS
A34: CL-000033 | B34: IPD-0004 | C34: ENC-IP-2026-00004 | D34: 46051 | E34: NuuCare Demo Medical Center | F34: Hospitalist | G34: Professional | H34: Professional Fees | I34: 0981 | J34: 99233 | K34: N39.0 | M34: 5 | N34: visit | O34: 188.7 | P34: =M34*O34 -> 943.5 | Q34: 0.85 | R34: =P34*Q34 -> 801.975 | S34: =P34-R34 -> 141.525 | T34: Posted | U34: PASS
A35: CL-000034 | B35: IPD-0004 | C35: ENC-IP-2026-00004 | D35: 46050 | E35: NuuCare Demo Medical Center | F35: Laboratory | G35: Laboratory | H35: Laboratory | I35: 0300 | J35: 85025 | K35: N39.0 | M35: 1 | N35: test | O35: 96.9 | P35: =M35*O35 -> 96.9 | Q35: 0.85 | R35: =P35*Q35 -> 82.365 | S35: =P35-R35 -> 14.535 | T35: Posted | U35: PASS
A36: CL-000035 | B36: IPD-0004 | C36: ENC-IP-2026-00004 | D36: 46050 | E36: NuuCare Demo Medical Center | F36: Laboratory | G36: Laboratory | H36: Laboratory - Chemistry | I36: 0301 | J36: 80053 | K36: N39.0 | M36: 1 | N36: panel | O36: 132.6 | P36: =M36*O36 -> 132.6 | Q36: 0.85 | R36: =P36*Q36 -> 112.71 | S36: =P36-R36 -> 19.89 | T36: Posted | U36: PASS
A37: CL-000036 | B37: IPD-0004 | C37: ENC-IP-2026-00004 | D37: 46050 | E37: NuuCare Demo Medical Center | F37: Pharmacy | G37: Pharmacy | H37: Pharmacy | I37: 0250 | K37: N39.0 | M37: 6 | N37: day | O37: 428.4 | P37: =M37*O37 -> 2570.4 | Q37: 0.85 | R37: =P37*Q37 -> 2184.84 | S37: =P37-R37 -> 385.56 | T37: Posted | U37: PASS
A38: CL-000037 | B38: IPD-0004 | C38: ENC-IP-2026-00004 | D38: 46050 | E38: NuuCare Demo Medical Center | F38: Nursing | G38: Supplies | H38: Medical/Surgical Supplies | I38: 0270 | K38: N39.0 | M38: 3 | N38: bundle | O38: 357 | P38: =M38*O38 -> 1071 | Q38: 0.85 | R38: =P38*Q38 -> 910.35 | S38: =P38-R38 -> 160.65 | T38: Posted | U38: PASS
A39: CL-000038 | B39: IPD-0004 | C39: ENC-IP-2026-00004 | D39: 46050 | E39: NuuCare Demo Medical Center | F39: Radiology | G39: Imaging | H39: CT Scan | I39: 0350 | J39: 70450 | K39: N39.0 | M39: 1 | N39: study | O39: 1479 | P39: =M39*O39 -> 1479 | Q39: 0.85 | R39: =P39*Q39 -> 1257.15 | S39: =P39-R39 -> 221.85 | T39: Posted | U39: PASS
A40: CL-000039 | B40: IPD-0005 | C40: ENC-IP-2026-00005 | D40: 46058 | E40: NuuCare Demo Medical Center | F40: Orthopedic Ward | G40: Room & Board | H40: Room & Board | I40: 0120 | K40: M17.11 | M40: 3 | N40: day | O40: 811.2 | P40: =M40*O40 -> 2433.6 | Q40: 0.85 | R40: =P40*Q40 -> 2068.56 | S40: =P40-R40 -> 365.04 | T40: Posted | U40: PASS
...

Sheet IPD_CPT_ICD_Code_Reference
A1: Code Type | B1: Code | C1: Plain-Language Diagnosis / Procedure | D1: Clinical Category | E1: Corresponding Disease / Treatment / Use | F1: Encounter Count | G1: Example Encounter IDs | H1: Code-System Source | I1: Important Note
A2: ICD-10-CM | B2: A41.9 | C2: Sepsis, unspecified organism | D2: Infectious disease | E2: Systemic infection requiring urgent inpatient evaluation and treatment | F2: 1 | G2: ENC-IP-2026-00011 | H2: https://www.cms.gov/medicare/coding-billing/icd-10-codes | I2: Diagnosis code; verify reporting year, sequencing, POA and payer rules.
A3: ICD-10-CM | B3: C18.9 | C3: Malignant neoplasm of colon, unspecified | D3: Oncology | E3: Colon cancer; may support colectomy, imaging and pathology | F3: 1 | G3: ENC-IP-2026-00024 | H3: https://www.cms.gov/medicare/coding-billing/icd-10-codes | I3: Diagnosis code; verify reporting year, sequencing, POA and payer rules.
A4: ICD-10-CM | B4: D57.00 | C4: Sickle-cell disease with crisis, unspecified | D4: Hematology | E4: Sickle-cell crisis; pain control, hydration and blood testing | F4: 1 | G4: ENC-IP-2026-00023 | H4: https://www.cms.gov/medicare/coding-billing/icd-10-codes | I4: Diagnosis code; verify reporting year, sequencing, POA and payer rules.
A5: ICD-10-CM | B5: D64.9 | C5: Anemia, unspecified | D5: Hematology | E5: Low hemoglobin or red-cell disorder requiring evaluation | F5: 5 | G5: ENC-IP-2026-00006, ENC-IP-2026-00010, ENC-IP-2026-00014, ENC-IP-2026-00016, ENC-IP-2026-00025 | H5: https://www.cms.gov/medicare/coding-billing/icd-10-codes | I5: Diagnosis code; verify reporting year, sequencing, POA and payer rules.
A6: ICD-10-CM | B6: E11.621 | C6: Type 2 diabetes mellitus with foot ulcer | D6: Endocrine / wound care | E6: Diabetic foot ulcer; wound care, vascular testing and debridement | F6: 1 | G6: ENC-IP-2026-00007 | H6: https://www.cms.gov/medicare/coding-billing/icd-10-codes | I6: Diagnosis code; verify reporting year, sequencing, POA and payer rules.
A7: ICD-10-CM | B7: E11.9 | C7: Type 2 diabetes mellitus without complications | D7: Endocrine | E7: Diabetes management and glucose monitoring | F7: 2 | G7: ENC-IP-2026-00007, ENC-IP-2026-00024 | H7: https://www.cms.gov/medicare/coding-billing/icd-10-codes | I7: Diagnosis code; verify reporting year, sequencing, POA and payer rules.
A8: ICD-10-CM | B8: E78.5 | C8: Hyperlipidemia, unspecified | D8: Cardiometabolic | E8: Abnormal lipid levels managed medically | F8: 3 | G8: ENC-IP-2026-00002, ENC-IP-2026-00003, ENC-IP-2026-00020 | H8: https://www.cms.gov/medicare/coding-billing/icd-10-codes | I8: Diagnosis code; verify reporting year, sequencing, POA and payer rules.
A9: ICD-10-CM | B9: F32.2 | C9: Major depressive disorder, single episode, severe without psychotic features | D9: Behavioral health | E9: Severe depression requiring psychiatric assessment and treatment | F9: 1 | G9: ENC-IP-2026-00020 | H9: https://www.cms.gov/medicare/coding-billing/icd-10-codes | I9: Diagnosis code; verify reporting year, sequencing, POA and payer rules.
A10: ICD-10-CM | B10: G40.909 | C10: Epilepsy, unspecified, not intractable, without status epilepticus | D10: Neurology | E10: Seizure disorder; may support EEG, imaging and medication management | F10: 1 | G10: ENC-IP-2026-00017 | H10: https://www.cms.gov/medicare/coding-billing/icd-10-codes | I10: Diagnosis code; verify reporting year, sequencing, POA and payer rules.
A11: ICD-10-CM | B11: I10 | C11: Essential primary hypertension | D11: Cardiology | E11: High blood pressure requiring monitoring and medication management | F11: 3 | G11: ENC-IP-2026-00001, ENC-IP-2026-00013, ENC-IP-2026-00022 | H11: https://www.cms.gov/medicare/coding-billing/icd-10-codes | I11: Diagnosis code; verify reporting year, sequencing, POA and payer rules.
A12: ICD-10-CM | B12: I21.4 | C12: Non-ST elevation myocardial infarction | D12: Cardiology | E12: NSTEMI; may require catheterization, coronary intervention and intensive monitoring | F12: 1 | G12: ENC-IP-2026-00006 | H12: https://www.cms.gov/medicare/coding-billing/icd-10-codes | I12: Diagnosis code; verify reporting year, sequencing, POA and payer rules.
A13: ICD-10-CM | B13: I50.23 | C13: Acute on chronic systolic heart failure | D13: Cardiology | E13: Heart-failure exacerbation requiring diuresis, telemetry and cardiac testing | F13: 1 | G13: ENC-IP-2026-00002 | H13: https://www.cms.gov/medicare/coding-billing/icd-10-codes | I13: Diagnosis code; verify reporting year, sequencing, POA and payer rules.
... A92: CPT | B92: 99468 | C92: Initial inpatient neonatal critical care | D92: Neonatal critical care | E92: Initial critical care for a young neonate | F92: 1 | G92: ENC-IP-2026-00019 | H92: https://www.cms.gov/medicare/regulations-guidance/physician-self-referral/list-cpt-hcpcs-codes | I92: Plain-language POC label, not the licensed official CPT descriptor. Verify against the current AMA CPT code set and payer policy.
