Workbook

Sheet START_HERE
A1: Northstar Health | Epic-Inspired Synthetic EHR Demo
A4: Scope | B4: 50 fully synthetic U.S. patients across common ambulatory, emergency, inpatient, clinical, revenue-cycle, and interoperability domains.
A5: Chart experience | B5: Open PATIENT_CHART and choose a Patient ID from cell B3. Excel recalculates the demographic banner and high-level chart metrics.
A6: Safety | B6: No real patient, provider, payer, address, phone, email, or account data is included. Not for diagnosis, care delivery, claims submission, or production integration.
A7: Design note | B7: The workbook is inspired by common U.S. EHR chart workflows and Epic-supported FHIR domains, but it is not an exact Epic Hyperspace replica, official Epic export, or proprietary Clarity/Caboodle schema.
A8: Relational key | B8: Patient_ID is the common key. Encounter_ID connects clinical and billing events.
A9: U.S. conventions | B9: MM/DD/YYYY dates, U.S. addresses and phone formats, USD financials, U.S. race/ethnicity/language fields, ICD-10-CM, CPT/HCPCS, LOINC, CVX, payer/member/group attributes.
A12: Navigation
A13: PATIENT_CHART
A14: Patient_Master
A15: Encounters
A16: Problems
A17: Allergies
A18: Medications
A19: Vitals
A20: Labs
A21: Orders_Procedures
A22: Immunizations
A23: Appointments
... A31: Sources

Sheet PATIENT_CHART
A1: NORTHSTAR HEALTH | PATIENT CHART
A3: Patient ID | B3: P100001
A5: Patient | D5: MRN | F5: DOB | H5: Age | J5: Sex
A6: =IFERROR(INDEX(Patient_Master!$E$2:$E$51,MATCH($B$3,Patient_Master!$A$2:$A$51,0)),"") -> Olivia Johnson | D6: =IFERROR(INDEX(Patient_Master!$B$2:$B$51,MATCH($B$3,Patient_Master!$A$2:$A$51,0)),"") -> MRN500001 | F6: =IFERROR(INDEX(Patient_Master!$F$2:$F$51,MATCH($B$3,Patient_Master!$A$2:$A$51,0)),"") -> 14611 | H6: =IFERROR(INDEX(Patient_Master!$G$2:$G$51,MATCH($B$3,Patient_Master!$A$2:$A$51,0)),"") -> 86 | J6: =IFERROR(INDEX(Patient_Master!$H$2:$H$51,MATCH($B$3,Patient_Master!$A$2:$A$51,0)),"") -> Female
A7: PCP | F7: Language | I7: Location
A8: =IFERROR(INDEX(Patient_Master!$O$2:$O$51,MATCH($B$3,Patient_Master!$A$2:$A$51,0)),"") -> Emily Carter, MD | F8: =IFERROR(INDEX(Patient_Master!$M$2:$M$51,MATCH($B$3,Patient_Master!$A$2:$A$51,0)),"") -> English | I8: =IFERROR(INDEX(Patient_Master!$T$2:$T$51,MATCH($B$3,Patient_Master!$A$2:$A$51,0))&", "&INDEX(Patient_Master!$U$2:$U$51,MATCH($B$3,Patient_Master!$A$2:$A$51,0)),"") -> Seattle, WA
A10: Summary | C10: Encounters | E10: Problems | G10: Meds | I10: Labs | K10: Orders | M10: Notes
A12: Active Problems | C12: Active Medications | E12: Allergies | G12: Recent Encounters | I12: Abnormal Labs | K12: Patient Balance
B13: =COUNTIFS(Problems!$B:$B,$B$3,Problems!$E:$E,"Active") -> 2 | D13: =COUNTIFS(Medications!$B:$B,$B$3,Medications!$H:$H,"Active") -> 1 | F13: =COUNTIF(Allergies!$B:$B,$B$3) -> 1 | H13: =COUNTIF(Encounters!$B:$B,$B$3) -> 3 | J13: =COUNTIFS(Labs!$B:$B,$B$3,Labs!$I:$I,"High") -> 0 | L13: =SUMIF(Billing_Claims!$B:$B,$B$3,Billing_Claims!$K:$K) -> 45
A16: Problem List | G16: Medications
A17: Primary problem | B17: =IFERROR(INDEX(Problems!$D$2:$D$101,MATCH($B$3,Problems!$B$2:$B$101,0)),"None") -> Essential hypertension | G17: Medication | H17: =IFERROR(INDEX(Medications!$C$2:$C$101,MATCH($B$3,Medications!$B$2:$B$101,0)),"None") -> Lisinopril 10 mg tablet
A18: ICD-10-CM | B18: =IFERROR(INDEX(Problems!$C$2:$C$101,MATCH($B$3,Problems!$B$2:$B$101,0)),"") -> I10 | G18: Dose | H18: =IFERROR(INDEX(Medications!$D$2:$D$101,MATCH($B$3,Medications!$B$2:$B$101,0)),"") -> 10 mg
A19: Status | B19: =IFERROR(INDEX(Problems!$E$2:$E$101,MATCH($B$3,Problems!$B$2:$B$101,0)),"") -> Active | G19: Frequency | H19: =IFERROR(INDEX(Medications!$F$2:$F$101,MATCH($B$3,Medications!$B$2:$B$101,0)),"") -> Daily
A25: Appointments | G25: Recent Results
A26: Next date | B26: =IFERROR(INDEX(Appointments!$C$2:$C$51,MATCH($B$3,Appointments!$B$2:$B$51,0)),"") -> 46300 | G26: Latest test | H26: =IFERROR(INDEX(Labs!$E$2:$E$251,MATCH($B$3,Labs!$B$2:$B$251,0)),"") -> Hemoglobin A1c
A27: Reason | B27: =IFERROR(INDEX(Appointments!$I$2:$I$51,MATCH($B$3,Appointments!$B$2:$B$51,0)),"") -> Chronic care follow-up | G27: Result | H27: =IFERROR(INDEX(Labs!$F$2:$F$251,MATCH($B$3,Labs!$B$2:$B$251,0))&" "&INDEX(Labs!$G$2:$G$251,MATCH($B$3,Labs!$B$2:$B$251,0)),"") -> 5.1 %
A28: Status | B28: =IFERROR(INDEX(Appointments!$H$2:$H$51,MATCH($B$3,Appointments!$B$2:$B$51,0)),"") -> Scheduled | G28: Flag | H28: =IFERROR(INDEX(Labs!$I$2:$I$251,MATCH($B$3,Labs!$B$2:$B$251,0)),"") -> Normal

Sheet Patient_Master
A1: Patient_ID | B1: MRN | C1: First_Name | D1: Last_Name | E1: Legal_Name | F1: DOB | G1: Age | H1: Sex_at_Birth | I1: Pronouns | J1: Marital_Status | K1: Race | L1: Ethnicity | M1: Preferred_Language | N1: Secondary_Language | O1: PCP | P1: Record_Status | Q1: Height_cm | R1: Weight_kg | S1: BMI | T1: City | U1: State | V1: ZIP | W1: Country | X1: Street_Address | Y1: Mobile | Z1: Email
A2: P100001 | B2: MRN500001 | C2: Olivia | D2: Johnson | E2: Olivia Johnson | F2: 14611 | G2: =DATEDIF(F2,TODAY(),"Y") -> 86 | H2: Female | I2: she/her | J2: Single | K2: White | L2: Not Hispanic or Latino | M2: English | N2: English | O2: Emily Carter, MD | P2: Active | Q2: 158 | R2: 55 | S2: =IFERROR(R2/((Q2/100)^2),"") -> 22.031726 | T2: Seattle | U2: WA | V2: 98101 | W2: United States | X2: 102 Main Street | Y2: (555) 202-1002 | Z2: olivia.johnson@example.test
A3: P100002 | B3: MRN500002 | C3: Liam | D3: Williams | E3: Liam Williams | F3: 17330 | G3: =DATEDIF(F3,TODAY(),"Y") -> 79 | H3: Male | I3: he/him | J3: Married | K3: Black or African American | L3: Hispanic or Latino | M3: Spanish | N3: English | O3: Michael Chen, MD | P3: Active | Q3: 172 | R3: 62 | S3: =IFERROR(R3/((Q3/100)^2),"") -> 20.957274 | T3: Portland | U3: OR | V3: 97201 | W3: United States | X3: 103 Main Street | Y3: (555) 203-1003 | Z3: liam.williams@example.test
A4: P100003 | B4: MRN500003 | C4: Emma | D4: Brown | E4: Emma Brown | F4: 20051 | G4: =DATEDIF(F4,TODAY(),"Y") -> 71 | H4: Female | I4: she/her | J4: Divorced | K4: Asian | L4: Declined to answer | M4: Mandarin | N4: English | O4: Sarah Williams, DO | P4: Active | Q4: 164 | R4: 69 | S4: =IFERROR(R4/((Q4/100)^2),"") -> 25.654372 | T4: San Francisco | U4: CA | V4: 94105 | W4: United States | X4: 104 Main Street | Y4: (555) 204-1004 | Z4: emma.brown@example.test
A5: P100004 | B5: MRN500004 | C5: Noah | D5: Jones | E5: Noah Jones | F5: 22378 | G5: =DATEDIF(F5,TODAY(),"Y") -> 65 | H5: Male | I5: he/him | J5: Widowed | K5: American Indian or Alaska Native | L5: Not Hispanic or Latino | M5: Vietnamese | N5: English | O5: David Martinez, MD | P5: Active | Q5: 180 | R5: 76 | S5: =IFERROR(R5/((Q5/100)^2),"") -> 23.45679 | T5: Los Angeles | U5: CA | V5: 90012 | W5: United States | X5: 105 Main Street | Y5: (555) 205-1005 | Z5: noah.jones@example.test
A6: P100005 | B6: MRN500005 | C6: Ava | D6: Garcia | E6: Ava Garcia | F6: 25099 | G6: =DATEDIF(F6,TODAY(),"Y") -> 58 | H6: Female | I6: she/her | J6: Single | K6: Native Hawaiian or Other Pacific Islander | L6: Hispanic or Latino | M6: French | N6: English | O6: Rachel Kim, MD | P6: Active | Q6: 170 | R6: 83 | S6: =IFERROR(R6/((Q6/100)^2),"") -> 28.719723 | T6: Phoenix | U6: AZ | V6: 85004 | W6: United States | X6: 106 Main Street | Y6: (555) 206-1006 | Z6: ava.garcia@example.test
A7: P100006 | B7: MRN500006 | C7: Oliver | D7: Miller | E7: Oliver Miller | F7: 27427 | G7: =DATEDIF(F7,TODAY(),"Y") -> 51 | H7: Male | I7: he/him | J7: Married | K7: Other race | L7: Declined to answer | M7: Arabic | N7: English | O7: James Wilson, NP | P7: Active | Q7: 188 | R7: 90 | S7: =IFERROR(R7/((Q7/100)^2),"") -> 25.464011 | T7: Denver | U7: CO | V7: 80202 | W7: United States | X7: 107 Main Street | Y7: (555) 207-1007 | Z7: oliver.miller@example.test
A8: P100007 | B8: MRN500007 | C8: Sophia | D8: Davis | E8: Sophia Davis | F8: 30145 | G8: =DATEDIF(F8,TODAY(),"Y") -> 44 | H8: Female | I8: she/her | J8: Divorced | K8: Declined to answer | L8: Not Hispanic or Latino | M8: English | N8: English | O8: Emily Carter, MD | P8: Active | Q8: 176 | R8: 97 | S8: =IFERROR(R8/((Q8/100)^2),"") -> 31.314566 | T8: Dallas | U8: TX | V8: 75201 | W8: United States | X8: 108 Main Street | Y8: (555) 208-1008 | Z8: sophia.davis@example.test
A9: P100008 | B9: MRN500008 | C9: Elijah | D9: Rodriguez | E9: Elijah Rodriguez | F9: 32866 | G9: =DATEDIF(F9,TODAY(),"Y") -> 36 | H9: Male | I9: he/him | J9: Widowed | K9: White | L9: Hispanic or Latino | M9: Spanish | N9: English | O9: Michael Chen, MD | P9: Active | Q9: 171 | R9: 104 | S9: =IFERROR(R9/((Q9/100)^2),"") -> 35.566499 | T9: Houston | U9: TX | V9: 77002 | W9: United States | X9: 109 Main Street | Y9: (555) 209-1009 | Z9: elijah.rodriguez@example.test
A10: P100009 | B10: MRN500009 | C10: Isabella | D10: Martinez | E10: Isabella Martinez | F10: 35193 | G10: =DATEDIF(F10,TODAY(),"Y") -> 30 | H10: Female | I10: she/her | J10: Single | K10: Black or African American | L10: Declined to answer | M10: Mandarin | N10: English | O10: Sarah Williams, DO | P10: Active | Q10: 182 | R10: 111 | S10: =IFERROR(R10/((Q10/100)^2),"") -> 33.510446 | T10: Chicago | U10: IL | V10: 60601 | W10: United States | X10: 110 Main Street | Y10: (555) 210-1010 | Z10: isabella.martinez@example.test
A11: P100010 | B11: MRN500010 | C11: James | D11: Hernandez | E11: James Hernandez | F11: 37913 | G11: =DATEDIF(F11,TODAY(),"Y") -> 22 | H11: Male | I11: he/him | J11: Married | K11: Asian | L11: Not Hispanic or Latino | M11: Vietnamese | N11: English | O11: David Martinez, MD | P11: Active | Q11: 179 | R11: 60 | S11: =IFERROR(R11/((Q11/100)^2),"") -> 18.726007 | T11: Atlanta | U11: GA | V11: 30303 | W11: United States | X11: 111 Main Street | Y11: (555) 211-1011 | Z11: james.hernandez@example.test
A12: P100011 | B12: MRN500011 | C12: Mia | D12: Lopez | E12: Mia Lopez | F12: 16134 | G12: =DATEDIF(F12,TODAY(),"Y") -> 82 | H12: Female | I12: she/her | J12: Divorced | K12: American Indian or Alaska Native | L12: Hispanic or Latino | M12: French | N12: English | O12: Rachel Kim, MD | P12: Active | Q12: 160 | R12: 67 | S12: =IFERROR(R12/((Q12/100)^2),"") -> 26.171875 | T12: Miami | U12: FL | V12: 33101 | W12: United States | X12: 112 Main Street | Y12: (555) 212-1012 | Z12: mia.lopez@example.test
A13: P100012 | B13: MRN500012 | C13: William | D13: Gonzalez | E13: William Gonzalez | F13: 18854 | G13: =DATEDIF(F13,TODAY(),"Y") -> 75 | H13: Male | I13: he/him | J13: Widowed | K13: Native Hawaiian or Other Pacific Islander | L13: Declined to answer | M13: Arabic | N13: English | O13: James Wilson, NP | P13: Active | Q13: 187 | R13: 74 | S13: =IFERROR(R13/((Q13/100)^2),"") -> 21.1616 | T13: Boston | U13: MA | V13: 02108 | W13: United States | X13: 113 Main Street | Y13: (555) 213-1013 | Z13: william.gonzalez@example.test
... A51: P100050 | B51: MRN500050 | C51: Asher | D51: Evans | E51: Asher Evans | F51: 19537 | G51: =DATEDIF(F51,TODAY(),"Y") -> 73 | H51: Male | I51: he/him | J51: Married | K51: White | L51: Hispanic or Latino | M51: Spanish | N51: English | O51: Michael Chen, MD | P51: Active | Q51: 189 | R51: 108 | S51: =IFERROR(R51/((Q51/100)^2),"") -> 30.234316 | T51: Atlanta | U51: GA | V51: 30303 | W51: United States | X51: 151 Main Street | Y51: (555) 251-1051 | Z51: asher.evans@example.test

Sheet Encounters
A1: Encounter_ID | B1: Patient_ID | C1: Date | D1: Type | E1: Department | F1: Provider | G1: Facility | H1: Status | I1: Primary_Diagnosis_Code | J1: Primary_Diagnosis | K1: Priority | L1: Disposition_or_Follow_Up
A2: ENC0011 | B2: P100001 | C2: 46285 | D2: Office Visit | E2: Family Medicine | F2: Emily Carter, MD | G2: Northstar Medical Center | H2: Completed | I2: I10 | J2: Essential hypertension | K2: Routine | L2: Follow-up in 3 months
A3: ENC0012 | B3: P100001 | C3: 46190 | D3: Annual Wellness | E3: Family Medicine | F3: Emily Carter, MD | G3: Northstar Medical Center | H3: Completed | I3: E11.9 | J3: Type 2 diabetes mellitus without complications | K3: Routine | L3: Follow-up in 3 months
A4: ENC0013 | B4: P100001 | C4: 46095 | D4: Emergency | E4: Family Medicine | F4: Emily Carter, MD | G4: Northstar Medical Center | H4: Completed | I4: E78.5 | J4: Hyperlipidemia, unspecified | K4: Urgent | L4: Follow-up in 3 months
A5: ENC0021 | B5: P100002 | C5: 46283 | D5: Office Visit | E5: Internal Medicine | F5: Michael Chen, MD | G5: Northstar Downtown Clinic | H5: Completed | I5: E11.9 | J5: Type 2 diabetes mellitus without complications | K5: Routine | L5: Follow-up in 4 months
A6: ENC0022 | B6: P100002 | C6: 46188 | D6: Annual Wellness | E6: Internal Medicine | F6: Michael Chen, MD | G6: Northstar Downtown Clinic | H6: Completed | I6: E78.5 | J6: Hyperlipidemia, unspecified | K6: Routine | L6: Follow-up in 4 months
A7: ENC0023 | B7: P100002 | C7: 46093 | D7: Annual Wellness | E7: Internal Medicine | F7: Michael Chen, MD | G7: Northstar Downtown Clinic | H7: Completed | I7: J45.909 | J7: Unspecified asthma, uncomplicated | K7: Routine | L7: Follow-up in 4 months
A8: ENC0031 | B8: P100003 | C8: 46281 | D8: Office Visit | E8: Cardiology | F8: Sarah Williams, DO | G8: Northstar Westside Clinic | H8: Completed | I8: E78.5 | J8: Hyperlipidemia, unspecified | K8: Routine | L8: Follow-up in 5 months
A9: ENC0032 | B9: P100003 | C9: 46186 | D9: Annual Wellness | E9: Cardiology | F9: Sarah Williams, DO | G9: Northstar Westside Clinic | H9: Completed | I9: J45.909 | J9: Unspecified asthma, uncomplicated | K9: Routine | L9: Follow-up in 5 months
A10: ENC0033 | B10: P100003 | C10: 46091 | D10: Annual Wellness | E10: Cardiology | F10: Sarah Williams, DO | G10: Northstar Westside Clinic | H10: Completed | I10: G43.909 | J10: Migraine, unspecified, not intractable | K10: Routine | L10: Follow-up in 5 months
A11: ENC0041 | B11: P100004 | C11: 46279 | D11: Office Visit | E11: Pulmonology | F11: David Martinez, MD | G11: Northstar Urgent Care | H11: Completed | I11: J45.909 | J11: Unspecified asthma, uncomplicated | K11: Routine | L11: Follow-up in 6 months
A12: ENC0042 | B12: P100004 | C12: 46184 | D12: Annual Wellness | E12: Pulmonology | F12: David Martinez, MD | G12: Northstar Urgent Care | H12: Completed | I12: G43.909 | J12: Migraine, unspecified, not intractable | K12: Routine | L12: Follow-up in 6 months
A13: ENC0043 | B13: P100004 | C13: 46089 | D13: Annual Wellness | E13: Pulmonology | F13: David Martinez, MD | G13: Northstar Urgent Care | H13: Completed | I13: M17.11 | J13: Osteoarthritis, right knee | K13: Routine | L13: Follow-up in 6 months
... A151: ENC0503 | B151: P100050 | C151: 45997 | D151: Annual Wellness | E151: Internal Medicine | F151: Michael Chen, MD | G151: Northstar Downtown Clinic | H151: Completed | I151: E11.9 | J151: Type 2 diabetes mellitus without complications | K151: Routine | L151: Follow-up in 4 months

Sheet Problems
A1: Problem_ID | B1: Patient_ID | C1: ICD_10_CM | D1: Problem_Name | E1: Clinical_Status | F1: Verification_Status | G1: Onset_Date | H1: Resolved_Date | I1: Provider | J1: Category
A2: PRB0011 | B2: P100001 | C2: I10 | D2: Essential hypertension | E2: Active | F2: Confirmed | G2: 43831 | I2: Emily Carter, MD | J2: Problem List
A3: PRB0012 | B3: P100001 | C3: E11.9 | D3: Type 2 diabetes mellitus without complications | E3: Active | F3: Confirmed | G3: 44197 | H3: 45823 | I3: Emily Carter, MD | J3: Problem List
A4: PRB0021 | B4: P100002 | C4: E11.9 | D4: Type 2 diabetes mellitus without complications | E4: Active | F4: Confirmed | G4: 44229 | I4: Michael Chen, MD | J4: Problem List
A5: PRB0022 | B5: P100002 | C5: E78.5 | D5: Hyperlipidemia, unspecified | E5: Resolved | F5: Confirmed | G5: 44594 | H5: 45823 | I5: Michael Chen, MD | J5: Problem List
A6: PRB0031 | B6: P100003 | C6: E78.5 | D6: Hyperlipidemia, unspecified | E6: Active | F6: Confirmed | G6: 44623 | I6: Sarah Williams, DO | J6: Problem List
A7: PRB0032 | B7: P100003 | C7: J45.909 | D7: Unspecified asthma, uncomplicated | E7: Resolved | F7: Confirmed | G7: 44988 | H7: 45823 | I7: Sarah Williams, DO | J7: Problem List
A8: PRB0041 | B8: P100004 | C8: J45.909 | D8: Unspecified asthma, uncomplicated | E8: Active | F8: Confirmed | G8: 45020 | I8: David Martinez, MD | J8: Problem List
A9: PRB0042 | B9: P100004 | C9: G43.909 | D9: Migraine, unspecified, not intractable | E9: Active | F9: Confirmed | G9: 45386 | H9: 45823 | I9: David Martinez, MD | J9: Problem List
A10: PRB0051 | B10: P100005 | C10: G43.909 | D10: Migraine, unspecified, not intractable | E10: Active | F10: Confirmed | G10: 45417 | I10: Rachel Kim, MD | J10: Problem List
A11: PRB0052 | B11: P100005 | C11: M17.11 | D11: Osteoarthritis, right knee | E11: Resolved | F11: Confirmed | G11: 43956 | H11: 45823 | I11: Rachel Kim, MD | J11: Problem List
A12: PRB0061 | B12: P100006 | C12: M17.11 | D12: Osteoarthritis, right knee | E12: Active | F12: Confirmed | G12: 43988 | I12: James Wilson, NP | J12: Problem List
A13: PRB0062 | B13: P100006 | C13: F41.9 | D13: Anxiety disorder, unspecified | E13: Resolved | F13: Confirmed | G13: 44353 | H13: 45823 | I13: James Wilson, NP | J13: Problem List
A14: PRB0071 | B14: P100007 | C14: F41.9 | D14: Anxiety disorder, unspecified | E14: Active | F14: Confirmed | G14: 44384 | I14: Emily Carter, MD | J14: Problem List
A15: PRB0072 | B15: P100007 | C15: K21.9 | D15: Gastro-esophageal reflux disease without esophagitis | E15: Active | F15: Confirmed | G15: 44749 | H15: 45823 | I15: Emily Carter, MD | J15: Problem List
A16: PRB0081 | B16: P100008 | C16: K21.9 | D16: Gastro-esophageal reflux disease without esophagitis | E16: Active | F16: Confirmed | G16: 44781 | I16: Michael Chen, MD | J16: Problem List
A17: PRB0082 | B17: P100008 | C17: E03.9 | D17: Hypothyroidism, unspecified | E17: Resolved | F17: Confirmed | G17: 45146 | H17: 45823 | I17: Michael Chen, MD | J17: Problem List
A18: PRB0091 | B18: P100009 | C18: E03.9 | D18: Hypothyroidism, unspecified | E18: Active | F18: Confirmed | G18: 45178 | I18: Sarah Williams, DO | J18: Problem List
A19: PRB0092 | B19: P100009 | C19: I25.10 | D19: Atherosclerotic heart disease | E19: Resolved | F19: Confirmed | G19: 45544 | H19: 45823 | I19: Sarah Williams, DO | J19: Problem List
A20: PRB0101 | B20: P100010 | C20: I25.10 | D20: Atherosclerotic heart disease | E20: Active | F20: Confirmed | G20: 45575 | I20: David Martinez, MD | J20: Problem List
A21: PRB0102 | B21: P100010 | C21: I10 | D21: Essential hypertension | E21: Active | F21: Confirmed | G21: 44114 | H21: 45823 | I21: David Martinez, MD | J21: Problem List
A22: PRB0111 | B22: P100011 | C22: I10 | D22: Essential hypertension | E22: Active | F22: Confirmed | G22: 43841 | I22: Rachel Kim, MD | J22: Problem List
A23: PRB0112 | B23: P100011 | C23: E11.9 | D23: Type 2 diabetes mellitus without complications | E23: Resolved | F23: Confirmed | G23: 44207 | H23: 45823 | I23: Rachel Kim, MD | J23: Problem List
A24: PRB0121 | B24: P100012 | C24: E11.9 | D24: Type 2 diabetes mellitus without complications | E24: Active | F24: Confirmed | G24: 44239 | I24: James Wilson, NP | J24: Problem List
A25: PRB0122 | B25: P100012 | C25: E78.5 | D25: Hyperlipidemia, unspecified | E25: Resolved | F25: Confirmed | G25: 44604 | H25: 45823 | I25: James Wilson, NP | J25: Problem List
A26: PRB0131 | B26: P100013 | C26: E78.5 | D26: Hyperlipidemia, unspecified | E26: Active | F26: Confirmed | G26: 44633 | I26: Emily Carter, MD | J26: Problem List
A27: PRB0132 | B27: P100013 | C27: J45.909 | D27: Unspecified asthma, uncomplicated | E27: Active | F27: Confirmed | G27: 44998 | H27: 45823 | I27: Emily Carter, MD | J27: Problem List
A28: PRB0141 | B28: P100014 | C28: J45.909 | D28: Unspecified asthma, uncomplicated | E28: Active | F28: Confirmed | G28: 45030 | I28: Michael Chen, MD | J28: Problem List
A29: PRB0142 | B29: P100014 | C29: G43.909 | D29: Migraine, unspecified, not intractable | E29: Resolved | F29: Confirmed | G29: 45396 | H29: 45823 | I29: Michael Chen, MD | J29: Problem List
A30: PRB0151 | B30: P100015 | C30: G43.909 | D30: Migraine, unspecified, not intractable | E30: Active | F30: Confirmed | G30: 45427 | I30: Sarah Williams, DO | J30: Problem List
A31: PRB0152 | B31: P100015 | C31: M17.11 | D31: Osteoarthritis, right knee | E31: Resolved | F31: Confirmed | G31: 43966 | H31: 45823 | I31: Sarah Williams, DO | J31: Problem List
A32: PRB0161 | B32: P100016 | C32: M17.11 | D32: Osteoarthritis, right knee | E32: Active | F32: Confirmed | G32: 43998 | I32: David Martinez, MD | J32: Problem List
A33: PRB0162 | B33: P100016 | C33: F41.9 | D33: Anxiety disorder, unspecified | E33: Active | F33: Confirmed | G33: 44363 | H33: 45823 | I33: David Martinez, MD | J33: Problem List
A34: PRB0171 | B34: P100017 | C34: F41.9 | D34: Anxiety disorder, unspecified | E34: Active | F34: Confirmed | G34: 44394 | I34: Rachel Kim, MD | J34: Problem List
A35: PRB0172 | B35: P100017 | C35: K21.9 | D35: Gastro-esophageal reflux disease without esophagitis | E35: Resolved | F35: Confirmed | G35: 44759 | H35: 45823 | I35: Rachel Kim, MD | J35: Problem List
A36: PRB0181 | B36: P100018 | C36: K21.9 | D36: Gastro-esophageal reflux disease without esophagitis | E36: Active | F36: Confirmed | G36: 44791 | I36: James Wilson, NP | J36: Problem List
A37: PRB0182 | B37: P100018 | C37: E03.9 | D37: Hypothyroidism, unspecified | E37: Resolved | F37: Confirmed | G37: 45156 | H37: 45823 | I37: James Wilson, NP | J37: Problem List
A38: PRB0191 | B38: P100019 | C38: E03.9 | D38: Hypothyroidism, unspecified | E38: Active | F38: Confirmed | G38: 45188 | I38: Emily Carter, MD | J38: Problem List
A39: PRB0192 | B39: P100019 | C39: I25.10 | D39: Atherosclerotic heart disease | E39: Active | F39: Confirmed | G39: 45554 | H39: 45823 | I39: Emily Carter, MD | J39: Problem List
A40: PRB0201 | B40: P100020 | C40: I25.10 | D40: Atherosclerotic heart disease | E40: Active | F40: Confirmed | G40: 45585 | I40: Michael Chen, MD | J40: Problem List
...

Sheet Allergies
A1: Allergy_ID | B1: Patient_ID | C1: Substance | D1: Category | E1: Reaction | F1: Severity | G1: Clinical_Status | H1: Verification_Status | I1: Recorded_Date | J1: Recorder
A2: ALG0001 | B2: P100001 | C2: Penicillin | D2: Drug | E2: Hives | F2: Moderate | G2: Active | H2: Confirmed | I2: 44296 | J2: Emily Carter, MD
A3: ALG0002 | B3: P100002 | C3: Sulfonamide antibiotics | D3: Drug | E3: Rash | F3: Moderate | G3: Active | H3: Confirmed | I3: 44661 | J3: Michael Chen, MD
A4: ALG0003 | B4: P100003 | C4: Peanut | D4: Food | E4: Anaphylaxis | F4: Severe | G4: Active | H4: Confirmed | I4: 45026 | J4: Sarah Williams, DO
A5: ALG0004 | B5: P100004 | C5: Latex | D5: Environmental | E5: Contact dermatitis | F5: Mild | G5: Active | H5: Confirmed | I5: 45392 | J5: David Martinez, MD
A6: ALG0005 | B6: P100005 | C6: No known allergies | D6: Environmental | E6: None | F6: None | G6: Active | H6: Confirmed | I6: 44296 | J6: Rachel Kim, MD
A7: ALG0006 | B7: P100006 | C7: Penicillin | D7: Drug | E7: Hives | F7: Moderate | G7: Active | H7: Confirmed | I7: 44661 | J7: James Wilson, NP
A8: ALG0007 | B8: P100007 | C8: Sulfonamide antibiotics | D8: Drug | E8: Rash | F8: Moderate | G8: Active | H8: Confirmed | I8: 45026 | J8: Emily Carter, MD
A9: ALG0008 | B9: P100008 | C9: Peanut | D9: Food | E9: Anaphylaxis | F9: Severe | G9: Active | H9: Confirmed | I9: 45392 | J9: Michael Chen, MD
A10: ALG0009 | B10: P100009 | C10: Latex | D10: Environmental | E10: Contact dermatitis | F10: Mild | G10: Active | H10: Confirmed | I10: 44296 | J10: Sarah Williams, DO
A11: ALG0010 | B11: P100010 | C11: No known allergies | D11: Environmental | E11: None | F11: None | G11: Active | H11: Confirmed | I11: 44661 | J11: David Martinez, MD
A12: ALG0011 | B12: P100011 | C12: Penicillin | D12: Drug | E12: Hives | F12: Moderate | G12: Active | H12: Confirmed | I12: 45026 | J12: Rachel Kim, MD
A13: ALG0012 | B13: P100012 | C13: Sulfonamide antibiotics | D13: Drug | E13: Rash | F13: Moderate | G13: Active | H13: Confirmed | I13: 45392 | J13: James Wilson, NP
... A51: ALG0050 | B51: P100050 | C51: No known allergies | D51: Environmental | E51: None | F51: None | G51: Active | H51: Confirmed | I51: 44661 | J51: Michael Chen, MD

Sheet Medications
A1: Medication_ID | B1: Patient_ID | C1: Medication | D1: Dose | E1: Route | F1: Frequency | G1: Start_Date | H1: Status | I1: Prescriber | J1: Indication_ICD_10 | K1: Dispense | L1: Refills
A2: MED0011 | B2: P100001 | C2: Lisinopril 10 mg tablet | D2: 10 mg | E2: Oral | F2: Daily | G2: 46027 | H2: Active | I2: Emily Carter, MD | J2: I10 | K2: 30 day supply | L2: 3
A3: MED0012 | B3: P100001 | C3: Metformin 500 mg tablet | D3: 500 mg | E3: Oral | F3: Twice daily | G3: 46058 | H3: Completed | I3: Emily Carter, MD | J3: E11.9 | K3: 30 day supply | L3: 0
A4: MED0021 | B4: P100002 | C4: Metformin 500 mg tablet | D4: 500 mg | E4: Oral | F4: Twice daily | G4: 46028 | H4: Active | I4: Michael Chen, MD | J4: E11.9 | K4: 30 day supply | L4: 3
A5: MED0022 | B5: P100002 | C5: Atorvastatin 20 mg tablet | D5: 20 mg | E5: Oral | F5: Nightly | G5: 46059 | H5: Completed | I5: Michael Chen, MD | J5: E78.5 | K5: 30 day supply | L5: 0
A6: MED0031 | B6: P100003 | C6: Atorvastatin 20 mg tablet | D6: 20 mg | E6: Oral | F6: Nightly | G6: 46029 | H6: Active | I6: Sarah Williams, DO | J6: E78.5 | K6: 30 day supply | L6: 3
A7: MED0032 | B7: P100003 | C7: Albuterol HFA 90 mcg inhaler | D7: 2 puffs | E7: Inhaled | F7: Every 4-6 hours as needed | G7: 46060 | H7: Completed | I7: Sarah Williams, DO | J7: J45.909 | K7: 30 day supply | L7: 0
A8: MED0041 | B8: P100004 | C8: Albuterol HFA 90 mcg inhaler | D8: 2 puffs | E8: Inhaled | F8: Every 4-6 hours as needed | G8: 46030 | H8: Active | I8: David Martinez, MD | J8: J45.909 | K8: 30 day supply | L8: 3
A9: MED0042 | B9: P100004 | C9: Levothyroxine 50 mcg tablet | D9: 50 mcg | E9: Oral | F9: Daily before breakfast | G9: 46061 | H9: Completed | I9: David Martinez, MD | J9: E03.9 | K9: 30 day supply | L9: 0
A10: MED0051 | B10: P100005 | C10: Levothyroxine 50 mcg tablet | D10: 50 mcg | E10: Oral | F10: Daily before breakfast | G10: 46031 | H10: Active | I10: Rachel Kim, MD | J10: E03.9 | K10: 30 day supply | L10: 3
A11: MED0052 | B11: P100005 | C11: Omeprazole 20 mg capsule | D11: 20 mg | E11: Oral | F11: Daily | G11: 46062 | H11: Completed | I11: Rachel Kim, MD | J11: K21.9 | K11: 30 day supply | L11: 0
A12: MED0061 | B12: P100006 | C12: Omeprazole 20 mg capsule | D12: 20 mg | E12: Oral | F12: Daily | G12: 46032 | H12: Active | I12: James Wilson, NP | J12: K21.9 | K12: 30 day supply | L12: 3
A13: MED0062 | B13: P100006 | C13: Lisinopril 10 mg tablet | D13: 10 mg | E13: Oral | F13: Daily | G13: 46063 | H13: Completed | I13: James Wilson, NP | J13: I10 | K13: 30 day supply | L13: 0
... A101: MED0502 | B101: P100050 | C101: Atorvastatin 20 mg tablet | D101: 20 mg | E101: Oral | F101: Nightly | G101: 46067 | H101: Completed | I101: Michael Chen, MD | J101: E78.5 | K101: 30 day supply | L101: 0

Sheet Vitals
A1: Vital_ID | B1: Patient_ID | C1: Observed_Date | D1: Systolic_mmHg | E1: Diastolic_mmHg | F1: Heart_Rate_bpm | G1: Respiratory_Rate | H1: SpO2_Percent | I1: Temperature_F | J1: Weight_kg | K1: Height_cm | L1: BMI | M1: Recorded_By | N1: Position
A2: VIT0011 | B2: P100001 | C2: 46280 | D2: 110 | E2: 68 | F2: 62 | G2: 14 | H2: 96 | I2: 97.6 | J2: 53.9 | K2: 158 | L2: 21.6 | M2: Emily Carter, MD | N2: Sitting
A3: VIT0012 | B3: P100001 | C3: 46190 | D3: 111 | E3: 68 | F3: 62 | G3: 14 | H3: 96 | I3: 97.6 | J3: 55 | K3: 158 | L3: 22 | M3: Emily Carter, MD | N3: Sitting
A4: VIT0013 | B4: P100001 | C4: 46100 | D4: 112 | E4: 68 | F4: 62 | G4: 14 | H4: 96 | I4: 97.6 | J4: 56.1 | K4: 158 | L4: 22.5 | M4: Emily Carter, MD | N4: Sitting
A5: VIT0021 | B5: P100002 | C5: 46279 | D5: 113 | E5: 70 | F5: 63 | G5: 15 | H5: 97 | I5: 97.8 | J5: 60.9 | K5: 172 | L5: 20.6 | M5: Michael Chen, MD | N5: Sitting
A6: VIT0022 | B6: P100002 | C6: 46189 | D6: 114 | E6: 70 | F6: 63 | G6: 15 | H6: 97 | I6: 97.8 | J6: 62 | K6: 172 | L6: 21 | M6: Michael Chen, MD | N6: Sitting
A7: VIT0023 | B7: P100002 | C7: 46099 | D7: 115 | E7: 70 | F7: 63 | G7: 15 | H7: 97 | I7: 97.8 | J7: 63.1 | K7: 172 | L7: 21.3 | M7: Michael Chen, MD | N7: Sitting
A8: VIT0031 | B8: P100003 | C8: 46278 | D8: 116 | E8: 72 | F8: 64 | G8: 16 | H8: 98 | I8: 98 | J8: 67.9 | K8: 164 | L8: 25.2 | M8: Sarah Williams, DO | N8: Sitting
A9: VIT0032 | B9: P100003 | C9: 46188 | D9: 117 | E9: 72 | F9: 64 | G9: 16 | H9: 98 | I9: 98 | J9: 69 | K9: 164 | L9: 25.7 | M9: Sarah Williams, DO | N9: Sitting
A10: VIT0033 | B10: P100003 | C10: 46098 | D10: 118 | E10: 72 | F10: 64 | G10: 16 | H10: 98 | I10: 98 | J10: 70.1 | K10: 164 | L10: 26.1 | M10: Sarah Williams, DO | N10: Sitting
A11: VIT0041 | B11: P100004 | C11: 46277 | D11: 119 | E11: 74 | F11: 65 | G11: 17 | H11: 99 | I11: 98.2 | J11: 74.9 | K11: 180 | L11: 23.1 | M11: David Martinez, MD | N11: Sitting
A12: VIT0042 | B12: P100004 | C12: 46187 | D12: 120 | E12: 74 | F12: 65 | G12: 17 | H12: 99 | I12: 98.2 | J12: 76 | K12: 180 | L12: 23.5 | M12: David Martinez, MD | N12: Sitting
A13: VIT0043 | B13: P100004 | C13: 46097 | D13: 121 | E13: 74 | F13: 65 | G13: 17 | H13: 99 | I13: 98.2 | J13: 77.1 | K13: 180 | L13: 23.8 | M13: David Martinez, MD | N13: Sitting
... A151: VIT0503 | B151: P100050 | C151: 46051 | D151: 115 | E151: 70 | F151: 71 | G151: 18 | H151: 97 | I151: 98.4 | J151: 109.1 | K151: 189 | L151: 30.5 | M151: Michael Chen, MD | N151: Sitting

Sheet Labs
A1: Lab_ID | B1: Patient_ID | C1: Result_Date | D1: LOINC_Code | E1: Test_Name | F1: Result | G1: Unit | H1: Reference_Range | I1: Flag | J1: Status | K1: Performing_Lab | L1: Ordering_Provider
A2: LAB0011 | B2: P100001 | C2: 46249 | D2: 4548-4 | E2: Hemoglobin A1c | F2: 5.1 | G2: % | H2: 4.0-5.6 | I2: Normal | J2: Final | K2: Northstar Reference Lab | L2: Emily Carter, MD
A3: LAB0012 | B3: P100001 | C3: 46249 | D3: 2345-7 | E3: Glucose | F3: 84 | G3: mg/dL | H3: 70-99 | I3: Normal | J3: Final | K3: Northstar Reference Lab | L3: Emily Carter, MD
A4: LAB0013 | B4: P100001 | C4: 46249 | D4: 2093-3 | E4: Total cholesterol | F4: 155 | G4: mg/dL | H4: <200 | I4: Normal | J4: Final | K4: Northstar Reference Lab | L4: Emily Carter, MD
A5: LAB0014 | B5: P100001 | C5: 46249 | D5: 718-7 | E5: Hemoglobin | F5: 12.2 | G5: g/dL | H5: 12.0-17.5 | I5: Normal | J5: Final | K5: Northstar Reference Lab | L5: Emily Carter, MD
A6: LAB0015 | B6: P100001 | C6: 46249 | D6: 6690-2 | E6: WBC | F6: 4.6 | G6: 10^3/uL | H6: 4.0-11.0 | I6: Normal | J6: Final | K6: Northstar Reference Lab | L6: Emily Carter, MD
A7: LAB0021 | B7: P100002 | C7: 46250 | D7: 4548-4 | E7: Hemoglobin A1c | F7: 5.3 | G7: % | H7: 4.0-5.6 | I7: Normal | J7: Final | K7: Northstar Reference Lab | L7: Michael Chen, MD
A8: LAB0022 | B8: P100002 | C8: 46250 | D8: 2345-7 | E8: Glucose | F8: 89 | G8: mg/dL | H8: 70-99 | I8: Normal | J8: Final | K8: Northstar Reference Lab | L8: Michael Chen, MD
A9: LAB0023 | B9: P100002 | C9: 46250 | D9: 2093-3 | E9: Total cholesterol | F9: 161 | G9: mg/dL | H9: <200 | I9: Normal | J9: Final | K9: Northstar Reference Lab | L9: Michael Chen, MD
A10: LAB0024 | B10: P100002 | C10: 46250 | D10: 718-7 | E10: Hemoglobin | F10: 12.5 | G10: g/dL | H10: 12.0-17.5 | I10: Normal | J10: Final | K10: Northstar Reference Lab | L10: Michael Chen, MD
A11: LAB0025 | B11: P100002 | C11: 46250 | D11: 6690-2 | E11: WBC | F11: 5 | G11: 10^3/uL | H11: 4.0-11.0 | I11: Normal | J11: Final | K11: Northstar Reference Lab | L11: Michael Chen, MD
A12: LAB0031 | B12: P100003 | C12: 46251 | D12: 4548-4 | E12: Hemoglobin A1c | F12: 5.5 | G12: % | H12: 4.0-5.6 | I12: Normal | J12: Final | K12: Northstar Reference Lab | L12: Sarah Williams, DO
A13: LAB0032 | B13: P100003 | C13: 46251 | D13: 2345-7 | E13: Glucose | F13: 94 | G13: mg/dL | H13: 70-99 | I13: Normal | J13: Final | K13: Northstar Reference Lab | L13: Sarah Williams, DO
... A251: LAB0505 | B251: P100050 | C251: 46258 | D251: 6690-2 | E251: WBC | F251: 7.8 | G251: 10^3/uL | H251: 4.0-11.0 | I251: Normal | J251: Final | K251: Northstar Reference Lab | L251: Michael Chen, MD

Sheet Orders_Procedures
A1: Order_ID | B1: Patient_ID | C1: Encounter_ID | D1: Order_Date | E1: Order_Type | F1: CPT_HCPCS | G1: Order_Description | H1: Status | I1: Ordering_Provider | J1: Facility | K1: Priority
A2: ORD0001 | B2: P100001 | C2: ENC0011 | D2: 46285 | E2: Procedure | F2: 99214 | G2: Established patient office visit | H2: Completed | I2: Emily Carter, MD | J2: Northstar Medical Center | K2: Routine
A3: ORD0002 | B3: P100002 | C3: ENC0021 | D3: 46283 | E3: Procedure | F3: 93000 | G3: Electrocardiogram | H3: Completed | I3: Michael Chen, MD | J3: Northstar Downtown Clinic | K3: Routine
A4: ORD0003 | B4: P100003 | C4: ENC0031 | D4: 46281 | E4: Procedure | F4: 71046 | G4: Chest radiography | H4: Completed | I4: Sarah Williams, DO | J4: Northstar Westside Clinic | K4: Routine
A5: ORD0004 | B5: P100004 | C5: ENC0041 | D5: 46279 | E5: Procedure | F5: 80053 | G5: Comprehensive metabolic panel | H5: Completed | I5: David Martinez, MD | J5: Northstar Urgent Care | K5: Routine
A6: ORD0005 | B6: P100005 | C6: ENC0051 | D6: 46277 | E6: Procedure | F6: 99214 | G6: Established patient office visit | H6: Completed | I6: Rachel Kim, MD | J6: Northstar Medical Center | K6: Routine
A7: ORD0006 | B7: P100006 | C7: ENC0061 | D7: 46275 | E7: Procedure | F7: 93000 | G7: Electrocardiogram | H7: Completed | I7: James Wilson, NP | J7: Northstar Downtown Clinic | K7: Routine
A8: ORD0007 | B8: P100007 | C8: ENC0071 | D8: 46273 | E8: Procedure | F8: 71046 | G8: Chest radiography | H8: Completed | I8: Emily Carter, MD | J8: Northstar Westside Clinic | K8: Routine
A9: ORD0008 | B9: P100008 | C9: ENC0081 | D9: 46271 | E9: Procedure | F9: 80053 | G9: Comprehensive metabolic panel | H9: Completed | I9: Michael Chen, MD | J9: Northstar Urgent Care | K9: Routine
A10: ORD0009 | B10: P100009 | C10: ENC0091 | D10: 46269 | E10: Procedure | F10: 99214 | G10: Established patient office visit | H10: Completed | I10: Sarah Williams, DO | J10: Northstar Medical Center | K10: Routine
A11: ORD0010 | B11: P100010 | C11: ENC0101 | D11: 46267 | E11: Procedure | F11: 93000 | G11: Electrocardiogram | H11: Completed | I11: David Martinez, MD | J11: Northstar Downtown Clinic | K11: Routine
A12: ORD0011 | B12: P100011 | C12: ENC0111 | D12: 46265 | E12: Procedure | F12: 71046 | G12: Chest radiography | H12: Completed | I12: Rachel Kim, MD | J12: Northstar Westside Clinic | K12: Routine
A13: ORD0012 | B13: P100012 | C13: ENC0121 | D13: 46263 | E13: Procedure | F13: 80053 | G13: Comprehensive metabolic panel | H13: Completed | I13: James Wilson, NP | J13: Northstar Urgent Care | K13: Routine
... A51: ORD0050 | B51: P100050 | C51: ENC0501 | D51: 46187 | E51: Procedure | F51: 93000 | G51: Electrocardiogram | H51: Completed | I51: Michael Chen, MD | J51: Northstar Downtown Clinic | K51: Routine

Sheet Immunizations
A1: Immunization_ID | B1: Patient_ID | C1: Vaccine | D1: CVX_Code | E1: Administration_Date | F1: Dose | G1: Route | H1: Site | I1: Administered_By | J1: Lot_Number
A2: IMM0001 | B2: P100001 | C2: Influenza vaccine, quadrivalent | D2: 150 | E2: 45920 | F2: 0.5 mL | G2: IM | H2: Left deltoid | I2: Emily Carter, MD | J2: FLU-DEMO-001
A3: IMM0002 | B3: P100002 | C3: Influenza vaccine, quadrivalent | D3: 150 | E3: 45921 | F3: 0.5 mL | G3: IM | H3: Left deltoid | I3: Michael Chen, MD | J3: FLU-DEMO-002
A4: IMM0003 | B4: P100003 | C4: Influenza vaccine, quadrivalent | D4: 150 | E4: 45922 | F4: 0.5 mL | G4: IM | H4: Left deltoid | I4: Sarah Williams, DO | J4: FLU-DEMO-003
A5: IMM0004 | B5: P100004 | C5: Influenza vaccine, quadrivalent | D5: 150 | E5: 45923 | F5: 0.5 mL | G5: IM | H5: Left deltoid | I5: David Martinez, MD | J5: FLU-DEMO-004
A6: IMM0005 | B6: P100005 | C6: Influenza vaccine, quadrivalent | D6: 150 | E6: 45924 | F6: 0.5 mL | G6: IM | H6: Left deltoid | I6: Rachel Kim, MD | J6: FLU-DEMO-005
A7: IMM0006 | B7: P100006 | C7: Influenza vaccine, quadrivalent | D7: 150 | E7: 45925 | F7: 0.5 mL | G7: IM | H7: Left deltoid | I7: James Wilson, NP | J7: FLU-DEMO-006
A8: IMM0007 | B8: P100007 | C8: Influenza vaccine, quadrivalent | D8: 150 | E8: 45926 | F8: 0.5 mL | G8: IM | H8: Left deltoid | I8: Emily Carter, MD | J8: FLU-DEMO-007
A9: IMM0008 | B9: P100008 | C9: Influenza vaccine, quadrivalent | D9: 150 | E9: 45927 | F9: 0.5 mL | G9: IM | H9: Left deltoid | I9: Michael Chen, MD | J9: FLU-DEMO-008
A10: IMM0009 | B10: P100009 | C10: Influenza vaccine, quadrivalent | D10: 150 | E10: 45928 | F10: 0.5 mL | G10: IM | H10: Left deltoid | I10: Sarah Williams, DO | J10: FLU-DEMO-009
A11: IMM0010 | B11: P100010 | C11: Influenza vaccine, quadrivalent | D11: 150 | E11: 45929 | F11: 0.5 mL | G11: IM | H11: Left deltoid | I11: David Martinez, MD | J11: FLU-DEMO-010
A12: IMM0011 | B12: P100011 | C12: Influenza vaccine, quadrivalent | D12: 150 | E12: 45930 | F12: 0.5 mL | G12: IM | H12: Left deltoid | I12: Rachel Kim, MD | J12: FLU-DEMO-011
A13: IMM0012 | B13: P100012 | C13: Influenza vaccine, quadrivalent | D13: 150 | E13: 45931 | F13: 0.5 mL | G13: IM | H13: Left deltoid | I13: James Wilson, NP | J13: FLU-DEMO-012
... A51: IMM0050 | B51: P100050 | C51: Influenza vaccine, quadrivalent | D51: 150 | E51: 45924 | F51: 0.5 mL | G51: IM | H51: Left deltoid | I51: Michael Chen, MD | J51: FLU-DEMO-050

Sheet Appointments
A1: Appointment_ID | B1: Patient_ID | C1: Date | D1: Time | E1: Department | F1: Provider | G1: Location | H1: Status | I1: Reason | J1: Booked_Via
A2: APT0001 | B2: P100001 | C2: 46300 | D2: 08:30 | E2: Family Medicine | F2: Emily Carter, MD | G2: Northstar Medical Center | H2: Scheduled | I2: Chronic care follow-up | J2: MyChart
A3: APT0002 | B3: P100002 | C3: 46301 | D3: 09:30 | E3: Family Medicine | F3: Michael Chen, MD | G3: Northstar Downtown Clinic | H3: Scheduled | I3: Chronic care follow-up | J3: MyChart
A4: APT0003 | B4: P100003 | C4: 46302 | D4: 10:30 | E4: Family Medicine | F4: Sarah Williams, DO | G4: Northstar Westside Clinic | H4: Scheduled | I4: Chronic care follow-up | J4: MyChart
A5: APT0004 | B5: P100004 | C5: 46303 | D5: 11:30 | E5: Family Medicine | F5: David Martinez, MD | G5: Northstar Urgent Care | H5: Scheduled | I5: Chronic care follow-up | J5: MyChart
A6: APT0005 | B6: P100005 | C6: 46304 | D6: 12:30 | E6: Family Medicine | F6: Rachel Kim, MD | G6: Northstar Medical Center | H6: Scheduled | I6: Chronic care follow-up | J6: MyChart
A7: APT0006 | B7: P100006 | C7: 46305 | D7: 13:30 | E7: Family Medicine | F7: James Wilson, NP | G7: Northstar Downtown Clinic | H7: Scheduled | I7: Chronic care follow-up | J7: MyChart
A8: APT0007 | B8: P100007 | C8: 46306 | D8: 14:30 | E8: Family Medicine | F8: Emily Carter, MD | G8: Northstar Westside Clinic | H8: Scheduled | I8: Chronic care follow-up | J8: MyChart
A9: APT0008 | B9: P100008 | C9: 46307 | D9: 15:30 | E9: Family Medicine | F9: Michael Chen, MD | G9: Northstar Urgent Care | H9: Scheduled | I9: Chronic care follow-up | J9: MyChart
A10: APT0009 | B10: P100009 | C10: 46308 | D10: 16:30 | E10: Family Medicine | F10: Sarah Williams, DO | G10: Northstar Medical Center | H10: Scheduled | I10: Chronic care follow-up | J10: MyChart
A11: APT0010 | B11: P100010 | C11: 46309 | D11: 08:30 | E11: Family Medicine | F11: David Martinez, MD | G11: Northstar Downtown Clinic | H11: Scheduled | I11: Chronic care follow-up | J11: MyChart
A12: APT0011 | B12: P100011 | C12: 46310 | D12: 09:30 | E12: Family Medicine | F12: Rachel Kim, MD | G12: Northstar Westside Clinic | H12: Scheduled | I12: Chronic care follow-up | J12: MyChart
A13: APT0012 | B13: P100012 | C13: 46311 | D13: 10:30 | E13: Family Medicine | F13: James Wilson, NP | G13: Northstar Urgent Care | H13: Scheduled | I13: Chronic care follow-up | J13: MyChart
... A51: APT0050 | B51: P100050 | C51: 46324 | D51: 12:30 | E51: Family Medicine | F51: Michael Chen, MD | G51: Northstar Downtown Clinic | H51: Scheduled | I51: Chronic care follow-up | J51: MyChart

Sheet Clinical_Notes
A1: Note_ID | B1: Patient_ID | C1: Encounter_ID | D1: Note_Type | E1: Service_Date | F1: Author | G1: Note_Summary | H1: Status | I1: Data_Tag
A2: NOTE0001 | B2: P100001 | C2: ENC0011 | D2: Progress Note | E2: 46285 | F2: Emily Carter, MD | G2: Follow-up for essential hypertension. Medication reconciliation completed. Results, risks, and return precautions reviewed. | H2: Signed | I2: Synthetic summary
A3: NOTE0002 | B3: P100002 | C3: ENC0021 | D3: Progress Note | E3: 46283 | F3: Michael Chen, MD | G3: Follow-up for type 2 diabetes mellitus without complications. Medication reconciliation completed. Results, risks, and return precautions reviewed. | H3: Signed | I3: Synthetic summary
A4: NOTE0003 | B4: P100003 | C4: ENC0031 | D4: Progress Note | E4: 46281 | F4: Sarah Williams, DO | G4: Follow-up for hyperlipidemia, unspecified. Medication reconciliation completed. Results, risks, and return precautions reviewed. | H4: Signed | I4: Synthetic summary
A5: NOTE0004 | B5: P100004 | C5: ENC0041 | D5: Progress Note | E5: 46279 | F5: David Martinez, MD | G5: Follow-up for unspecified asthma, uncomplicated. Medication reconciliation completed. Results, risks, and return precautions reviewed. | H5: Signed | I5: Synthetic summary
A6: NOTE0005 | B6: P100005 | C6: ENC0051 | D6: Progress Note | E6: 46277 | F6: Rachel Kim, MD | G6: Follow-up for migraine, unspecified, not intractable. Medication reconciliation completed. Results, risks, and return precautions reviewed. | H6: Signed | I6: Synthetic summary
A7: NOTE0006 | B7: P100006 | C7: ENC0061 | D7: Progress Note | E7: 46275 | F7: James Wilson, NP | G7: Follow-up for osteoarthritis, right knee. Medication reconciliation completed. Results, risks, and return precautions reviewed. | H7: Signed | I7: Synthetic summary
A8: NOTE0007 | B8: P100007 | C8: ENC0071 | D8: Progress Note | E8: 46273 | F8: Emily Carter, MD | G8: Follow-up for anxiety disorder, unspecified. Medication reconciliation completed. Results, risks, and return precautions reviewed. | H8: Signed | I8: Synthetic summary
A9: NOTE0008 | B9: P100008 | C9: ENC0081 | D9: Progress Note | E9: 46271 | F9: Michael Chen, MD | G9: Follow-up for gastro-esophageal reflux disease without esophagitis. Medication reconciliation completed. Results, risks, and return precautions reviewed. | H9: Signed | I9: Synthetic summary
A10: NOTE0009 | B10: P100009 | C10: ENC0091 | D10: Progress Note | E10: 46269 | F10: Sarah Williams, DO | G10: Follow-up for hypothyroidism, unspecified. Medication reconciliation completed. Results, risks, and return precautions reviewed. | H10: Signed | I10: Synthetic summary
A11: NOTE0010 | B11: P100010 | C11: ENC0101 | D11: Progress Note | E11: 46267 | F11: David Martinez, MD | G11: Follow-up for atherosclerotic heart disease. Medication reconciliation completed. Results, risks, and return precautions reviewed. | H11: Signed | I11: Synthetic summary
A12: NOTE0011 | B12: P100011 | C12: ENC0111 | D12: Progress Note | E12: 46265 | F12: Rachel Kim, MD | G12: Follow-up for essential hypertension. Medication reconciliation completed. Results, risks, and return precautions reviewed. | H12: Signed | I12: Synthetic summary
A13: NOTE0012 | B13: P100012 | C13: ENC0121 | D13: Progress Note | E13: 46263 | F13: James Wilson, NP | G13: Follow-up for type 2 diabetes mellitus without complications. Medication reconciliation completed. Results, risks, and return precautions reviewed. | H13: Signed | I13: Synthetic summary
... A51: NOTE0050 | B51: P100050 | C51: ENC0501 | D51: Progress Note | E51: 46187 | F51: Michael Chen, MD | G51: Follow-up for atherosclerotic heart disease. Medication reconciliation completed. Results, risks, and return precautions reviewed. | H51: Signed | I51: Synthetic summary

Sheet Insurance
A1: Coverage_ID | B1: Patient_ID | C1: Priority | D1: Payer_Name | E1: Member_ID | F1: Group_Number | G1: Relationship_to_Subscriber | H1: Effective_Date | I1: Termination_Date | J1: Status | K1: Plan_Type | L1: Assigned_PCP | M1: Annual_Deductible_USD | N1: Copay_USD
A2: COV700001 | B2: P100001 | C2: Primary | D2: UnitedHealthcare Demo PPO | E2: MBR800001 | F2: GRP3000 | G2: Self | H2: 46023 | I2: 46387 | J2: Active | K2: PPO | L2: Emily Carter, MD | M2: 1500 | N2: 20
A3: COV700002 | B3: P100002 | C3: Primary | D3: Blue Cross Demo HMO | E3: MBR800002 | F3: GRP3001 | G3: Self | H3: 46023 | I3: 46387 | J3: Active | K3: HMO | L3: Michael Chen, MD | M3: 2000 | N3: 25
A4: COV700003 | B4: P100003 | C4: Primary | D4: Aetna Demo Choice POS | E4: MBR800003 | F4: GRP3002 | G4: Self | H4: 46023 | I4: 46387 | J4: Active | K4: POS | L4: Sarah Williams, DO | M4: 2500 | N4: 30
A5: COV700004 | B5: P100004 | C5: Primary | D5: Cigna Demo Open Access | E5: MBR800004 | F5: GRP3003 | G5: Self | H5: 46023 | I5: 46387 | J5: Active | K5: Medicare | L5: David Martinez, MD | M5: 3000 | N5: 20
A6: COV700005 | B6: P100005 | C6: Primary | D6: Medicare Demo | E6: MBR800005 | F6: GRP3004 | G6: Self | H6: 46023 | I6: 46387 | J6: Active | K6: Medicaid | L6: Rachel Kim, MD | M6: 1500 | N6: 25
A7: COV700006 | B7: P100006 | C7: Primary | D7: Medicaid Demo | E7: MBR800006 | F7: GRP3005 | G7: Self | H7: 46023 | I7: 46387 | J7: Active | K7: PPO | L7: James Wilson, NP | M7: 2000 | N7: 30
A8: COV700007 | B8: P100007 | C8: Primary | D8: UnitedHealthcare Demo PPO | E8: MBR800007 | F8: GRP3006 | G8: Self | H8: 46023 | I8: 46387 | J8: Active | K8: HMO | L8: Emily Carter, MD | M8: 2500 | N8: 20
A9: COV700008 | B9: P100008 | C9: Primary | D9: Blue Cross Demo HMO | E9: MBR800008 | F9: GRP3007 | G9: Self | H9: 46023 | I9: 46387 | J9: Active | K9: POS | L9: Michael Chen, MD | M9: 3000 | N9: 25
A10: COV700009 | B10: P100009 | C10: Primary | D10: Aetna Demo Choice POS | E10: MBR800009 | F10: GRP3008 | G10: Self | H10: 46023 | I10: 46387 | J10: Active | K10: Medicare | L10: Sarah Williams, DO | M10: 1500 | N10: 30
A11: COV700010 | B11: P100010 | C11: Primary | D11: Cigna Demo Open Access | E11: MBR800010 | F11: GRP3009 | G11: Self | H11: 46023 | I11: 46387 | J11: Active | K11: Medicaid | L11: David Martinez, MD | M11: 2000 | N11: 20
A12: COV700011 | B12: P100011 | C12: Primary | D12: Medicare Demo | E12: MBR800011 | F12: GRP3010 | G12: Self | H12: 46023 | I12: 46387 | J12: Active | K12: PPO | L12: Rachel Kim, MD | M12: 2500 | N12: 25
A13: COV700012 | B13: P100012 | C13: Primary | D13: Medicaid Demo | E13: MBR800012 | F13: GRP3011 | G13: Self | H13: 46023 | I13: 46387 | J13: Active | K13: HMO | L13: James Wilson, NP | M13: 3000 | N13: 30
... A51: COV700050 | B51: P100050 | C51: Primary | D51: Blue Cross Demo HMO | E51: MBR800050 | F51: GRP3001 | G51: Self | H51: 46023 | I51: 46387 | J51: Active | K51: Medicaid | L51: Michael Chen, MD | M51: 2000 | N51: 25

Sheet Billing_Claims
A1: Claim_ID | B1: Patient_ID | C1: Encounter_ID | D1: Service_Date | E1: CPT_HCPCS | F1: Description | G1: Units | H1: Charge_USD | I1: Contractual_Adjustment_USD | J1: Payment_USD | K1: Patient_Balance_USD | L1: Payer | M1: Claim_Status | N1: Currency
A2: CLM00001 | B2: P100001 | C2: ENC0011 | D2: 46285 | E2: 99214 | F2: Established patient office visit | G2: 1 | H2: 185 | I2: 40 | J2: 100 | K2: =H2-I2-J2 -> 45 | L2: UnitedHealthcare Demo PPO | M2: Paid | N2: USD
A3: CLM00002 | B3: P100002 | C3: ENC0021 | D3: 46283 | E3: 93000 | F3: Electrocardiogram | G3: 1 | H3: 210 | I3: 50 | J3: 115 | K3: =H3-I3-J3 -> 45 | L3: Blue Cross Demo HMO | M3: Submitted | N3: USD
A4: CLM00003 | B4: P100003 | C4: ENC0031 | D4: 46281 | E4: 71046 | F4: Chest radiography | G4: 1 | H4: 235 | I4: 60 | J4: 130 | K4: =H4-I4-J4 -> 45 | L4: Aetna Demo Choice POS | M4: Pending | N4: USD
A5: CLM00004 | B5: P100004 | C5: ENC0041 | D5: 46279 | E5: 80053 | F5: Comprehensive metabolic panel | G5: 1 | H5: 260 | I5: 70 | J5: 145 | K5: =H5-I5-J5 -> 45 | L5: Cigna Demo Open Access | M5: Paid | N5: USD
A6: CLM00005 | B6: P100005 | C6: ENC0051 | D6: 46277 | E6: 99214 | F6: Established patient office visit | G6: 1 | H6: 285 | I6: 40 | J6: 160 | K6: =H6-I6-J6 -> 85 | L6: Medicare Demo | M6: Submitted | N6: USD
A7: CLM00006 | B7: P100006 | C7: ENC0061 | D7: 46275 | E7: 93000 | F7: Electrocardiogram | G7: 1 | H7: 310 | I7: 50 | J7: 100 | K7: =H7-I7-J7 -> 160 | L7: Medicaid Demo | M7: Pending | N7: USD
A8: CLM00007 | B8: P100007 | C8: ENC0071 | D8: 46273 | E8: 71046 | F8: Chest radiography | G8: 1 | H8: 335 | I8: 60 | J8: 115 | K8: =H8-I8-J8 -> 160 | L8: UnitedHealthcare Demo PPO | M8: Paid | N8: USD
A9: CLM00008 | B9: P100008 | C9: ENC0081 | D9: 46271 | E9: 80053 | F9: Comprehensive metabolic panel | G9: 1 | H9: 360 | I9: 70 | J9: 130 | K9: =H9-I9-J9 -> 160 | L9: Blue Cross Demo HMO | M9: Submitted | N9: USD
A10: CLM00009 | B10: P100009 | C10: ENC0091 | D10: 46269 | E10: 99214 | F10: Established patient office visit | G10: 1 | H10: 185 | I10: 40 | J10: 145 | K10: =H10-I10-J10 -> 0 | L10: Aetna Demo Choice POS | M10: Pending | N10: USD
A11: CLM00010 | B11: P100010 | C11: ENC0101 | D11: 46267 | E11: 93000 | F11: Electrocardiogram | G11: 1 | H11: 210 | I11: 50 | J11: 160 | K11: =H11-I11-J11 -> 0 | L11: Cigna Demo Open Access | M11: Paid | N11: USD
A12: CLM00011 | B12: P100011 | C12: ENC0111 | D12: 46265 | E12: 71046 | F12: Chest radiography | G12: 1 | H12: 235 | I12: 60 | J12: 100 | K12: =H12-I12-J12 -> 75 | L12: Medicare Demo | M12: Submitted | N12: USD
A13: CLM00012 | B13: P100012 | C13: ENC0121 | D13: 46263 | E13: 80053 | F13: Comprehensive metabolic panel | G13: 1 | H13: 260 | I13: 70 | J13: 115 | K13: =H13-I13-J13 -> 75 | L13: Medicaid Demo | M13: Pending | N13: USD
... A51: CLM00050 | B51: P100050 | C51: ENC0501 | D51: 46187 | E51: 93000 | F51: Electrocardiogram | G51: 1 | H51: 210 | I51: 50 | J51: 160 | K51: =H51-I51-J51 -> 0 | L51: Blue Cross Demo HMO | M51: Submitted | N51: USD

Sheet Consent_Directives
A1: Patient_ID | B1: Consent_Type | C1: Status | D1: Effective_Date | E1: Expiration_Date | F1: Capture_Method | G1: Privacy_Notice | H1: Portal_Consent | I1: Advance_Directive_On_File | J1: Code_Status
A2: P100001 | B2: General Treatment Consent | C2: Active | D2: 46023 | E2: 46388 | F2: Electronic signature | G2: Acknowledged | H2: Active | I2: Yes | J2: Advance directive on file
A3: P100002 | B3: General Treatment Consent | C3: Active | D3: 46023 | E3: 46388 | F3: Electronic signature | G3: Acknowledged | H3: Active | I3: No | J3: Full Code
A4: P100003 | B4: General Treatment Consent | C4: Active | D4: 46023 | E4: 46388 | F4: Electronic signature | G4: Acknowledged | H4: Active | I4: No | J4: Full Code
A5: P100004 | B5: General Treatment Consent | C5: Active | D5: 46023 | E5: 46388 | F5: Electronic signature | G5: Acknowledged | H5: Active | I5: No | J5: Full Code
A6: P100005 | B6: General Treatment Consent | C6: Active | D6: 46023 | E6: 46388 | F6: Electronic signature | G6: Acknowledged | H6: Active | I6: No | J6: Full Code
A7: P100006 | B7: General Treatment Consent | C7: Active | D7: 46023 | E7: 46388 | F7: Electronic signature | G7: Acknowledged | H7: Active | I7: No | J7: Full Code
A8: P100007 | B8: General Treatment Consent | C8: Active | D8: 46023 | E8: 46388 | F8: Electronic signature | G8: Acknowledged | H8: Active | I8: No | J8: Full Code
A9: P100008 | B9: General Treatment Consent | C9: Active | D9: 46023 | E9: 46388 | F9: Electronic signature | G9: Acknowledged | H9: Active | I9: No | J9: Full Code
A10: P100009 | B10: General Treatment Consent | C10: Active | D10: 46023 | E10: 46388 | F10: Electronic signature | G10: Acknowledged | H10: Active | I10: Yes | J10: Advance directive on file
A11: P100010 | B11: General Treatment Consent | C11: Active | D11: 46023 | E11: 46388 | F11: Electronic signature | G11: Acknowledged | H11: Active | I11: No | J11: Full Code
A12: P100011 | B12: General Treatment Consent | C12: Active | D12: 46023 | E12: 46388 | F12: Electronic signature | G12: Acknowledged | H12: Active | I12: No | J12: Full Code
A13: P100012 | B13: General Treatment Consent | C13: Active | D13: 46023 | E13: 46388 | F13: Electronic signature | G13: Acknowledged | H13: Active | I13: No | J13: Full Code
... A51: P100050 | B51: General Treatment Consent | C51: Active | D51: 46023 | E51: 46388 | F51: Electronic signature | G51: Acknowledged | H51: Active | I51: No | J51: Full Code

Sheet Care_Team
A1: Care_Team_ID | B1: Patient_ID | C1: Provider | D1: Specialty | E1: Role | F1: Status | G1: Start_Date | H1: Organization
A2: CT0001A | B2: P100001 | C2: Emily Carter, MD | D2: Primary Care | E2: PCP | F2: Active | G2: 45292 | H2: Northstar Health
A3: CT0001B | B3: P100001 | C3: Sarah Williams, DO | D3: Cardiology | E3: Consulting | F3: Active | G3: 45809 | H3: Northstar Health
A4: CT0002A | B4: P100002 | C4: Michael Chen, MD | D4: Primary Care | E4: PCP | F4: Active | G4: 45292 | H4: Northstar Health
A5: CT0002B | B5: P100002 | C5: David Martinez, MD | D5: Pulmonology | E5: Consulting | F5: Active | G5: 45809 | H5: Northstar Health
A6: CT0003A | B6: P100003 | C6: Sarah Williams, DO | D6: Primary Care | E6: PCP | F6: Active | G6: 45292 | H6: Northstar Health
A7: CT0003B | B7: P100003 | C7: Rachel Kim, MD | D7: Endocrinology | E7: Consulting | F7: Active | G7: 45809 | H7: Northstar Health
A8: CT0004A | B8: P100004 | C8: David Martinez, MD | D8: Primary Care | E8: PCP | F8: Active | G8: 45292 | H8: Northstar Health
A9: CT0004B | B9: P100004 | C9: James Wilson, NP | D9: Cardiology | E9: Consulting | F9: Active | G9: 45809 | H9: Northstar Health
A10: CT0005A | B10: P100005 | C10: Rachel Kim, MD | D10: Primary Care | E10: PCP | F10: Active | G10: 45292 | H10: Northstar Health
A11: CT0005B | B11: P100005 | C11: Emily Carter, MD | D11: Pulmonology | E11: Consulting | F11: Active | G11: 45809 | H11: Northstar Health
A12: CT0006A | B12: P100006 | C12: James Wilson, NP | D12: Primary Care | E12: PCP | F12: Active | G12: 45292 | H12: Northstar Health
A13: CT0006B | B13: P100006 | C13: Michael Chen, MD | D13: Endocrinology | E13: Consulting | F13: Active | G13: 45809 | H13: Northstar Health
... A101: CT0050B | B101: P100050 | C101: David Martinez, MD | D101: Pulmonology | E101: Consulting | F101: Active | G101: 45809 | H101: Northstar Health

Sheet Family_Social_Hx
A1: Patient_ID | B1: Family_Member | C1: Family_Condition | D1: Family_Status | E1: Tobacco_Use | F1: Alcohol_Use | G1: Recreational_Drug_Use | H1: Physical_Activity | I1: Occupation | J1: Housing_Status | K1: Social_Risk
A2: P100001 | B2: Mother | C2: Type 2 diabetes | D2: Deceased | E2: Former | F2: Social | G2: No | H2: 60 min/week | I2: Engineer | J2: Stable housing | K2: Moderate
A3: P100002 | B3: Father | C3: Hypertension | D3: Living | E3: Never | F3: None | G3: No | H3: 150 min/week | I3: Teacher | J3: Stable housing | K3: Low
A4: P100003 | B4: Mother | C4: Hypertension | D4: Living | E4: Never | F4: None | G4: No | H4: 60 min/week | I4: Student | J4: Stable housing | K4: Low
A5: P100004 | B5: Father | C5: Type 2 diabetes | D5: Living | E5: Never | F5: Social | G5: No | H5: 150 min/week | I5: Retired | J5: Stable housing | K5: Low
A6: P100005 | B6: Mother | C6: Hypertension | D6: Living | E6: Former | F6: None | G6: No | H6: 60 min/week | I6: Healthcare worker | J6: Stable housing | K6: Low
A7: P100006 | B7: Father | C7: Hypertension | D7: Deceased | E7: Never | F7: None | G7: No | H7: 150 min/week | I7: Engineer | J7: Stable housing | K7: Low
A8: P100007 | B8: Mother | C8: Type 2 diabetes | D8: Living | E8: Never | F8: Social | G8: No | H8: 60 min/week | I8: Teacher | J8: Stable housing | K8: Low
A9: P100008 | B9: Father | C9: Hypertension | D9: Living | E9: Never | F9: None | G9: No | H9: 150 min/week | I9: Student | J9: Stable housing | K9: Moderate
A10: P100009 | B10: Mother | C10: Hypertension | D10: Living | E10: Former | F10: None | G10: No | H10: 60 min/week | I10: Retired | J10: Stable housing | K10: Low
A11: P100010 | B11: Father | C11: Type 2 diabetes | D11: Living | E11: Never | F11: Social | G11: No | H11: 150 min/week | I11: Healthcare worker | J11: Stable housing | K11: Low
A12: P100011 | B12: Mother | C12: Hypertension | D12: Deceased | E12: Never | F12: None | G12: No | H12: 60 min/week | I12: Engineer | J12: Stable housing | K12: Low
... A51: P100050 | B51: Father | C51: Hypertension | D51: Living | E51: Never | F51: None | G51: No | H51: 150 min/week | I51: Healthcare worker | J51: Stable housing | K51: Moderate

Sheet Population_Dashboard
A1: Northstar Health | Synthetic Population Dashboard
A4: Patients | B4: =COUNTA(Patient_Master!A:A)-1 -> 50 | D4: Encounter Type | E4: Count
A5: Active Problems | B5: =COUNTIF(Problems!E:E,"Active") -> 67 | D5: Office Visit | E5: =COUNTIF(Encounters!D:D,D5) -> 50
A6: Abnormal Labs | B6: =COUNTIF(Labs!I:I,"High") -> 88 | D6: Annual Wellness | E6: =COUNTIF(Encounters!D:D,D6) -> 87
A7: Open Patient Balance | B7: =SUM(Billing_Claims!K:K) -> 4245 | D7: Emergency | E7: =COUNTIF(Encounters!D:D,D7) -> 13

Sheet Data_Dictionary
A1: Sheet | B1: Field | C1: Business_Description | D1: Conceptual_FHIR_Mapping | E1: Note
A2: Patient_Master | B2: Patient_ID | C2: Patient ID | D2: FHIR Patient | E2: Synthetic demo field
A3: Patient_Master | B3: MRN | C3: MRN | D3: FHIR Patient | E3: Synthetic demo field
A4: Patient_Master | B4: First_Name | C4: First Name | D4: FHIR Patient | E4: Synthetic demo field
A5: Patient_Master | B5: Last_Name | C5: Last Name | D5: FHIR Patient | E5: Synthetic demo field
A6: Patient_Master | B6: Legal_Name | C6: Legal Name | D6: FHIR Patient | E6: Synthetic demo field
A7: Patient_Master | B7: DOB | C7: DOB | D7: FHIR Patient | E7: Synthetic demo field
A8: Patient_Master | B8: Age | C8: Age | D8: FHIR Patient | E8: Synthetic demo field
A9: Patient_Master | B9: Sex_at_Birth | C9: Sex at Birth | D9: FHIR Patient | E9: Synthetic demo field
A10: Patient_Master | B10: Pronouns | C10: Pronouns | D10: FHIR Patient | E10: Synthetic demo field
A11: Patient_Master | B11: Marital_Status | C11: Marital Status | D11: FHIR Patient | E11: Synthetic demo field
A12: Patient_Master | B12: Race | C12: Race | D12: FHIR Patient | E12: Synthetic demo field
... A194: Family_Social_Hx | B194: Social_Risk | C194: Social Risk | D194: FHIR FamilyMemberHistory / Observation | E194: Synthetic demo field

Sheet Sources
A1: Source | B1: URL | C1: Purpose
A2: Epic on FHIR | B2: https://fhir.epic.com/ | C2: Public documentation for Epic-supported FHIR resources and interoperability context
A3: Epic on FHIR FAQ | B3: https://fhir.epic.com/FAQ | C3: Public overview of Epic FHIR and USCDI support
A4: HL7 FHIR R4 | B4: https://hl7.org/fhir/R4/ | C4: Common healthcare resource structures
A5: US Core | B5: https://hl7.org/fhir/us/core/ | C5: U.S. patient and clinical interoperability profiles
