Workbook

Sheet README
A1: Original Hospital Revenue Cycle Charge Demo
A2: Independent synthetic demonstration workbook. It is not an Epic product, replica, extract, or proprietary build.
A3: Purpose
A4: Provides an original hospital revenue-cycle dataset with payer-specific pricing for Athena Health Insurance and Care Gap Health. | B4: Provides an original hospital revenue-cycle dataset with separate inpatient and outpatient charge-detail views, CDM controls, routing, billing edits, contracts, governance, and auditability.
A5: Epic alignment | B5: Uses common US hospital billing concepts such as hospital accounts, charge routing, workqueues, facility/professional split, institutional claims, and reimbursement. No proprietary EHR design is reproduced.
A6: Primary sheets | B6: CDM Master; IPD Encounter; Charge Router Rules; Claim Edits; Payer Contracts; Price Transparency; Governance; Audit Trail; Data Source Map; Data Dictionary; Dashboard.
A7: Color convention | B7: Blue = editable input; black = formula/derived; green = linked/imported; gray = static reference; orange = review; red = error/hold; purple = control logic; teal = KPI/visualization.
A8: Data disclaimer | B8: All patients, payers, prices, contracts, identifiers, effective dates, and operational scenarios are synthetic. No PHI is included.
A9: Sources | B9: Epic public financial interface documentation: https://open.epic.com/Financial/Billing CMS Hospital Price Transparency: https://www.cms.gov/priorities/key-initiatives/hospital-price-transparency CMS technical implementation guide: https://github.com/CMSgov/hospital-price-transparency

Sheet Charge Summary
A1: IPD and OPD Charge Summary
A2: Executive comparison of 420 payer-priced charge rows: 220 IPD and 200 OPD.
A4: Setting | B4: Charge Lines | C4: Gross Charges ($) | D4: Expected Allowed ($) | E4: Patient Responsibility ($) | F4: Adjustments ($) | G4: Held Charges | H4: Review Edits
A5: IPD | B5: =COUNTA('IPD Charges'!A5:A500) | C5: =SUM('IPD Charges'!O:O) | D5: =SUM('IPD Charges'!P:P) | E5: =SUM('IPD Charges'!Q:Q) | F5: =SUM('IPD Charges'!R:R) | G5: =COUNTIF('IPD Charges'!Z:Z,"Hold") | H5: =COUNTIF('IPD Charges'!AB:AB,"Review")
A6: OPD | B6: =COUNTA('OPD Charges'!A5:A500) | C6: =SUM('OPD Charges'!O:O) | D6: =SUM('OPD Charges'!P:P) | E6: =SUM('OPD Charges'!Q:Q) | F6: =SUM('OPD Charges'!R:R) | G6: =COUNTIF('OPD Charges'!Z:Z,"Hold") | H6: =COUNTIF('OPD Charges'!AB:AB,"Review")
A7: TOTAL | B7: =SUM(B5:B6) | C7: =SUM(C5:C6) | D7: =SUM(D5:D6) | E7: =SUM(E5:E6) | F7: =SUM(F5:F6) | G7: =SUM(G5:G6) | H7: =SUM(H5:H6)

Sheet Payer Pricing Comparison
A1: Payer Pricing Comparison
A2: Care Gap Health negotiated allowed amounts are 10% lower than Athena for every IPD and OPD charge line.
A4: Setting | B4: Original Services | C4: Athena Rows | D4: Care Gap Rows | E4: Total Rows | F4: Athena Pricing | G4: Care Gap Pricing | H4: Patient Coinsurance
A5: IPD | B5: 110 | C5: 110 | D5: 110 | E5: 220 | F5: Original allowed amount | G5: 10% below Athena | H5: Athena 20% / Care Gap 15%
A6: OPD | B6: 100 | C6: 100 | D6: 100 | E6: 200 | F6: Original allowed amount | G6: 10% below Athena | H6: Athena 20% / Care Gap 15%
A7: TOTAL | B7: =SUM(B5:B6) | C7: =SUM(C5:C6) | D7: =SUM(D5:D6) | E7: =SUM(E5:E6)

Sheet IPD Charges
A1: Inpatient Charge Detail
A2: 110 original synthetic inpatient charge lines, each represented for Athena Health Insurance and Care Gap Health (220 payer-priced rows).
A4: Charge Line ID | B4: Patient Account | C4: Encounter ID | D4: Patient Class | E4: Facility | F4: Department | G4: Service Date | H4: Charge Code | I4: Charge Description | J4: Revenue Code | K4: CPT/HCPCS | L4: Modifier | M4: Quantity | N4: Unit Charge ($) | O4: Extended Gross ($) | P4: Expected Allowed ($) | Q4: Patient Responsibility ($) | R4: Contractual Adjustment ($) | S4: Payer | T4: Plan | U4: Authorization ID | V4: Ordering Provider | W4: Performing Provider | X4: Source System | Y4: Charge Trigger | Z4: Charge Status | AA4: Reconciliation Status | AB4: Claim Edit Status | AC4: Workqueue | AD4: Medical Necessity | AE4: Diagnosis Link | AF4: Place of Service | AG4: Posting Date/Time | AH4: Notes
A5: IPD-CHG-0001-ATH | B5: HAR-202600001-ATH | C5: CSN-IPD-780001-ATH | D5: Inpatient | E5: Demo Regional Medical Center | F5: Accommodation | G5: 2026-09-02 | H5: RM-SEMI-DAY | I5: Semiprivate Medical/Surgical Room | J5: 0120 | M5: 1 | N5: 3500 | O5: =M5*N5 | P5: 1496.26 | Q5: =P5*20% | R5: =O5-P5 | S5: Athena Health Insurance | T5: Athena PPO | V5: Eleanor Brooks, MD | W5: Assigned Department Provider | X5: ADT | Y5: Midnight census | Z5: Posted | AA5: Matched | AB5: Passed | AD5: N/A | AE5: M17.11 | AF5: 21 | AG5: 2026-09-02 16:30 | AH5: Synthetic Athena negotiated charge
A6: IPD-CHG-0001-CGH | B6: HAR-202600001-CGH | C6: CSN-IPD-780001-CGH | D6: Inpatient | E6: Demo Regional Medical Center | F6: Accommodation | G6: 2026-09-02 | H6: RM-SEMI-DAY | I6: Semiprivate Medical/Surgical Room | J6: 0120 | M6: 1 | N6: 3500 | O6: =M6*N6 | P6: 1346.63 | Q6: =P6*15% | R6: =O6-P6 | S6: Care Gap Health | T6: Care Gap Value PPO | V6: Eleanor Brooks, MD | W6: Assigned Department Provider | X6: ADT | Y6: Midnight census | Z6: Posted | AA6: Matched | AB6: Passed | AD6: N/A | AE6: M17.11 | AF6: 21 | AG6: 2026-09-02 16:30 | AH6: Synthetic Care Gap charge; 10% below Athena allowed amount
A7: IPD-CHG-0002-ATH | B7: HAR-202600002-ATH | C7: CSN-IPD-780002-ATH | D7: Inpatient | E7: Demo Regional Medical Center | F7: Accommodation | G7: 2026-09-03 | H7: RM-PRIV-DAY | I7: Private Medical/Surgical Room | J7: 0110 | M7: 3 | N7: 4600 | O7: =M7*N7 | P7: 6809.85 | Q7: =P7*20% | R7: =O7-P7 | S7: Athena Health Insurance | T7: Athena PPO | V7: Eleanor Brooks, MD | W7: Assigned Department Provider | X7: ADT | Y7: Midnight census | Z7: Posted | AA7: Matched | AB7: Passed | AD7: N/A | AE7: M17.11 | AF7: 21 | AG7: 2026-09-03 16:30 | AH7: Synthetic Athena negotiated charge
A8: IPD-CHG-0002-CGH | B8: HAR-202600002-CGH | C8: CSN-IPD-780002-CGH | D8: Inpatient | E8: Demo Regional Medical Center | F8: Accommodation | G8: 2026-09-03 | H8: RM-PRIV-DAY | I8: Private Medical/Surgical Room | J8: 0110 | M8: 3 | N8: 4600 | O8: =M8*N8 | P8: 6128.87 | Q8: =P8*15% | R8: =O8-P8 | S8: Care Gap Health | T8: Care Gap Value PPO | V8: Eleanor Brooks, MD | W8: Assigned Department Provider | X8: ADT | Y8: Midnight census | Z8: Posted | AA8: Matched | AB8: Passed | AD8: N/A | AE8: M17.11 | AF8: 21 | AG8: 2026-09-03 16:30 | AH8: Synthetic Care Gap charge; 10% below Athena allowed amount
A9: IPD-CHG-0003-ATH | B9: HAR-202600003-ATH | C9: CSN-IPD-780003-ATH | D9: Inpatient | E9: Demo Regional Medical Center | F9: Intensive Care | G9: 2026-09-04 | H9: ICU-DAY | I9: Intensive Care Unit Room | J9: 0200 | M9: 2 | N9: 8200 | O9: =M9*N9 | P9: 10511.44 | Q9: =P9*20% | R9: =O9-P9 | S9: Athena Health Insurance | T9: Athena PPO | V9: Eleanor Brooks, MD | W9: Assigned Department Provider | X9: ADT | Y9: Midnight census | Z9: Posted | AA9: Matched | AB9: Passed | AD9: N/A | AE9: J96.01 | AF9: 21 | AG9: 2026-09-04 16:30 | AH9: Synthetic Athena negotiated charge
A10: IPD-CHG-0003-CGH | B10: HAR-202600003-CGH | C10: CSN-IPD-780003-CGH | D10: Inpatient | E10: Demo Regional Medical Center | F10: Intensive Care | G10: 2026-09-04 | H10: ICU-DAY | I10: Intensive Care Unit Room | J10: 0200 | M10: 2 | N10: 8200 | O10: =M10*N10 | P10: 9460.3 | Q10: =P10*15% | R10: =O10-P10 | S10: Care Gap Health | T10: Care Gap Value PPO | V10: Eleanor Brooks, MD | W10: Assigned Department Provider | X10: ADT | Y10: Midnight census | Z10: Posted | AA10: Matched | AB10: Passed | AD10: N/A | AE10: J96.01 | AF10: 21 | AG10: 2026-09-04 16:30 | AH10: Synthetic Care Gap charge; 10% below Athena allowed amount
A11: IPD-CHG-0004-ATH | B11: HAR-202600004-ATH | C11: CSN-IPD-780004-ATH | D11: Inpatient | E11: Demo Regional Medical Center | F11: Operating Room | G11: 2026-09-05 | H11: OR-MAJOR-1H | I11: Major Operating Room, First Hour | J11: 0360 | M11: 1 | N11: 10250 | O11: =M11*N11 | P11: 6120.76 | Q11: =P11*20% | R11: =O11-P11 | S11: Athena Health Insurance | T11: Athena PPO | V11: Eleanor Brooks, MD | W11: Assigned Department Provider | X11: Perioperative | Y11: Procedure end | Z11: Posted | AA11: Matched | AB11: Passed | AD11: Procedure-specific | AE11: M17.11 | AF11: 21 | AG11: 2026-09-05 16:30 | AH11: Synthetic Athena negotiated charge
A12: IPD-CHG-0004-CGH | B12: HAR-202600004-CGH | C12: CSN-IPD-780004-CGH | D12: Inpatient | E12: Demo Regional Medical Center | F12: Operating Room | G12: 2026-09-05 | H12: OR-MAJOR-1H | I12: Major Operating Room, First Hour | J12: 0360 | M12: 1 | N12: 10250 | O12: =M12*N12 | P12: 5508.68 | Q12: =P12*15% | R12: =O12-P12 | S12: Care Gap Health | T12: Care Gap Value PPO | V12: Eleanor Brooks, MD | W12: Assigned Department Provider | X12: Perioperative | Y12: Procedure end | Z12: Posted | AA12: Matched | AB12: Passed | AD12: Procedure-specific | AE12: M17.11 | AF12: 21 | AG12: 2026-09-05 16:30 | AH12: Synthetic Care Gap charge; 10% below Athena allowed amount
A13: IPD-CHG-0005-ATH | B13: HAR-202600005-ATH | C13: CSN-IPD-780005-ATH | D13: Inpatient | E13: Demo Regional Medical Center | F13: Operating Room | G13: 2026-09-06 | H13: OR-ADD-15 | I13: Operating Room, Additional 15 Minutes | J13: 0360 | M13: 2 | N13: 1280 | O13: =M13*N13 | P13: 1098.08 | Q13: =P13*20% | R13: =O13-P13 | S13: Athena Health Insurance | T13: Athena PPO | V13: Eleanor Brooks, MD | W13: Assigned Department Provider | X13: Perioperative | Y13: Procedure end | Z13: Posted | AA13: Matched | AB13: Passed | AD13: Procedure-specific | AE13: M17.11 | AF13: 21 | AG13: 2026-09-06 16:30 | AH13: Synthetic Athena negotiated charge
A14: IPD-CHG-0005-CGH | B14: HAR-202600005-CGH | C14: CSN-IPD-780005-CGH | D14: Inpatient | E14: Demo Regional Medical Center | F14: Operating Room | G14: 2026-09-06 | H14: OR-ADD-15 | I14: Operating Room, Additional 15 Minutes | J14: 0360 | M14: 2 | N14: 1280 | O14: =M14*N14 | P14: 988.27 | Q14: =P14*15% | R14: =O14-P14 | S14: Care Gap Health | T14: Care Gap Value PPO | V14: Eleanor Brooks, MD | W14: Assigned Department Provider | X14: Perioperative | Y14: Procedure end | Z14: Posted | AA14: Matched | AB14: Passed | AD14: Procedure-specific | AE14: M17.11 | AF14: 21 | AG14: 2026-09-06 16:30 | AH14: Synthetic Care Gap charge; 10% below Athena allowed amount
A15: IPD-CHG-0006-ATH | B15: HAR-202600006-ATH | C15: CSN-IPD-780006-ATH | D15: Inpatient | E15: Demo Regional Medical Center | F15: Recovery Room | G15: 2026-09-07 | H15: PACU-1H | I15: Post-Anesthesia Care, First Hour | J15: 0710 | M15: 1 | N15: 2100 | O15: =M15*N15 | P15: 1019.74 | Q15: =P15*20% | R15: =O15-P15 | S15: Athena Health Insurance | T15: Athena PPO | V15: Eleanor Brooks, MD | W15: Assigned Department Provider | X15: Perioperative | Y15: PACU discharge | Z15: Posted | AA15: Matched | AB15: Passed | AD15: N/A | AE15: Z47.1 | AF15: 21 | AG15: 2026-09-07 16:30 | AH15: Synthetic Athena negotiated charge
A16: IPD-CHG-0006-CGH | B16: HAR-202600006-CGH | C16: CSN-IPD-780006-CGH | D16: Inpatient | E16: Demo Regional Medical Center | F16: Recovery Room | G16: 2026-09-07 | H16: PACU-1H | I16: Post-Anesthesia Care, First Hour | J16: 0710 | M16: 1 | N16: 2100 | O16: =M16*N16 | P16: 917.77 | Q16: =P16*15% | R16: =O16-P16 | S16: Care Gap Health | T16: Care Gap Value PPO | V16: Eleanor Brooks, MD | W16: Assigned Department Provider | X16: Perioperative | Y16: PACU discharge | Z16: Posted | AA16: Matched | AB16: Passed | AD16: N/A | AE16: Z47.1 | AF16: 21 | AG16: 2026-09-07 16:30 | AH16: Synthetic Care Gap charge; 10% below Athena allowed amount
A17: IPD-CHG-0007-ATH | B17: HAR-202600007-ATH | C17: CSN-IPD-780007-ATH | D17: Inpatient | E17: Demo Regional Medical Center | F17: Surgical Supplies | G17: 2026-09-08 | H17: SUP-MAJOR-PACK | I17: Major Surgery Disposable Supply Pack | J17: 0270 | M17: 1 | N17: 4200 | O17: =M17*N17 | P17: 2400.75 | Q17: =P17*20% | R17: =O17-P17 | S17: Athena Health Insurance | T17: Athena PPO | V17: Eleanor Brooks, MD | W17: Assigned Department Provider | X17: Inventory | Y17: Supply issue | Z17: Posted | AA17: Matched | AB17: Passed | AD17: Contract rule | AE17: Z47.1 | AF17: 21 | AG17: 2026-09-08 16:30 | AH17: Synthetic Athena negotiated charge
A18: IPD-CHG-0007-CGH | B18: HAR-202600007-CGH | C18: CSN-IPD-780007-CGH | D18: Inpatient | E18: Demo Regional Medical Center | F18: Surgical Supplies | G18: 2026-09-08 | H18: SUP-MAJOR-PACK | I18: Major Surgery Disposable Supply Pack | J18: 0270 | M18: 1 | N18: 4200 | O18: =M18*N18 | P18: 2160.68 | Q18: =P18*15% | R18: =O18-P18 | S18: Care Gap Health | T18: Care Gap Value PPO | V18: Eleanor Brooks, MD | W18: Assigned Department Provider | X18: Inventory | Y18: Supply issue | Z18: Posted | AA18: Matched | AB18: Passed | AD18: Contract rule | AE18: Z47.1 | AF18: 21 | AG18: 2026-09-08 16:30 | AH18: Synthetic Care Gap charge; 10% below Athena allowed amount
A19: IPD-CHG-0008-ATH | B19: HAR-202600008-ATH | C19: CSN-IPD-780008-ATH | D19: Inpatient | E19: Demo Regional Medical Center | F19: Implants | G19: 2026-09-09 | H19: IMP-KNEE-CEM | I19: Cemented Knee Implant System | J19: 0278 | M19: 1 | N19: 20500 | O19: =M19*N19 | P19: 8773.2 | Q19: =P19*20% | R19: =O19-P19 | S19: Athena Health Insurance | T19: Athena PPO | V19: Eleanor Brooks, MD | W19: Assigned Department Provider | X19: Inventory | Y19: Implant scan | Z19: Posted | AA19: Matched | AB19: Passed | AD19: Contract rule | AE19: M17.11 | AF19: 21 | AG19: 2026-09-09 16:30 | AH19: Synthetic Athena negotiated charge
A20: IPD-CHG-0008-CGH | B20: HAR-202600008-CGH | C20: CSN-IPD-780008-CGH | D20: Inpatient | E20: Demo Regional Medical Center | F20: Implants | G20: 2026-09-09 | H20: IMP-KNEE-CEM | I20: Cemented Knee Implant System | J20: 0278 | M20: 1 | N20: 20500 | O20: =M20*N20 | P20: 7895.88 | Q20: =P20*15% | R20: =O20-P20 | S20: Care Gap Health | T20: Care Gap Value PPO | V20: Eleanor Brooks, MD | W20: Assigned Department Provider | X20: Inventory | Y20: Implant scan | Z20: Posted | AA20: Matched | AB20: Passed | AD20: Contract rule | AE20: M17.11 | AF20: 21 | AG20: 2026-09-09 16:30 | AH20: Synthetic Care Gap charge; 10% below Athena allowed amount
A21: IPD-CHG-0009-ATH | B21: HAR-202600009-ATH | C21: CSN-IPD-780009-ATH | D21: Inpatient | E21: Demo Regional Medical Center | F21: Implants | G21: 2026-09-10 | H21: IMP-SCREW | I21: Orthopedic Fixation Screw | J21: 0278 | K21: C1713 | M21: 1 | N21: 950 | O21: =M21*N21 | P21: 455.67 | Q21: =P21*20% | R21: =O21-P21 | S21: Athena Health Insurance | T21: Athena PPO | V21: Eleanor Brooks, MD | W21: Assigned Department Provider | X21: Inventory | Y21: Implant scan | Z21: Posted | AA21: Matched | AB21: Passed | AD21: Contract rule | AE21: M17.11 | AF21: 21 | AG21: 2026-09-10 16:30 | AH21: Synthetic Athena negotiated charge
A22: IPD-CHG-0009-CGH | B22: HAR-202600009-CGH | C22: CSN-IPD-780009-CGH | D22: Inpatient | E22: Demo Regional Medical Center | F22: Implants | G22: 2026-09-10 | H22: IMP-SCREW | I22: Orthopedic Fixation Screw | J22: 0278 | K22: C1713 | M22: 1 | N22: 950 | O22: =M22*N22 | P22: 410.1 | Q22: =P22*15% | R22: =O22-P22 | S22: Care Gap Health | T22: Care Gap Value PPO | V22: Eleanor Brooks, MD | W22: Assigned Department Provider | X22: Inventory | Y22: Implant scan | Z22: Posted | AA22: Matched | AB22: Passed | AD22: Contract rule | AE22: M17.11 | AF22: 21 | AG22: 2026-09-10 16:30 | AH22: Synthetic Care Gap charge; 10% below Athena allowed amount
A23: IPD-CHG-0010-ATH | B23: HAR-202600010-ATH | C23: CSN-IPD-780010-ATH | D23: Inpatient | E23: Demo Regional Medical Center | F23: Pharmacy | G23: 2026-09-11 | H23: DRUG-CEFA-1G | I23: Cefazolin 1 g Injection | J23: 0250 | K23: J0690 | M23: 3 | N23: 500 | O23: =M23*N23 | P23: 945.6 | Q23: =P23*20% | R23: =O23-P23 | S23: Athena Health Insurance | T23: Athena PPO | V23: Eleanor Brooks, MD | W23: Assigned Department Provider | X23: Pharmacy MAR | Y23: Medication administration | Z23: Posted | AA23: Matched | AB23: Passed | AD23: Dose/frequency | AE23: Z79.2 | AF23: 21 | AG23: 2026-09-11 16:30 | AH23: Synthetic Athena negotiated charge
A24: IPD-CHG-0010-CGH | B24: HAR-202600010-CGH | C24: CSN-IPD-780010-CGH | D24: Inpatient | E24: Demo Regional Medical Center | F24: Pharmacy | G24: 2026-09-11 | H24: DRUG-CEFA-1G | I24: Cefazolin 1 g Injection | J24: 0250 | K24: J0690 | M24: 3 | N24: 500 | O24: =M24*N24 | P24: 851.04 | Q24: =P24*15% | R24: =O24-P24 | S24: Care Gap Health | T24: Care Gap Value PPO | V24: Eleanor Brooks, MD | W24: Assigned Department Provider | X24: Pharmacy MAR | Y24: Medication administration | Z24: Posted | AA24: Matched | AB24: Passed | AD24: Dose/frequency | AE24: Z79.2 | AF24: 21 | AG24: 2026-09-11 16:30 | AH24: Synthetic Care Gap charge; 10% below Athena allowed amount
A25: IPD-CHG-0011-ATH | B25: HAR-202600011-ATH | C25: CSN-IPD-780011-ATH | D25: Inpatient | E25: Demo Regional Medical Center | F25: Pharmacy | G25: 2026-09-12 | H25: DRUG-VANC-500 | I25: Vancomycin 500 mg Injection | J25: 0250 | K25: J3370 | M25: 2 | N25: 680 | O25: =M25*N25 | P25: 661.14 | Q25: =P25*20% | R25: =O25-P25 | S25: Athena Health Insurance | T25: Athena PPO | V25: Eleanor Brooks, MD | W25: Assigned Department Provider | X25: Pharmacy MAR | Y25: Medication administration | Z25: Posted | AA25: Matched | AB25: Passed | AD25: Dose/frequency | AE25: Z79.2 | AF25: 21 | AG25: 2026-09-12 16:30 | AH25: Synthetic Athena negotiated charge
A26: IPD-CHG-0011-CGH | B26: HAR-202600011-CGH | C26: CSN-IPD-780011-CGH | D26: Inpatient | E26: Demo Regional Medical Center | F26: Pharmacy | G26: 2026-09-12 | H26: DRUG-VANC-500 | I26: Vancomycin 500 mg Injection | J26: 0250 | K26: J3370 | M26: 2 | N26: 680 | O26: =M26*N26 | P26: 595.03 | Q26: =P26*15% | R26: =O26-P26 | S26: Care Gap Health | T26: Care Gap Value PPO | V26: Eleanor Brooks, MD | W26: Assigned Department Provider | X26: Pharmacy MAR | Y26: Medication administration | Z26: Posted | AA26: Matched | AB26: Passed | AD26: Dose/frequency | AE26: Z79.2 | AF26: 21 | AG26: 2026-09-12 16:30 | AH26: Synthetic Care Gap charge; 10% below Athena allowed amount
A27: IPD-CHG-0012-ATH | B27: HAR-202600012-ATH | C27: CSN-IPD-780012-ATH | D27: Inpatient | E27: Demo Regional Medical Center | F27: Pharmacy | G27: 2026-09-13 | H27: IV-NS-1L | I27: Normal Saline 1,000 mL | J27: 0258 | K27: J7030 | M27: 3 | N27: 90 | O27: =M27*N27 | P27: 135.93 | Q27: =P27*20% | R27: =O27-P27 | S27: Athena Health Insurance | T27: Athena PPO | V27: Eleanor Brooks, MD | W27: Assigned Department Provider | X27: Pharmacy MAR | Y27: Medication administration | Z27: Posted | AA27: Matched | AB27: Passed | AD27: N/A | AE27: E86.0 | AF27: 21 | AG27: 2026-09-13 16:30 | AH27: Synthetic Athena negotiated charge
A28: IPD-CHG-0012-CGH | B28: HAR-202600012-CGH | C28: CSN-IPD-780012-CGH | D28: Inpatient | E28: Demo Regional Medical Center | F28: Pharmacy | G28: 2026-09-13 | H28: IV-NS-1L | I28: Normal Saline 1,000 mL | J28: 0258 | K28: J7030 | M28: 3 | N28: 90 | O28: =M28*N28 | P28: 122.34 | Q28: =P28*15% | R28: =O28-P28 | S28: Care Gap Health | T28: Care Gap Value PPO | V28: Eleanor Brooks, MD | W28: Assigned Department Provider | X28: Pharmacy MAR | Y28: Medication administration | Z28: Posted | AA28: Matched | AB28: Passed | AD28: N/A | AE28: E86.0 | AF28: 21 | AG28: 2026-09-13 16:30 | AH28: Synthetic Care Gap charge; 10% below Athena allowed amount
A29: IPD-CHG-0013-ATH | B29: HAR-202600013-ATH | C29: CSN-IPD-780013-ATH | D29: Inpatient | E29: Demo Regional Medical Center | F29: Laboratory | G29: 2026-09-14 | H29: LAB-CBC | I29: Complete Blood Count with Differential | J29: 0300 | K29: 85025 | M29: 1 | N29: 155 | O29: =M29*N29 | P29: 105.52 | Q29: =P29*20% | R29: =O29-P29 | S29: Athena Health Insurance | T29: Athena PPO | V29: Eleanor Brooks, MD | W29: Assigned Department Provider | X29: LIS | Y29: Final result | Z29: Posted | AA29: Matched | AB29: Passed | AD29: Diagnosis/LCD | AE29: D64.9 | AF29: 21 | AG29: 2026-09-14 16:30 | AH29: Synthetic Athena negotiated charge
A30: IPD-CHG-0013-CGH | B30: HAR-202600013-CGH | C30: CSN-IPD-780013-CGH | D30: Inpatient | E30: Demo Regional Medical Center | F30: Laboratory | G30: 2026-09-14 | H30: LAB-CBC | I30: Complete Blood Count with Differential | J30: 0300 | K30: 85025 | M30: 1 | N30: 155 | O30: =M30*N30 | P30: 94.97 | Q30: =P30*15% | R30: =O30-P30 | S30: Care Gap Health | T30: Care Gap Value PPO | V30: Eleanor Brooks, MD | W30: Assigned Department Provider | X30: LIS | Y30: Final result | Z30: Posted | AA30: Matched | AB30: Passed | AD30: Diagnosis/LCD | AE30: D64.9 | AF30: 21 | AG30: 2026-09-14 16:30 | AH30: Synthetic Care Gap charge; 10% below Athena allowed amount
A31: IPD-CHG-0014-ATH | B31: HAR-202600014-ATH | C31: CSN-IPD-780014-ATH | D31: Inpatient | E31: Demo Regional Medical Center | F31: Laboratory | G31: 2026-09-15 | H31: LAB-CMP | I31: Comprehensive Metabolic Panel | J31: 0301 | K31: 80053 | M31: 1 | N31: 245 | O31: =M31*N31 | P31: 158.67 | Q31: =P31*20% | R31: =O31-P31 | S31: Athena Health Insurance | T31: Athena PPO | V31: Eleanor Brooks, MD | W31: Assigned Department Provider | X31: LIS | Y31: Final result | Z31: Posted | AA31: Matched | AB31: Passed | AD31: Diagnosis/LCD | AE31: E11.9 | AF31: 21 | AG31: 2026-09-15 16:30 | AH31: Synthetic Athena negotiated charge
A32: IPD-CHG-0014-CGH | B32: HAR-202600014-CGH | C32: CSN-IPD-780014-CGH | D32: Inpatient | E32: Demo Regional Medical Center | F32: Laboratory | G32: 2026-09-15 | H32: LAB-CMP | I32: Comprehensive Metabolic Panel | J32: 0301 | K32: 80053 | M32: 1 | N32: 245 | O32: =M32*N32 | P32: 142.8 | Q32: =P32*15% | R32: =O32-P32 | S32: Care Gap Health | T32: Care Gap Value PPO | V32: Eleanor Brooks, MD | W32: Assigned Department Provider | X32: LIS | Y32: Final result | Z32: Posted | AA32: Matched | AB32: Passed | AD32: Diagnosis/LCD | AE32: E11.9 | AF32: 21 | AG32: 2026-09-15 16:30 | AH32: Synthetic Care Gap charge; 10% below Athena allowed amount
A33: IPD-CHG-0015-ATH | B33: HAR-202600015-ATH | C33: CSN-IPD-780015-ATH | D33: Inpatient | E33: Demo Regional Medical Center | F33: Laboratory | G33: 2026-09-16 | H33: LAB-PTINR | I33: Prothrombin Time / INR | J33: 0305 | K33: 85610 | M33: 1 | N33: 125 | O33: =M33*N33 | P33: 58.49 | Q33: =P33*20% | R33: =O33-P33 | S33: Athena Health Insurance | T33: Athena PPO | V33: Eleanor Brooks, MD | W33: Assigned Department Provider | X33: LIS | Y33: Final result | Z33: Posted | AA33: Matched | AB33: Passed | AD33: Diagnosis/LCD | AE33: Z79.01 | AF33: 21 | AG33: 2026-09-16 16:30 | AH33: Synthetic Athena negotiated charge
A34: IPD-CHG-0015-CGH | B34: HAR-202600015-CGH | C34: CSN-IPD-780015-CGH | D34: Inpatient | E34: Demo Regional Medical Center | F34: Laboratory | G34: 2026-09-16 | H34: LAB-PTINR | I34: Prothrombin Time / INR | J34: 0305 | K34: 85610 | M34: 1 | N34: 125 | O34: =M34*N34 | P34: 52.64 | Q34: =P34*15% | R34: =O34-P34 | S34: Care Gap Health | T34: Care Gap Value PPO | V34: Eleanor Brooks, MD | W34: Assigned Department Provider | X34: LIS | Y34: Final result | Z34: Posted | AA34: Matched | AB34: Passed | AD34: Diagnosis/LCD | AE34: Z79.01 | AF34: 21 | AG34: 2026-09-16 16:30 | AH34: Synthetic Care Gap charge; 10% below Athena allowed amount
A35: IPD-CHG-0016-ATH | B35: HAR-202600016-ATH | C35: CSN-IPD-780016-ATH | D35: Inpatient | E35: Demo Regional Medical Center | F35: Radiology | G35: 2026-09-17 | H35: RAD-CHEST-2V | I35: Chest X-ray, 2 Views | J35: 0320 | K35: 71046 | M35: 1 | N35: 185 | O35: =M35*N35 | P35: 101.16 | Q35: =P35*20% | R35: =O35-P35 | S35: Athena Health Insurance | T35: Athena PPO | V35: Eleanor Brooks, MD | W35: Assigned Department Provider | X35: RIS/PACS | Y35: Exam completed | Z35: Posted | AA35: Matched | AB35: Passed | AD35: Diagnosis/LCD | AE35: R06.02 | AF35: 21 | AG35: 2026-09-17 16:30 | AH35: Synthetic Athena negotiated charge
A36: IPD-CHG-0016-CGH | B36: HAR-202600016-CGH | C36: CSN-IPD-780016-CGH | D36: Inpatient | E36: Demo Regional Medical Center | F36: Radiology | G36: 2026-09-17 | H36: RAD-CHEST-2V | I36: Chest X-ray, 2 Views | J36: 0320 | K36: 71046 | M36: 1 | N36: 185 | O36: =M36*N36 | P36: 91.04 | Q36: =P36*15% | R36: =O36-P36 | S36: Care Gap Health | T36: Care Gap Value PPO | V36: Eleanor Brooks, MD | W36: Assigned Department Provider | X36: RIS/PACS | Y36: Exam completed | Z36: Posted | AA36: Matched | AB36: Passed | AD36: Diagnosis/LCD | AE36: R06.02 | AF36: 21 | AG36: 2026-09-17 16:30 | AH36: Synthetic Care Gap charge; 10% below Athena allowed amount
A37: IPD-CHG-0017-ATH | B37: HAR-202600017-ATH | C37: CSN-IPD-780017-ATH | D37: Inpatient | E37: Demo Regional Medical Center | F37: Radiology | G37: 2026-09-18 | H37: RAD-KNEE-2V | I37: Knee X-ray, 1-2 Views | J37: 0320 | K37: 73560 | M37: 1 | N37: 410 | O37: =M37*N37 | P37: 206.38 | Q37: =P37*20% | R37: =O37-P37 | S37: Athena Health Insurance | T37: Athena PPO | V37: Eleanor Brooks, MD | W37: Assigned Department Provider | X37: RIS/PACS | Y37: Exam completed | Z37: Posted | AA37: Matched | AB37: Passed | AD37: Diagnosis/LCD | AE37: M25.561 | AF37: 21 | AG37: 2026-09-18 16:30 | AH37: Synthetic Athena negotiated charge
A38: IPD-CHG-0017-CGH | B38: HAR-202600017-CGH | C38: CSN-IPD-780017-CGH | D38: Inpatient | E38: Demo Regional Medical Center | F38: Radiology | G38: 2026-09-18 | H38: RAD-KNEE-2V | I38: Knee X-ray, 1-2 Views | J38: 0320 | K38: 73560 | M38: 1 | N38: 410 | O38: =M38*N38 | P38: 185.74 | Q38: =P38*15% | R38: =O38-P38 | S38: Care Gap Health | T38: Care Gap Value PPO | V38: Eleanor Brooks, MD | W38: Assigned Department Provider | X38: RIS/PACS | Y38: Exam completed | Z38: Posted | AA38: Matched | AB38: Passed | AD38: Diagnosis/LCD | AE38: M25.561 | AF38: 21 | AG38: 2026-09-18 16:30 | AH38: Synthetic Care Gap charge; 10% below Athena allowed amount
A39: IPD-CHG-0018-ATH | B39: HAR-202600018-ATH | C39: CSN-IPD-780018-ATH | D39: Inpatient | E39: Demo Regional Medical Center | F39: Cardiology | G39: 2026-09-19 | H39: CARD-ECG12 | I39: 12-Lead ECG | J39: 0730 | K39: 93005 | M39: 1 | N39: 190 | O39: =M39*N39 | P39: 92.07 | Q39: =P39*20% | R39: =O39-P39 | S39: Athena Health Insurance | T39: Athena PPO | V39: Eleanor Brooks, MD | W39: Assigned Department Provider | X39: Cardiology | Y39: Test completed | Z39: Posted | AA39: Matched | AB39: Passed | AD39: Diagnosis/LCD | AE39: R07.9 | AF39: 21 | AG39: 2026-09-19 16:30 | AH39: Synthetic Athena negotiated charge
A40: IPD-CHG-0018-CGH | B40: HAR-202600018-CGH | C40: CSN-IPD-780018-CGH | D40: Inpatient | E40: Demo Regional Medical Center | F40: Cardiology | G40: 2026-09-19 | H40: CARD-ECG12 | I40: 12-Lead ECG | J40: 0730 | K40: 93005 | M40: 1 | N40: 190 | O40: =M40*N40 | P40: 82.86 | Q40: =P40*15% | R40: =O40-P40 | S40: Care Gap Health | T40: Care Gap Value PPO | V40: Eleanor Brooks, MD | W40: Assigned Department Provider | X40: Cardiology | Y40: Test completed | Z40: Posted | AA40: Matched | AB40: Passed | AD40: Diagnosis/LCD | AE40: R07.9 | AF40: 21 | AG40: 2026-09-19 16:30 | AH40: Synthetic Care Gap charge; 10% below Athena allowed amount
A41: IPD-CHG-0019-ATH | B41: HAR-202600019-ATH | C41: CSN-IPD-780019-ATH | D41: Inpatient | E41: Demo Regional Medical Center | F41: Respiratory | G41: 2026-09-20 | H41: RESP-NEB | I41: Nebulizer Treatment | J41: 0410 | K41: 94640 | M41: 1 | N41: 245 | O41: =M41*N41 | P41: 159.02 | Q41: =P41*20% | R41: =O41-P41 | S41: Athena Health Insurance | T41: Athena PPO | V41: Eleanor Brooks, MD | W41: Assigned Department Provider | X41: Respiratory | Y41: Treatment completed | Z41: Posted | AA41: Matched | AB41: Passed | AD41: Diagnosis/LCD | AE41: J45.901 | AF41: 21 | AG41: 2026-09-20 16:30 | AH41: Synthetic Athena negotiated charge
...

Sheet OPD Charges
A1: Outpatient Charge Detail
A2: 100 original synthetic outpatient charge lines, each represented for Athena Health Insurance and Care Gap Health (200 payer-priced rows).
A4: Charge Line ID | B4: Patient Account | C4: Encounter ID | D4: Patient Class | E4: Facility | F4: Department | G4: Service Date | H4: Charge Code | I4: Charge Description | J4: Revenue Code | K4: CPT/HCPCS | L4: Modifier | M4: Quantity | N4: Unit Charge ($) | O4: Extended Gross ($) | P4: Expected Allowed ($) | Q4: Patient Responsibility ($) | R4: Contractual Adjustment ($) | S4: Payer | T4: Plan | U4: Authorization ID | V4: Ordering Provider | W4: Performing Provider | X4: Source System | Y4: Charge Trigger | Z4: Charge Status | AA4: Reconciliation Status | AB4: Claim Edit Status | AC4: Workqueue | AD4: Medical Necessity | AE4: Diagnosis Link | AF4: Place of Service | AG4: Posting Date/Time | AH4: Notes
A5: OPD-CHG-0001-ATH | B5: OP-202600001-ATH | C5: CSN-OPD-780001-ATH | D5: Outpatient | E5: Demo Regional Medical Center | F5: Emergency Department | G5: 2026-09-02 | H5: ED-LEVEL-1 | I5: Emergency Department Visit Level 1 | J5: 0450 | K5: 99281 | M5: 1 | N5: 360 | O5: =M5*N5 | P5: 221.39 | Q5: =P5*20% | R5: =O5-P5 | S5: Athena Health Insurance | T5: Athena PPO | V5: Eleanor Brooks, MD | W5: Assigned Department Provider | X5: ED | Y5: Encounter close | Z5: Posted | AA5: Matched | AB5: Passed | AD5: Documentation | AE5: R50.9 | AF5: 22 | AG5: 2026-09-02 16:30 | AH5: Synthetic Athena negotiated charge
A6: OPD-CHG-0001-CGH | B6: OP-202600001-CGH | C6: CSN-OPD-780001-CGH | D6: Outpatient | E6: Demo Regional Medical Center | F6: Emergency Department | G6: 2026-09-02 | H6: ED-LEVEL-1 | I6: Emergency Department Visit Level 1 | J6: 0450 | K6: 99281 | M6: 1 | N6: 360 | O6: =M6*N6 | P6: 199.25 | Q6: =P6*15% | R6: =O6-P6 | S6: Care Gap Health | T6: Care Gap Value PPO | V6: Eleanor Brooks, MD | W6: Assigned Department Provider | X6: ED | Y6: Encounter close | Z6: Posted | AA6: Matched | AB6: Passed | AD6: Documentation | AE6: R50.9 | AF6: 22 | AG6: 2026-09-02 16:30 | AH6: Synthetic Care Gap charge; 10% below Athena allowed amount
A7: OPD-CHG-0002-ATH | B7: OP-202600002-ATH | C7: CSN-OPD-780002-ATH | D7: Outpatient | E7: Demo Regional Medical Center | F7: Emergency Department | G7: 2026-09-03 | H7: ED-LEVEL-2 | I7: Emergency Department Visit Level 2 | J7: 0450 | K7: 99282 | M7: 1 | N7: 670 | O7: =M7*N7 | P7: 369.46 | Q7: =P7*20% | R7: =O7-P7 | S7: Athena Health Insurance | T7: Athena PPO | V7: Eleanor Brooks, MD | W7: Assigned Department Provider | X7: ED | Y7: Encounter close | Z7: Posted | AA7: Matched | AB7: Passed | AD7: Documentation | AE7: R51.9 | AF7: 22 | AG7: 2026-09-03 16:30 | AH7: Synthetic Athena negotiated charge
A8: OPD-CHG-0002-CGH | B8: OP-202600002-CGH | C8: CSN-OPD-780002-CGH | D8: Outpatient | E8: Demo Regional Medical Center | F8: Emergency Department | G8: 2026-09-03 | H8: ED-LEVEL-2 | I8: Emergency Department Visit Level 2 | J8: 0450 | K8: 99282 | M8: 1 | N8: 670 | O8: =M8*N8 | P8: 332.51 | Q8: =P8*15% | R8: =O8-P8 | S8: Care Gap Health | T8: Care Gap Value PPO | V8: Eleanor Brooks, MD | W8: Assigned Department Provider | X8: ED | Y8: Encounter close | Z8: Posted | AA8: Matched | AB8: Passed | AD8: Documentation | AE8: R51.9 | AF8: 22 | AG8: 2026-09-03 16:30 | AH8: Synthetic Care Gap charge; 10% below Athena allowed amount
A9: OPD-CHG-0003-ATH | B9: OP-202600003-ATH | C9: CSN-OPD-780003-ATH | D9: Outpatient | E9: Demo Regional Medical Center | F9: Emergency Department | G9: 2026-09-04 | H9: ED-LEVEL-3 | I9: Emergency Department Visit Level 3 | J9: 0450 | K9: 99283 | M9: 1 | N9: 1280 | O9: =M9*N9 | P9: 736.35 | Q9: =P9*20% | R9: =O9-P9 | S9: Athena Health Insurance | T9: Athena PPO | V9: Eleanor Brooks, MD | W9: Assigned Department Provider | X9: ED | Y9: Encounter close | Z9: Posted | AA9: Matched | AB9: Passed | AD9: Documentation | AE9: R10.9 | AF9: 22 | AG9: 2026-09-04 16:30 | AH9: Synthetic Athena negotiated charge
A10: OPD-CHG-0003-CGH | B10: OP-202600003-CGH | C10: CSN-OPD-780003-CGH | D10: Outpatient | E10: Demo Regional Medical Center | F10: Emergency Department | G10: 2026-09-04 | H10: ED-LEVEL-3 | I10: Emergency Department Visit Level 3 | J10: 0450 | K10: 99283 | M10: 1 | N10: 1280 | O10: =M10*N10 | P10: 662.72 | Q10: =P10*15% | R10: =O10-P10 | S10: Care Gap Health | T10: Care Gap Value PPO | V10: Eleanor Brooks, MD | W10: Assigned Department Provider | X10: ED | Y10: Encounter close | Z10: Posted | AA10: Matched | AB10: Passed | AD10: Documentation | AE10: R10.9 | AF10: 22 | AG10: 2026-09-04 16:30 | AH10: Synthetic Care Gap charge; 10% below Athena allowed amount
A11: OPD-CHG-0004-ATH | B11: OP-202600004-ATH | C11: CSN-OPD-780004-ATH | D11: Outpatient | E11: Demo Regional Medical Center | F11: Emergency Department | G11: 2026-09-05 | H11: ED-LEVEL-4 | I11: Emergency Department Visit Level 4 | J11: 0450 | K11: 99284 | M11: 1 | N11: 2350 | O11: =M11*N11 | P11: 1072.31 | Q11: =P11*20% | R11: =O11-P11 | S11: Athena Health Insurance | T11: Athena PPO | V11: Eleanor Brooks, MD | W11: Assigned Department Provider | X11: ED | Y11: Encounter close | Z11: Posted | AA11: Matched | AB11: Passed | AD11: Documentation | AE11: R06.02 | AF11: 22 | AG11: 2026-09-05 16:30 | AH11: Synthetic Athena negotiated charge
A12: OPD-CHG-0004-CGH | B12: OP-202600004-CGH | C12: CSN-OPD-780004-CGH | D12: Outpatient | E12: Demo Regional Medical Center | F12: Emergency Department | G12: 2026-09-05 | H12: ED-LEVEL-4 | I12: Emergency Department Visit Level 4 | J12: 0450 | K12: 99284 | M12: 1 | N12: 2350 | O12: =M12*N12 | P12: 965.08 | Q12: =P12*15% | R12: =O12-P12 | S12: Care Gap Health | T12: Care Gap Value PPO | V12: Eleanor Brooks, MD | W12: Assigned Department Provider | X12: ED | Y12: Encounter close | Z12: Posted | AA12: Matched | AB12: Passed | AD12: Documentation | AE12: R06.02 | AF12: 22 | AG12: 2026-09-05 16:30 | AH12: Synthetic Care Gap charge; 10% below Athena allowed amount
A13: OPD-CHG-0005-ATH | B13: OP-202600005-ATH | C13: CSN-OPD-780005-ATH | D13: Outpatient | E13: Demo Regional Medical Center | F13: Emergency Department | G13: 2026-09-06 | H13: ED-LEVEL-5 | I13: Emergency Department Visit Level 5 | J13: 0450 | K13: 99285 | M13: 1 | N13: 4300 | O13: =M13*N13 | P13: 2095.86 | Q13: =P13*20% | R13: =O13-P13 | S13: Athena Health Insurance | T13: Athena PPO | V13: Eleanor Brooks, MD | W13: Assigned Department Provider | X13: ED | Y13: Encounter close | Z13: Posted | AA13: Matched | AB13: Passed | AD13: Documentation | AE13: R07.9 | AF13: 22 | AG13: 2026-09-06 16:30 | AH13: Synthetic Athena negotiated charge
A14: OPD-CHG-0005-CGH | B14: OP-202600005-CGH | C14: CSN-OPD-780005-CGH | D14: Outpatient | E14: Demo Regional Medical Center | F14: Emergency Department | G14: 2026-09-06 | H14: ED-LEVEL-5 | I14: Emergency Department Visit Level 5 | J14: 0450 | K14: 99285 | M14: 1 | N14: 4300 | O14: =M14*N14 | P14: 1886.27 | Q14: =P14*15% | R14: =O14-P14 | S14: Care Gap Health | T14: Care Gap Value PPO | V14: Eleanor Brooks, MD | W14: Assigned Department Provider | X14: ED | Y14: Encounter close | Z14: Posted | AA14: Matched | AB14: Passed | AD14: Documentation | AE14: R07.9 | AF14: 22 | AG14: 2026-09-06 16:30 | AH14: Synthetic Care Gap charge; 10% below Athena allowed amount
A15: OPD-CHG-0006-ATH | B15: OP-202600006-ATH | C15: CSN-OPD-780006-ATH | D15: Outpatient | E15: Demo Regional Medical Center | F15: Hospital Clinic | G15: 2026-09-07 | H15: CLINIC-L2 | I15: Hospital Outpatient Clinic Visit Level 2 | J15: 0510 | K15: 99212 | M15: 1 | N15: 215 | O15: =M15*N15 | P15: 112.11 | Q15: =P15*20% | R15: =O15-P15 | S15: Athena Health Insurance | T15: Athena PPO | V15: Eleanor Brooks, MD | W15: Assigned Department Provider | X15: Ambulatory | Y15: Visit close | Z15: Posted | AA15: Matched | AB15: Passed | AD15: E/M documentation | AE15: I10 | AF15: 22 | AG15: 2026-09-07 16:30 | AH15: Synthetic Athena negotiated charge
A16: OPD-CHG-0006-CGH | B16: OP-202600006-CGH | C16: CSN-OPD-780006-CGH | D16: Outpatient | E16: Demo Regional Medical Center | F16: Hospital Clinic | G16: 2026-09-07 | H16: CLINIC-L2 | I16: Hospital Outpatient Clinic Visit Level 2 | J16: 0510 | K16: 99212 | M16: 1 | N16: 215 | O16: =M16*N16 | P16: 100.9 | Q16: =P16*15% | R16: =O16-P16 | S16: Care Gap Health | T16: Care Gap Value PPO | V16: Eleanor Brooks, MD | W16: Assigned Department Provider | X16: Ambulatory | Y16: Visit close | Z16: Posted | AA16: Matched | AB16: Passed | AD16: E/M documentation | AE16: I10 | AF16: 22 | AG16: 2026-09-07 16:30 | AH16: Synthetic Care Gap charge; 10% below Athena allowed amount
A17: OPD-CHG-0007-ATH | B17: OP-202600007-ATH | C17: CSN-OPD-780007-ATH | D17: Outpatient | E17: Demo Regional Medical Center | F17: Hospital Clinic | G17: 2026-09-08 | H17: CLINIC-L3 | I17: Hospital Outpatient Clinic Visit Level 3 | J17: 0510 | K17: 99213 | M17: 1 | N17: 315 | O17: =M17*N17 | P17: 187.9 | Q17: =P17*20% | R17: =O17-P17 | S17: Athena Health Insurance | T17: Athena PPO | V17: Eleanor Brooks, MD | W17: Assigned Department Provider | X17: Ambulatory | Y17: Visit close | Z17: Posted | AA17: Matched | AB17: Passed | AD17: E/M documentation | AE17: E11.9 | AF17: 22 | AG17: 2026-09-08 16:30 | AH17: Synthetic Athena negotiated charge
A18: OPD-CHG-0007-CGH | B18: OP-202600007-CGH | C18: CSN-OPD-780007-CGH | D18: Outpatient | E18: Demo Regional Medical Center | F18: Hospital Clinic | G18: 2026-09-08 | H18: CLINIC-L3 | I18: Hospital Outpatient Clinic Visit Level 3 | J18: 0510 | K18: 99213 | M18: 1 | N18: 315 | O18: =M18*N18 | P18: 169.11 | Q18: =P18*15% | R18: =O18-P18 | S18: Care Gap Health | T18: Care Gap Value PPO | V18: Eleanor Brooks, MD | W18: Assigned Department Provider | X18: Ambulatory | Y18: Visit close | Z18: Posted | AA18: Matched | AB18: Passed | AD18: E/M documentation | AE18: E11.9 | AF18: 22 | AG18: 2026-09-08 16:30 | AH18: Synthetic Care Gap charge; 10% below Athena allowed amount
A19: OPD-CHG-0008-ATH | B19: OP-202600008-ATH | C19: CSN-OPD-780008-ATH | D19: Outpatient | E19: Demo Regional Medical Center | F19: Hospital Clinic | G19: 2026-09-09 | H19: CLINIC-L4 | I19: Hospital Outpatient Clinic Visit Level 4 | J19: 0510 | K19: 99214 | M19: 1 | N19: 410 | O19: =M19*N19 | P19: 200.5 | Q19: =P19*20% | R19: =O19-P19 | S19: Athena Health Insurance | T19: Athena PPO | V19: Eleanor Brooks, MD | W19: Assigned Department Provider | X19: Ambulatory | Y19: Visit close | Z19: Posted | AA19: Matched | AB19: Passed | AD19: E/M documentation | AE19: J45.40 | AF19: 22 | AG19: 2026-09-09 16:30 | AH19: Synthetic Athena negotiated charge
A20: OPD-CHG-0008-CGH | B20: OP-202600008-CGH | C20: CSN-OPD-780008-CGH | D20: Outpatient | E20: Demo Regional Medical Center | F20: Hospital Clinic | G20: 2026-09-09 | H20: CLINIC-L4 | I20: Hospital Outpatient Clinic Visit Level 4 | J20: 0510 | K20: 99214 | M20: 1 | N20: 410 | O20: =M20*N20 | P20: 180.45 | Q20: =P20*15% | R20: =O20-P20 | S20: Care Gap Health | T20: Care Gap Value PPO | V20: Eleanor Brooks, MD | W20: Assigned Department Provider | X20: Ambulatory | Y20: Visit close | Z20: Posted | AA20: Matched | AB20: Passed | AD20: E/M documentation | AE20: J45.40 | AF20: 22 | AG20: 2026-09-09 16:30 | AH20: Synthetic Care Gap charge; 10% below Athena allowed amount
A21: OPD-CHG-0009-ATH | B21: OP-202600009-ATH | C21: CSN-OPD-780009-ATH | D21: Outpatient | E21: Demo Regional Medical Center | F21: Hospital Clinic | G21: 2026-09-10 | H21: CLINIC-L5 | I21: Hospital Outpatient Clinic Visit Level 5 | J21: 0510 | K21: 99215 | M21: 1 | N21: 570 | O21: =M21*N21 | P21: 277.06 | Q21: =P21*20% | R21: =O21-P21 | S21: Athena Health Insurance | T21: Athena PPO | V21: Eleanor Brooks, MD | W21: Assigned Department Provider | X21: Ambulatory | Y21: Visit close | Z21: Posted | AA21: Matched | AB21: Passed | AD21: E/M documentation | AE21: I50.9 | AF21: 22 | AG21: 2026-09-10 16:30 | AH21: Synthetic Athena negotiated charge
A22: OPD-CHG-0009-CGH | B22: OP-202600009-CGH | C22: CSN-OPD-780009-CGH | D22: Outpatient | E22: Demo Regional Medical Center | F22: Hospital Clinic | G22: 2026-09-10 | H22: CLINIC-L5 | I22: Hospital Outpatient Clinic Visit Level 5 | J22: 0510 | K22: 99215 | M22: 1 | N22: 570 | O22: =M22*N22 | P22: 249.35 | Q22: =P22*15% | R22: =O22-P22 | S22: Care Gap Health | T22: Care Gap Value PPO | V22: Eleanor Brooks, MD | W22: Assigned Department Provider | X22: Ambulatory | Y22: Visit close | Z22: Posted | AA22: Matched | AB22: Passed | AD22: E/M documentation | AE22: I50.9 | AF22: 22 | AG22: 2026-09-10 16:30 | AH22: Synthetic Care Gap charge; 10% below Athena allowed amount
A23: OPD-CHG-0010-ATH | B23: OP-202600010-ATH | C23: CSN-OPD-780010-ATH | D23: Outpatient | E23: Demo Regional Medical Center | F23: Radiology | G23: 2026-09-11 | H23: XR-CHEST-2V | I23: Chest X-ray, 2 Views | J23: 0320 | K23: 71046 | M23: 1 | N23: 185 | O23: =M23*N23 | P23: 81.64 | Q23: =P23*20% | R23: =O23-P23 | S23: Athena Health Insurance | T23: Athena PPO | V23: Eleanor Brooks, MD | W23: Assigned Department Provider | X23: RIS/PACS | Y23: Exam completed | Z23: Posted | AA23: Matched | AB23: Passed | AD23: Diagnosis/LCD | AE23: R05.9 | AF23: 22 | AG23: 2026-09-11 16:30 | AH23: Synthetic Athena negotiated charge
A24: OPD-CHG-0010-CGH | B24: OP-202600010-CGH | C24: CSN-OPD-780010-CGH | D24: Outpatient | E24: Demo Regional Medical Center | F24: Radiology | G24: 2026-09-11 | H24: XR-CHEST-2V | I24: Chest X-ray, 2 Views | J24: 0320 | K24: 71046 | M24: 1 | N24: 185 | O24: =M24*N24 | P24: 73.48 | Q24: =P24*15% | R24: =O24-P24 | S24: Care Gap Health | T24: Care Gap Value PPO | V24: Eleanor Brooks, MD | W24: Assigned Department Provider | X24: RIS/PACS | Y24: Exam completed | Z24: Posted | AA24: Matched | AB24: Passed | AD24: Diagnosis/LCD | AE24: R05.9 | AF24: 22 | AG24: 2026-09-11 16:30 | AH24: Synthetic Care Gap charge; 10% below Athena allowed amount
A25: OPD-CHG-0011-ATH | B25: OP-202600011-ATH | C25: CSN-OPD-780011-ATH | D25: Outpatient | E25: Demo Regional Medical Center | F25: Radiology | G25: 2026-09-12 | H25: CT-HEAD-WO | I25: CT Head Without Contrast | J25: 0350 | K25: 70450 | M25: 1 | N25: 1900 | O25: =M25*N25 | P25: 1157.73 | Q25: =P25*20% | R25: =O25-P25 | S25: Athena Health Insurance | T25: Athena PPO | U25: AUTH-700011 | V25: Eleanor Brooks, MD | W25: Assigned Department Provider | X25: RIS/PACS | Y25: Exam completed | Z25: Posted | AA25: Matched | AB25: Passed | AD25: Prior authorization | AE25: R51.9 | AF25: 22 | AG25: 2026-09-12 16:30 | AH25: Synthetic Athena negotiated charge
A26: OPD-CHG-0011-CGH | B26: OP-202600011-CGH | C26: CSN-OPD-780011-CGH | D26: Outpatient | E26: Demo Regional Medical Center | F26: Radiology | G26: 2026-09-12 | H26: CT-HEAD-WO | I26: CT Head Without Contrast | J26: 0350 | K26: 70450 | M26: 1 | N26: 1900 | O26: =M26*N26 | P26: 1041.96 | Q26: =P26*15% | R26: =O26-P26 | S26: Care Gap Health | T26: Care Gap Value PPO | U26: AUTH-700011 | V26: Eleanor Brooks, MD | W26: Assigned Department Provider | X26: RIS/PACS | Y26: Exam completed | Z26: Posted | AA26: Matched | AB26: Passed | AD26: Prior authorization | AE26: R51.9 | AF26: 22 | AG26: 2026-09-12 16:30 | AH26: Synthetic Care Gap charge; 10% below Athena allowed amount
A27: OPD-CHG-0012-ATH | B27: OP-202600012-ATH | C27: CSN-OPD-780012-ATH | D27: Outpatient | E27: Demo Regional Medical Center | F27: Radiology | G27: 2026-09-13 | H27: CT-CHEST-W | I27: CT Chest With Contrast | J27: 0350 | K27: 71260 | M27: 1 | N27: 2500 | O27: =M27*N27 | P27: 1221.71 | Q27: =P27*20% | R27: =O27-P27 | S27: Athena Health Insurance | T27: Athena PPO | U27: AUTH-700012 | V27: Eleanor Brooks, MD | W27: Assigned Department Provider | X27: RIS/PACS | Y27: Exam completed | Z27: Posted | AA27: Matched | AB27: Passed | AD27: Prior authorization | AE27: R91.1 | AF27: 22 | AG27: 2026-09-13 16:30 | AH27: Synthetic Athena negotiated charge
A28: OPD-CHG-0012-CGH | B28: OP-202600012-CGH | C28: CSN-OPD-780012-CGH | D28: Outpatient | E28: Demo Regional Medical Center | F28: Radiology | G28: 2026-09-13 | H28: CT-CHEST-W | I28: CT Chest With Contrast | J28: 0350 | K28: 71260 | M28: 1 | N28: 2500 | O28: =M28*N28 | P28: 1099.54 | Q28: =P28*15% | R28: =O28-P28 | S28: Care Gap Health | T28: Care Gap Value PPO | U28: AUTH-700012 | V28: Eleanor Brooks, MD | W28: Assigned Department Provider | X28: RIS/PACS | Y28: Exam completed | Z28: Posted | AA28: Matched | AB28: Passed | AD28: Prior authorization | AE28: R91.1 | AF28: 22 | AG28: 2026-09-13 16:30 | AH28: Synthetic Care Gap charge; 10% below Athena allowed amount
A29: OPD-CHG-0013-ATH | B29: OP-202600013-ATH | C29: CSN-OPD-780013-ATH | D29: Outpatient | E29: Demo Regional Medical Center | F29: Radiology | G29: 2026-09-14 | H29: MRI-BRAIN-WO | I29: MRI Brain Without Contrast | J29: 0610 | K29: 70551 | M29: 1 | N29: 3250 | O29: =M29*N29 | P29: 2247.78 | Q29: =P29*20% | R29: =O29-P29 | S29: Athena Health Insurance | T29: Athena PPO | U29: AUTH-700013 | V29: Eleanor Brooks, MD | W29: Assigned Department Provider | X29: RIS/PACS | Y29: Exam completed | Z29: Posted | AA29: Matched | AB29: Passed | AD29: Prior authorization | AE29: G43.909 | AF29: 22 | AG29: 2026-09-14 16:30 | AH29: Synthetic Athena negotiated charge
A30: OPD-CHG-0013-CGH | B30: OP-202600013-CGH | C30: CSN-OPD-780013-CGH | D30: Outpatient | E30: Demo Regional Medical Center | F30: Radiology | G30: 2026-09-14 | H30: MRI-BRAIN-WO | I30: MRI Brain Without Contrast | J30: 0610 | K30: 70551 | M30: 1 | N30: 3250 | O30: =M30*N30 | P30: 2023 | Q30: =P30*15% | R30: =O30-P30 | S30: Care Gap Health | T30: Care Gap Value PPO | U30: AUTH-700013 | V30: Eleanor Brooks, MD | W30: Assigned Department Provider | X30: RIS/PACS | Y30: Exam completed | Z30: Posted | AA30: Matched | AB30: Passed | AD30: Prior authorization | AE30: G43.909 | AF30: 22 | AG30: 2026-09-14 16:30 | AH30: Synthetic Care Gap charge; 10% below Athena allowed amount
A31: OPD-CHG-0014-ATH | B31: OP-202600014-ATH | C31: CSN-OPD-780014-ATH | D31: Outpatient | E31: Demo Regional Medical Center | F31: Radiology | G31: 2026-09-15 | H31: US-ABD-COMP | I31: Ultrasound Abdomen Complete | J31: 0402 | K31: 76700 | M31: 1 | N31: 875 | O31: =M31*N31 | P31: 593.15 | Q31: =P31*20% | R31: =O31-P31 | S31: Athena Health Insurance | T31: Athena PPO | V31: Eleanor Brooks, MD | W31: Assigned Department Provider | X31: RIS/PACS | Y31: Exam completed | Z31: Posted | AA31: Matched | AB31: Passed | AD31: Diagnosis/LCD | AE31: R10.84 | AF31: 22 | AG31: 2026-09-15 16:30 | AH31: Synthetic Athena negotiated charge
A32: OPD-CHG-0014-CGH | B32: OP-202600014-CGH | C32: CSN-OPD-780014-CGH | D32: Outpatient | E32: Demo Regional Medical Center | F32: Radiology | G32: 2026-09-15 | H32: US-ABD-COMP | I32: Ultrasound Abdomen Complete | J32: 0402 | K32: 76700 | M32: 1 | N32: 875 | O32: =M32*N32 | P32: 533.84 | Q32: =P32*15% | R32: =O32-P32 | S32: Care Gap Health | T32: Care Gap Value PPO | V32: Eleanor Brooks, MD | W32: Assigned Department Provider | X32: RIS/PACS | Y32: Exam completed | Z32: Posted | AA32: Matched | AB32: Passed | AD32: Diagnosis/LCD | AE32: R10.84 | AF32: 22 | AG32: 2026-09-15 16:30 | AH32: Synthetic Care Gap charge; 10% below Athena allowed amount
A33: OPD-CHG-0015-ATH | B33: OP-202600015-ATH | C33: CSN-OPD-780015-ATH | D33: Outpatient | E33: Demo Regional Medical Center | F33: Mammography | G33: 2026-09-16 | H33: MAMMO-SCREEN | I33: Screening Mammography, Bilateral | J33: 0403 | K33: 77067 | M33: 1 | N33: 535 | O33: =M33*N33 | P33: 236.07 | Q33: =P33*20% | R33: =O33-P33 | S33: Athena Health Insurance | T33: Athena PPO | V33: Eleanor Brooks, MD | W33: Assigned Department Provider | X33: RIS/PACS | Y33: Exam completed | Z33: Posted | AA33: Matched | AB33: Passed | AD33: Preventive rule | AE33: Z12.31 | AF33: 22 | AG33: 2026-09-16 16:30 | AH33: Synthetic Athena negotiated charge
A34: OPD-CHG-0015-CGH | B34: OP-202600015-CGH | C34: CSN-OPD-780015-CGH | D34: Outpatient | E34: Demo Regional Medical Center | F34: Mammography | G34: 2026-09-16 | H34: MAMMO-SCREEN | I34: Screening Mammography, Bilateral | J34: 0403 | K34: 77067 | M34: 1 | N34: 535 | O34: =M34*N34 | P34: 212.46 | Q34: =P34*15% | R34: =O34-P34 | S34: Care Gap Health | T34: Care Gap Value PPO | V34: Eleanor Brooks, MD | W34: Assigned Department Provider | X34: RIS/PACS | Y34: Exam completed | Z34: Posted | AA34: Matched | AB34: Passed | AD34: Preventive rule | AE34: Z12.31 | AF34: 22 | AG34: 2026-09-16 16:30 | AH34: Synthetic Care Gap charge; 10% below Athena allowed amount
A35: OPD-CHG-0016-ATH | B35: OP-202600016-ATH | C35: CSN-OPD-780016-ATH | D35: Outpatient | E35: Demo Regional Medical Center | F35: Laboratory | G35: 2026-09-17 | H35: CBC-OP | I35: Complete Blood Count with Differential | J35: 0300 | K35: 85025 | M35: 1 | N35: 155 | O35: =M35*N35 | P35: 76.17 | Q35: =P35*20% | R35: =O35-P35 | S35: Athena Health Insurance | T35: Athena PPO | V35: Eleanor Brooks, MD | W35: Assigned Department Provider | X35: LIS | Y35: Final result | Z35: Posted | AA35: Matched | AB35: Passed | AD35: Diagnosis/LCD | AE35: R53.83 | AF35: 22 | AG35: 2026-09-17 16:30 | AH35: Synthetic Athena negotiated charge
A36: OPD-CHG-0016-CGH | B36: OP-202600016-CGH | C36: CSN-OPD-780016-CGH | D36: Outpatient | E36: Demo Regional Medical Center | F36: Laboratory | G36: 2026-09-17 | H36: CBC-OP | I36: Complete Blood Count with Differential | J36: 0300 | K36: 85025 | M36: 1 | N36: 155 | O36: =M36*N36 | P36: 68.55 | Q36: =P36*15% | R36: =O36-P36 | S36: Care Gap Health | T36: Care Gap Value PPO | V36: Eleanor Brooks, MD | W36: Assigned Department Provider | X36: LIS | Y36: Final result | Z36: Posted | AA36: Matched | AB36: Passed | AD36: Diagnosis/LCD | AE36: R53.83 | AF36: 22 | AG36: 2026-09-17 16:30 | AH36: Synthetic Care Gap charge; 10% below Athena allowed amount
A37: OPD-CHG-0017-ATH | B37: OP-202600017-ATH | C37: CSN-OPD-780017-ATH | D37: Outpatient | E37: Demo Regional Medical Center | F37: Laboratory | G37: 2026-09-18 | H37: BMP-OP | I37: Basic Metabolic Panel | J37: 0301 | K37: 80048 | M37: 1 | N37: 185 | O37: =M37*N37 | P37: 114.83 | Q37: =P37*20% | R37: =O37-P37 | S37: Athena Health Insurance | T37: Athena PPO | V37: Eleanor Brooks, MD | W37: Assigned Department Provider | X37: LIS | Y37: Final result | Z37: Posted | AA37: Matched | AB37: Passed | AD37: Diagnosis/LCD | AE37: I10 | AF37: 22 | AG37: 2026-09-18 16:30 | AH37: Synthetic Athena negotiated charge
A38: OPD-CHG-0017-CGH | B38: OP-202600017-CGH | C38: CSN-OPD-780017-CGH | D38: Outpatient | E38: Demo Regional Medical Center | F38: Laboratory | G38: 2026-09-18 | H38: BMP-OP | I38: Basic Metabolic Panel | J38: 0301 | K38: 80048 | M38: 1 | N38: 185 | O38: =M38*N38 | P38: 103.35 | Q38: =P38*15% | R38: =O38-P38 | S38: Care Gap Health | T38: Care Gap Value PPO | V38: Eleanor Brooks, MD | W38: Assigned Department Provider | X38: LIS | Y38: Final result | Z38: Posted | AA38: Matched | AB38: Passed | AD38: Diagnosis/LCD | AE38: I10 | AF38: 22 | AG38: 2026-09-18 16:30 | AH38: Synthetic Care Gap charge; 10% below Athena allowed amount
A39: OPD-CHG-0018-ATH | B39: OP-202600018-ATH | C39: CSN-OPD-780018-ATH | D39: Outpatient | E39: Demo Regional Medical Center | F39: Laboratory | G39: 2026-09-19 | H39: A1C-OP | I39: Hemoglobin A1c | J39: 0301 | K39: 83036 | M39: 1 | N39: 110 | O39: =M39*N39 | P39: 53.27 | Q39: =P39*20% | R39: =O39-P39 | S39: Athena Health Insurance | T39: Athena PPO | V39: Eleanor Brooks, MD | W39: Assigned Department Provider | X39: LIS | Y39: Final result | Z39: Posted | AA39: Matched | AB39: Passed | AD39: Diagnosis/LCD | AE39: E11.9 | AF39: 22 | AG39: 2026-09-19 16:30 | AH39: Synthetic Athena negotiated charge
A40: OPD-CHG-0018-CGH | B40: OP-202600018-CGH | C40: CSN-OPD-780018-CGH | D40: Outpatient | E40: Demo Regional Medical Center | F40: Laboratory | G40: 2026-09-19 | H40: A1C-OP | I40: Hemoglobin A1c | J40: 0301 | K40: 83036 | M40: 1 | N40: 110 | O40: =M40*N40 | P40: 47.94 | Q40: =P40*15% | R40: =O40-P40 | S40: Care Gap Health | T40: Care Gap Value PPO | V40: Eleanor Brooks, MD | W40: Assigned Department Provider | X40: LIS | Y40: Final result | Z40: Posted | AA40: Matched | AB40: Passed | AD40: Diagnosis/LCD | AE40: E11.9 | AF40: 22 | AG40: 2026-09-19 16:30 | AH40: Synthetic Care Gap charge; 10% below Athena allowed amount
A41: OPD-CHG-0019-ATH | B41: OP-202600019-ATH | C41: CSN-OPD-780019-ATH | D41: Outpatient | E41: Demo Regional Medical Center | F41: Laboratory | G41: 2026-09-20 | H41: LIPID-OP | I41: Lipid Panel | J41: 0301 | K41: 80061 | M41: 1 | N41: 215 | O41: =M41*N41 | P41: 98.83 | Q41: =P41*20% | R41: =O41-P41 | S41: Athena Health Insurance | T41: Athena PPO | V41: Eleanor Brooks, MD | W41: Assigned Department Provider | X41: LIS | Y41: Final result | Z41: Posted | AA41: Matched | AB41: Passed | AD41: Diagnosis/LCD | AE41: E78.5 | AF41: 22 | AG41: 2026-09-20 16:30 | AH41: Synthetic Athena negotiated charge
...

Sheet Dashboard
A1: bsolutely original add multiple charges
A2: Executive view of CDM completeness, financial exposure, review status, and charge reconciliation.
A4: Active CDM Records | E4: Gross Charge Value | I4: Expected Allowed
A5: =COUNTIF('CDM Master'!AD:AD,"Active") | E5: =SUM('IPD Encounter'!R5:R15) | I5: =SUM('IPD Encounter'!S5:S15)
A8: Patient Responsibility | E8: Open Governance | I8: Active Claim Edits
A9: =SUM('IPD Encounter'!T5:T15) | E9: =COUNTIF(Governance!O:O,"<>Closed")-1 | I9: =COUNTIF('Claim Edits'!L:L,"Active")
A13: Department | B13: Gross Price Total
A14: Operating Room | B14: =SUMIF('CDM Master'!E:E,A14,'CDM Master'!O:O)
A15: Pharmacy | B15: =SUMIF('CDM Master'!E:E,A15,'CDM Master'!O:O)
A16: Radiology | B16: =SUMIF('CDM Master'!E:E,A16,'CDM Master'!O:O)
A17: Laboratory | B17: =SUMIF('CDM Master'!E:E,A17,'CDM Master'!O:O)
A18: Physical Therapy | B18: =SUMIF('CDM Master'!E:E,A18,'CDM Master'!O:O)
A19: Surgical Supplies | B19: =SUMIF('CDM Master'!E:E,A19,'CDM Master'!O:O)

Sheet CDM Master
A1: Charge Description Master (CDM)
A2: Enterprise master of billable facility items/services, coding, pricing, ownership, and lifecycle controls.
A4: Facility ID | B4: Location | C4: Service Area | D4: Department ID | E4: Department | F4: EAP/CDM Charge Code | G4: Charge Description | H4: Patient-Friendly Description | I4: Charge Type | J4: Revenue Code | K4: CPT/HCPCS | L4: Modifier | M4: NDC / Device ID | N4: Unit Basis | O4: Gross Unit Charge ($) | P4: Cost ($) | Q4: Markup % | R4: HCPCS Units | S4: Bill Area | T4: HB/PB | U4: Charge Trigger | V4: Source System | W4: Orderable/Procedure ID | X4: Price Tier | Y4: Taxable | Z4: Prior Auth Flag | AA4: Medical Necessity Rule | AB4: Effective Date | AC4: Termination Date | AD4: Status | AE4: Owner | AF4: Last Review Date | AG4: Next Review Date | AH4: Review Flag | AI4: Compliance Notes
A5: MAIN | B5: Main Campus | C5: HB | D5: D100 | E5: Inpatient Nursing | F5: RM-SP-001 | G5: Semiprivate Medical/Surgical Room | H5: Semiprivate hospital room | I5: Accommodation | J5: 0120 | N5: Per day | O5: 3500 | P5: 1200 | Q5: =IFERROR((O5-P5)/P5,0) | R5: 1 | S5: HB-NURS | T5: HB | U5: ADT discharge | V5: ADT | W5: BED-SP | X5: Standard | Y5: No | Z5: No | AA5: N/A | AB5: 2026-01-01 | AD5: Active | AE5: Director Revenue Integrity | AF5: 2026-07-15 | AG5: =EDATE(AF5,12) | AH5: =IF(AD5<>"Active","Inactive",IF(AG5<TODAY(),"Overdue",IF(AG5<=TODAY()+60,"Due Soon","Current")))
A6: MAIN | B6: Main Campus | C6: HB | D6: D105 | E6: Intensive Care | F6: ICU-DAY-001 | G6: Intensive Care Unit Room | H6: ICU room and monitoring | I6: Accommodation | J6: 0200 | N6: Per day | O6: 8000 | P6: 3500 | Q6: =IFERROR((O6-P6)/P6,0) | R6: 1 | S6: HB-ICU | T6: HB | U6: ADT bed event | V6: ADT | W6: BED-ICU | X6: Standard | Y6: No | Z6: No | AA6: N/A | AB6: 2026-01-01 | AD6: Active | AE6: Director Revenue Integrity | AF6: 2026-07-15 | AG6: =EDATE(AF6,12) | AH6: =IF(AD6<>"Active","Inactive",IF(AG6<TODAY(),"Overdue",IF(AG6<=TODAY()+60,"Due Soon","Current")))
A7: MAIN | B7: Main Campus | C7: HB | D7: D200 | E7: Operating Room | F7: OR-MAJOR-01 | G7: Major Operating Room, First Hour | H7: Operating room first hour | I7: Timed Service | J7: 0360 | N7: Per hour | O7: 10000 | P7: 4200 | Q7: =IFERROR((O7-P7)/P7,0) | R7: 1 | S7: HB-OR | T7: HB | U7: Procedure end | V7: OpTime | W7: PROC-OR-MAJ | X7: Standard | Y7: No | Z7: Yes | AA7: Procedure-specific | AB7: 2026-01-01 | AD7: Active | AE7: OR Finance Manager | AF7: 2026-08-01 | AG7: =EDATE(AF7,12) | AH7: =IF(AD7<>"Active","Inactive",IF(AG7<TODAY(),"Overdue",IF(AG7<=TODAY()+60,"Due Soon","Current")))
A8: MAIN | B8: Main Campus | C8: HB | D8: D200 | E8: Operating Room | F8: OR-ADD-15 | G8: Operating Room, Additional 15 Minutes | H8: Additional operating room time | I8: Timed Service | J8: 0360 | N8: Per 15 minutes | O8: 1250 | P8: 525 | Q8: =IFERROR((O8-P8)/P8,0) | R8: 1 | S8: HB-OR | T8: HB | U8: Procedure end | V8: OpTime | W8: PROC-OR-15 | X8: Standard | Y8: No | Z8: Yes | AA8: Procedure-specific | AB8: 2026-01-01 | AD8: Active | AE8: OR Finance Manager | AF8: 2026-08-01 | AG8: =EDATE(AF8,12) | AH8: =IF(AD8<>"Active","Inactive",IF(AG8<TODAY(),"Overdue",IF(AG8<=TODAY()+60,"Due Soon","Current")))
A9: MAIN | B9: Main Campus | C9: HB | D9: D210 | E9: Recovery Room | F9: RR-HR-001 | G9: Recovery Room, First Hour | H9: Recovery room first hour | I9: Timed Service | J9: 0710 | N9: Per hour | O9: 2000 | P9: 720 | Q9: =IFERROR((O9-P9)/P9,0) | R9: 1 | S9: HB-PACU | T9: HB | U9: PACU discharge | V9: OpTime | W9: PROC-PACU | X9: Standard | Y9: No | Z9: No | AA9: N/A | AB9: 2026-01-01 | AD9: Active | AE9: OR Finance Manager | AF9: 2026-08-01 | AG9: =EDATE(AF9,12) | AH9: =IF(AD9<>"Active","Inactive",IF(AG9<TODAY(),"Overdue",IF(AG9<=TODAY()+60,"Due Soon","Current")))
A10: MAIN | B10: Main Campus | C10: HB | D10: D220 | E10: Surgical Supplies | F10: IMP-KNEE-01 | G10: Cemented Knee Implant Package | H10: Knee implant package | I10: Implant | J10: 0278 | M10: DI-088590000001 | N10: Per implant | O10: 20000 | P10: 11500 | Q10: =IFERROR((O10-P10)/P10,0) | R10: 1 | S10: HB-SUP | T10: HB | U10: Implant scan | V10: Inventory | W10: ITEM-KNEE-CEM | X10: Carve-Out | Y10: No | Z10: Yes | AA10: Contract rule | AB10: 2026-01-01 | AD10: Active | AE10: Supply Chain Finance | AF10: 2026-06-30 | AG10: =EDATE(AF10,12) | AH10: =IF(AD10<>"Active","Inactive",IF(AG10<TODAY(),"Overdue",IF(AG10<=TODAY()+60,"Due Soon","Current")))
A11: MAIN | B11: Main Campus | C11: HB | D11: D220 | E11: Surgical Supplies | F11: SUP-KNEE-01 | G11: Knee Surgery Supply Pack | H11: Disposable knee surgery supplies | I11: Supply | J11: 0270 | N11: Per pack | O11: 4000 | P11: 1450 | Q11: =IFERROR((O11-P11)/P11,0) | R11: 1 | S11: HB-SUP | T11: HB | U11: Supply issue | V11: Inventory | W11: ITEM-KNEE-PACK | X11: Standard | Y11: No | Z11: No | AA11: N/A | AB11: 2026-01-01 | AD11: Active | AE11: Supply Chain Finance | AF11: 2026-06-30 | AG11: =EDATE(AF11,12) | AH11: =IF(AD11<>"Active","Inactive",IF(AG11<TODAY(),"Overdue",IF(AG11<=TODAY()+60,"Due Soon","Current")))
A12: MAIN | B12: Main Campus | C12: HB | D12: D300 | E12: Pharmacy | F12: PH-IV-ABX-01 | G12: Cefazolin 1 g Injection | H12: Cefazolin antibiotic injection | I12: Drug | J12: 0250 | K12: J0690 | M12: 00071-3069-23 | N12: Per 1 g | O12: 500 | P12: 42 | Q12: =IFERROR((O12-P12)/P12,0) | R12: 1 | S12: HB-PHAR | T12: HB | U12: Medication administration | V12: Willow/MAR | W12: MED-CEFAZ-1G | X12: Drug | Y12: No | Z12: No | AA12: Dose/frequency | AB12: 2026-01-01 | AD12: Active | AE12: Pharmacy Revenue Integrity | AF12: 2026-09-01 | AG12: =EDATE(AF12,12) | AH12: =IF(AD12<>"Active","Inactive",IF(AG12<TODAY(),"Overdue",IF(AG12<=TODAY()+60,"Due Soon","Current")))
A13: MAIN | B13: Main Campus | C13: HB | D13: D400 | E13: Laboratory | F13: LAB-CBC-001 | G13: Complete Blood Count with Automated Differential | H13: Complete blood count test | I13: Lab | J13: 0300 | K13: 85025 | N13: Per test | O13: 150 | P13: 22 | Q13: =IFERROR((O13-P13)/P13,0) | R13: 1 | S13: HB-LAB | T13: HB | U13: Final result | V13: LIS | W13: LAB-CBC | X13: Standard | Y13: No | Z13: No | AA13: Diagnosis/LCD | AB13: 2026-01-01 | AD13: Active | AE13: Lab Finance Manager | AF13: 2026-08-15 | AG13: =EDATE(AF13,12) | AH13: =IF(AD13<>"Active","Inactive",IF(AG13<TODAY(),"Overdue",IF(AG13<=TODAY()+60,"Due Soon","Current")))
