Workbook

Sheet README
A1: Original Hospital Revenue Cycle Charge Demo
A2: Independent synthetic demonstration workbook. It is not an Epic product, replica, extract, or proprietary build.
A4: Purpose | B4: Provides an original hospital revenue-cycle dataset with separate inpatient and outpatient charge-detail views, CDM controls, routing, billing edits, contracts, governance, and auditability.
A5: Epic alignment | B5: Uses common US hospital billing concepts such as hospital accounts, charge routing, workqueues, facility/professional split, institutional claims, and reimbursement. No proprietary EHR design is reproduced.
A6: Primary sheets | B6: CDM Master; IPD Encounter; Charge Router Rules; Claim Edits; Payer Contracts; Price Transparency; Governance; Audit Trail; Data Source Map; Data Dictionary; Dashboard.
A7: Color convention | B7: Blue = editable input; black = formula/derived; green = linked/imported; gray = static reference; orange = review; red = error/hold; purple = control logic; teal = KPI/visualization.
A8: Data disclaimer | B8: All patients, payers, prices, contracts, identifiers, effective dates, and operational scenarios are synthetic. No PHI is included.
A9: Sources | B9: Epic public financial interface documentation: https://open.epic.com/Financial/Billing CMS Hospital Price Transparency: https://www.cms.gov/priorities/key-initiatives/hospital-price-transparency CMS technical implementation guide: https://github.com/CMSgov/hospital-price-transparency

Sheet Charge Summary
A1: IPD and OPD Charge Summary
A2: Executive comparison of the 210 synthetic charge lines included in this workbook.
A4: Setting | B4: Charge Lines | C4: Gross Charges ($) | D4: Expected Allowed ($) | E4: Patient Responsibility ($) | F4: Adjustments ($) | G4: Held Charges | H4: Review Edits
A5: IPD | B5: =COUNTA('IPD Charges'!A5:A500) -> 110 | C5: =SUM('IPD Charges'!O:O) -> 1002840 | D5: =SUM('IPD Charges'!P:P) -> 555691.1 | E5: =SUM('IPD Charges'!Q:Q) -> 111138.22 | F5: =SUM('IPD Charges'!R:R) -> 447148.9 | G5: =COUNTIF('IPD Charges'!Z:Z,"Hold") -> 3 | H5: =COUNTIF('IPD Charges'!AB:AB,"Review") -> 7
A6: OPD | B6: =COUNTA('OPD Charges'!A5:A500) -> 100 | C6: =SUM('OPD Charges'!O:O) -> 250780 | D6: =SUM('OPD Charges'!P:P) -> 140185 | E6: =SUM('OPD Charges'!Q:Q) -> 28037 | F6: =SUM('OPD Charges'!R:R) -> 110595 | G6: =COUNTIF('OPD Charges'!Z:Z,"Hold") -> 3 | H6: =COUNTIF('OPD Charges'!AB:AB,"Review") -> 7
A7: TOTAL | B7: =SUM(B5:B6) -> 210 | C7: =SUM(C5:C6) -> 1253620 | D7: =SUM(D5:D6) -> 695876.1 | E7: =SUM(E5:E6) -> 139175.22 | F7: =SUM(F5:F6) -> 557743.9 | G7: =SUM(G5:G6) -> 6 | H7: =SUM(H5:H6) -> 14

Sheet IPD Charges
A1: Inpatient Charge Detail
A2: 110 original synthetic inpatient charge lines covering accommodation, surgery, implants, drugs, diagnostics, therapies, and ancillary services.
A4: Charge Line ID | B4: Patient Account | C4: Encounter ID | D4: Patient Class | E4: Facility | F4: Department | G4: Service Date | H4: Charge Code | I4: Charge Description | J4: Revenue Code | K4: CPT/HCPCS | L4: Modifier | M4: Quantity | N4: Unit Charge ($) | O4: Extended Gross ($) | P4: Expected Allowed ($) | Q4: Patient Responsibility ($) | R4: Contractual Adjustment ($) | S4: Payer | T4: Plan | U4: Authorization ID | V4: Ordering Provider | W4: Performing Provider | X4: Source System | Y4: Charge Trigger | Z4: Charge Status | AA4: Reconciliation Status | AB4: Claim Edit Status | AC4: Workqueue | AD4: Medical Necessity | AE4: Diagnosis Link | AF4: Place of Service | AG4: Posting Date/Time | AH4: Notes
A5: IPD-CHG-0001 | B5: HAR-202600001 | C5: CSN-IPD-780001 | D5: Inpatient | E5: Demo Regional Medical Center | F5: Accommodation | G5: 2026-09-02 | H5: RM-SEMI-DAY | I5: Semiprivate Medical/Surgical Room | J5: 0120 | M5: 1 | N5: 3500 | O5: =M5*N5 -> 3500 | P5: 1496.26 | Q5: =P5*20% -> 299.252 | R5: =O5-P5 -> 2003.74 | S5: Demo PPO | T5: Gold PPO | V5: Eleanor Brooks, MD | W5: Assigned Department Provider | X5: ADT | Y5: Midnight census | Z5: Posted | AA5: Matched | AB5: Passed | AD5: N/A | AE5: M17.11 | AF5: 21 | AG5: 2026-09-02 16:30 | AH5: Synthetic demonstration charge
A6: IPD-CHG-0002 | B6: HAR-202600002 | C6: CSN-IPD-780002 | D6: Inpatient | E6: Demo Regional Medical Center | F6: Accommodation | G6: 2026-09-03 | H6: RM-PRIV-DAY | I6: Private Medical/Surgical Room | J6: 0110 | M6: 3 | N6: 4600 | O6: =M6*N6 -> 13800 | P6: 6809.85 | Q6: =P6*20% -> 1361.97 | R6: =O6-P6 -> 6990.15 | S6: Demo PPO | T6: Gold PPO | V6: Eleanor Brooks, MD | W6: Assigned Department Provider | X6: ADT | Y6: Midnight census | Z6: Posted | AA6: Matched | AB6: Passed | AD6: N/A | AE6: M17.11 | AF6: 21 | AG6: 2026-09-03 16:30 | AH6: Synthetic demonstration charge
A7: IPD-CHG-0003 | B7: HAR-202600003 | C7: CSN-IPD-780003 | D7: Inpatient | E7: Demo Regional Medical Center | F7: Intensive Care | G7: 2026-09-04 | H7: ICU-DAY | I7: Intensive Care Unit Room | J7: 0200 | M7: 2 | N7: 8200 | O7: =M7*N7 -> 16400 | P7: 10511.44 | Q7: =P7*20% -> 2102.288 | R7: =O7-P7 -> 5888.56 | S7: Demo PPO | T7: Gold PPO | V7: Eleanor Brooks, MD | W7: Assigned Department Provider | X7: ADT | Y7: Midnight census | Z7: Posted | AA7: Matched | AB7: Passed | AD7: N/A | AE7: J96.01 | AF7: 21 | AG7: 2026-09-04 16:30 | AH7: Synthetic demonstration charge
A8: IPD-CHG-0004 | B8: HAR-202600004 | C8: CSN-IPD-780004 | D8: Inpatient | E8: Demo Regional Medical Center | F8: Operating Room | G8: 2026-09-05 | H8: OR-MAJOR-1H | I8: Major Operating Room, First Hour | J8: 0360 | M8: 1 | N8: 10250 | O8: =M8*N8 -> 10250 | P8: 6120.76 | Q8: =P8*20% -> 1224.152 | R8: =O8-P8 -> 4129.24 | S8: Demo PPO | T8: Gold PPO | V8: Eleanor Brooks, MD | W8: Assigned Department Provider | X8: Perioperative | Y8: Procedure end | Z8: Posted | AA8: Matched | AB8: Passed | AD8: Procedure-specific | AE8: M17.11 | AF8: 21 | AG8: 2026-09-05 16:30 | AH8: Synthetic demonstration charge
A9: IPD-CHG-0005 | B9: HAR-202600005 | C9: CSN-IPD-780005 | D9: Inpatient | E9: Demo Regional Medical Center | F9: Operating Room | G9: 2026-09-06 | H9: OR-ADD-15 | I9: Operating Room, Additional 15 Minutes | J9: 0360 | M9: 2 | N9: 1280 | O9: =M9*N9 -> 2560 | P9: 1098.08 | Q9: =P9*20% -> 219.616 | R9: =O9-P9 -> 1461.92 | S9: Demo PPO | T9: Gold PPO | V9: Eleanor Brooks, MD | W9: Assigned Department Provider | X9: Perioperative | Y9: Procedure end | Z9: Posted | AA9: Matched | AB9: Passed | AD9: Procedure-specific | AE9: M17.11 | AF9: 21 | AG9: 2026-09-06 16:30 | AH9: Synthetic demonstration charge
A10: IPD-CHG-0006 | B10: HAR-202600006 | C10: CSN-IPD-780006 | D10: Inpatient | E10: Demo Regional Medical Center | F10: Recovery Room | G10: 2026-09-07 | H10: PACU-1H | I10: Post-Anesthesia Care, First Hour | J10: 0710 | M10: 1 | N10: 2100 | O10: =M10*N10 -> 2100 | P10: 1019.74 | Q10: =P10*20% -> 203.948 | R10: =O10-P10 -> 1080.26 | S10: Demo PPO | T10: Gold PPO | V10: Eleanor Brooks, MD | W10: Assigned Department Provider | X10: Perioperative | Y10: PACU discharge | Z10: Posted | AA10: Matched | AB10: Passed | AD10: N/A | AE10: Z47.1 | AF10: 21 | AG10: 2026-09-07 16:30 | AH10: Synthetic demonstration charge
A11: IPD-CHG-0007 | B11: HAR-202600007 | C11: CSN-IPD-780007 | D11: Inpatient | E11: Demo Regional Medical Center | F11: Surgical Supplies | G11: 2026-09-08 | H11: SUP-MAJOR-PACK | I11: Major Surgery Disposable Supply Pack | J11: 0270 | M11: 1 | N11: 4200 | O11: =M11*N11 -> 4200 | P11: 2400.75 | Q11: =P11*20% -> 480.15 | R11: =O11-P11 -> 1799.25 | S11: Demo PPO | T11: Gold PPO | V11: Eleanor Brooks, MD | W11: Assigned Department Provider | X11: Inventory | Y11: Supply issue | Z11: Posted | AA11: Matched | AB11: Passed | AD11: Contract rule | AE11: Z47.1 | AF11: 21 | AG11: 2026-09-08 16:30 | AH11: Synthetic demonstration charge
A12: IPD-CHG-0008 | B12: HAR-202600008 | C12: CSN-IPD-780008 | D12: Inpatient | E12: Demo Regional Medical Center | F12: Implants | G12: 2026-09-09 | H12: IMP-KNEE-CEM | I12: Cemented Knee Implant System | J12: 0278 | M12: 1 | N12: 20500 | O12: =M12*N12 -> 20500 | P12: 8773.2 | Q12: =P12*20% -> 1754.64 | R12: =O12-P12 -> 11726.8 | S12: Demo PPO | T12: Gold PPO | V12: Eleanor Brooks, MD | W12: Assigned Department Provider | X12: Inventory | Y12: Implant scan | Z12: Posted | AA12: Matched | AB12: Passed | AD12: Contract rule | AE12: M17.11 | AF12: 21 | AG12: 2026-09-09 16:30 | AH12: Synthetic demonstration charge
A13: IPD-CHG-0009 | B13: HAR-202600009 | C13: CSN-IPD-780009 | D13: Inpatient | E13: Demo Regional Medical Center | F13: Implants | G13: 2026-09-10 | H13: IMP-SCREW | I13: Orthopedic Fixation Screw | J13: 0278 | K13: C1713 | M13: 1 | N13: 950 | O13: =M13*N13 -> 950 | P13: 455.67 | Q13: =P13*20% -> 91.134 | R13: =O13-P13 -> 494.33 | S13: Demo PPO | T13: Gold PPO | V13: Eleanor Brooks, MD | W13: Assigned Department Provider | X13: Inventory | Y13: Implant scan | Z13: Posted | AA13: Matched | AB13: Passed | AD13: Contract rule | AE13: M17.11 | AF13: 21 | AG13: 2026-09-10 16:30 | AH13: Synthetic demonstration charge
A14: IPD-CHG-0010 | B14: HAR-202600010 | C14: CSN-IPD-780010 | D14: Inpatient | E14: Demo Regional Medical Center | F14: Pharmacy | G14: 2026-09-11 | H14: DRUG-CEFA-1G | I14: Cefazolin 1 g Injection | J14: 0250 | K14: J0690 | M14: 3 | N14: 500 | O14: =M14*N14 -> 1500 | P14: 945.6 | Q14: =P14*20% -> 189.12 | R14: =O14-P14 -> 554.4 | S14: Demo PPO | T14: Gold PPO | V14: Eleanor Brooks, MD | W14: Assigned Department Provider | X14: Pharmacy MAR | Y14: Medication administration | Z14: Posted | AA14: Matched | AB14: Passed | AD14: Dose/frequency | AE14: Z79.2 | AF14: 21 | AG14: 2026-09-11 16:30 | AH14: Synthetic demonstration charge
A15: IPD-CHG-0011 | B15: HAR-202600011 | C15: CSN-IPD-780011 | D15: Inpatient | E15: Demo Regional Medical Center | F15: Pharmacy | G15: 2026-09-12 | H15: DRUG-VANC-500 | I15: Vancomycin 500 mg Injection | J15: 0250 | K15: J3370 | M15: 2 | N15: 680 | O15: =M15*N15 -> 1360 | P15: 661.14 | Q15: =P15*20% -> 132.228 | R15: =O15-P15 -> 698.86 | S15: Demo PPO | T15: Gold PPO | V15: Eleanor Brooks, MD | W15: Assigned Department Provider | X15: Pharmacy MAR | Y15: Medication administration | Z15: Posted | AA15: Matched | AB15: Passed | AD15: Dose/frequency | AE15: Z79.2 | AF15: 21 | AG15: 2026-09-12 16:30 | AH15: Synthetic demonstration charge
A16: IPD-CHG-0012 | B16: HAR-202600012 | C16: CSN-IPD-780012 | D16: Inpatient | E16: Demo Regional Medical Center | F16: Pharmacy | G16: 2026-09-13 | H16: IV-NS-1L | I16: Normal Saline 1,000 mL | J16: 0258 | K16: J7030 | M16: 3 | N16: 90 | O16: =M16*N16 -> 270 | P16: 135.93 | Q16: =P16*20% -> 27.186 | R16: =O16-P16 -> 134.07 | S16: Demo PPO | T16: Gold PPO | V16: Eleanor Brooks, MD | W16: Assigned Department Provider | X16: Pharmacy MAR | Y16: Medication administration | Z16: Posted | AA16: Matched | AB16: Passed | AD16: N/A | AE16: E86.0 | AF16: 21 | AG16: 2026-09-13 16:30 | AH16: Synthetic demonstration charge
A17: IPD-CHG-0013 | B17: HAR-202600013 | C17: CSN-IPD-780013 | D17: Inpatient | E17: Demo Regional Medical Center | F17: Laboratory | G17: 2026-09-14 | H17: LAB-CBC | I17: Complete Blood Count with Differential | J17: 0300 | K17: 85025 | M17: 1 | N17: 155 | O17: =M17*N17 -> 155 | P17: 105.52 | Q17: =P17*20% -> 21.104 | R17: =O17-P17 -> 49.48 | S17: Demo PPO | T17: Gold PPO | V17: Eleanor Brooks, MD | W17: Assigned Department Provider | X17: LIS | Y17: Final result | Z17: Posted | AA17: Matched | AB17: Passed | AD17: Diagnosis/LCD | AE17: D64.9 | AF17: 21 | AG17: 2026-09-14 16:30 | AH17: Synthetic demonstration charge
A18: IPD-CHG-0014 | B18: HAR-202600014 | C18: CSN-IPD-780014 | D18: Inpatient | E18: Demo Regional Medical Center | F18: Laboratory | G18: 2026-09-15 | H18: LAB-CMP | I18: Comprehensive Metabolic Panel | J18: 0301 | K18: 80053 | M18: 1 | N18: 245 | O18: =M18*N18 -> 245 | P18: 158.67 | Q18: =P18*20% -> 31.734 | R18: =O18-P18 -> 86.33 | S18: Demo PPO | T18: Gold PPO | V18: Eleanor Brooks, MD | W18: Assigned Department Provider | X18: LIS | Y18: Final result | Z18: Posted | AA18: Matched | AB18: Passed | AD18: Diagnosis/LCD | AE18: E11.9 | AF18: 21 | AG18: 2026-09-15 16:30 | AH18: Synthetic demonstration charge
A19: IPD-CHG-0015 | B19: HAR-202600015 | C19: CSN-IPD-780015 | D19: Inpatient | E19: Demo Regional Medical Center | F19: Laboratory | G19: 2026-09-16 | H19: LAB-PTINR | I19: Prothrombin Time / INR | J19: 0305 | K19: 85610 | M19: 1 | N19: 125 | O19: =M19*N19 -> 125 | P19: 58.49 | Q19: =P19*20% -> 11.698 | R19: =O19-P19 -> 66.51 | S19: Demo PPO | T19: Gold PPO | V19: Eleanor Brooks, MD | W19: Assigned Department Provider | X19: LIS | Y19: Final result | Z19: Posted | AA19: Matched | AB19: Passed | AD19: Diagnosis/LCD | AE19: Z79.01 | AF19: 21 | AG19: 2026-09-16 16:30 | AH19: Synthetic demonstration charge
A20: IPD-CHG-0016 | B20: HAR-202600016 | C20: CSN-IPD-780016 | D20: Inpatient | E20: Demo Regional Medical Center | F20: Radiology | G20: 2026-09-17 | H20: RAD-CHEST-2V | I20: Chest X-ray, 2 Views | J20: 0320 | K20: 71046 | M20: 1 | N20: 185 | O20: =M20*N20 -> 185 | P20: 101.16 | Q20: =P20*20% -> 20.232 | R20: =O20-P20 -> 83.84 | S20: Demo PPO | T20: Gold PPO | V20: Eleanor Brooks, MD | W20: Assigned Department Provider | X20: RIS/PACS | Y20: Exam completed | Z20: Posted | AA20: Matched | AB20: Passed | AD20: Diagnosis/LCD | AE20: R06.02 | AF20: 21 | AG20: 2026-09-17 16:30 | AH20: Synthetic demonstration charge
A21: IPD-CHG-0017 | B21: HAR-202600017 | C21: CSN-IPD-780017 | D21: Inpatient | E21: Demo Regional Medical Center | F21: Radiology | G21: 2026-09-18 | H21: RAD-KNEE-2V | I21: Knee X-ray, 1-2 Views | J21: 0320 | K21: 73560 | M21: 1 | N21: 410 | O21: =M21*N21 -> 410 | P21: 206.38 | Q21: =P21*20% -> 41.276 | R21: =O21-P21 -> 203.62 | S21: Demo PPO | T21: Gold PPO | V21: Eleanor Brooks, MD | W21: Assigned Department Provider | X21: RIS/PACS | Y21: Exam completed | Z21: Posted | AA21: Matched | AB21: Passed | AD21: Diagnosis/LCD | AE21: M25.561 | AF21: 21 | AG21: 2026-09-18 16:30 | AH21: Synthetic demonstration charge
A22: IPD-CHG-0018 | B22: HAR-202600018 | C22: CSN-IPD-780018 | D22: Inpatient | E22: Demo Regional Medical Center | F22: Cardiology | G22: 2026-09-19 | H22: CARD-ECG12 | I22: 12-Lead ECG | J22: 0730 | K22: 93005 | M22: 1 | N22: 190 | O22: =M22*N22 -> 190 | P22: 92.07 | Q22: =P22*20% -> 18.414 | R22: =O22-P22 -> 97.93 | S22: Demo PPO | T22: Gold PPO | V22: Eleanor Brooks, MD | W22: Assigned Department Provider | X22: Cardiology | Y22: Test completed | Z22: Posted | AA22: Matched | AB22: Passed | AD22: Diagnosis/LCD | AE22: R07.9 | AF22: 21 | AG22: 2026-09-19 16:30 | AH22: Synthetic demonstration charge
A23: IPD-CHG-0019 | B23: HAR-202600019 | C23: CSN-IPD-780019 | D23: Inpatient | E23: Demo Regional Medical Center | F23: Respiratory | G23: 2026-09-20 | H23: RESP-NEB | I23: Nebulizer Treatment | J23: 0410 | K23: 94640 | M23: 1 | N23: 245 | O23: =M23*N23 -> 245 | P23: 159.02 | Q23: =P23*20% -> 31.804 | R23: =O23-P23 -> 85.98 | S23: Demo PPO | T23: Gold PPO | V23: Eleanor Brooks, MD | W23: Assigned Department Provider | X23: Respiratory | Y23: Treatment completed | Z23: Posted | AA23: Matched | AB23: Passed | AD23: Diagnosis/LCD | AE23: J45.901 | AF23: 21 | AG23: 2026-09-20 16:30 | AH23: Synthetic demonstration charge
A24: IPD-CHG-0020 | B24: HAR-202600020 | C24: CSN-IPD-780020 | D24: Inpatient | E24: Demo Regional Medical Center | F24: Physical Therapy | G24: 2026-09-21 | H24: PT-EVAL-LOW | I24: Physical Therapy Evaluation, Low Complexity | J24: 0420 | K24: 97161 | M24: 1 | N24: 710 | O24: =M24*N24 -> 710 | P24: 319.97 | Q24: =P24*20% -> 63.994 | R24: =O24-P24 -> 390.03 | S24: Demo PPO | T24: Gold PPO | U24: AUTH-700020 | V24: Eleanor Brooks, MD | W24: Assigned Department Provider | X24: Therapy | Y24: Note signed | Z24: Posted | AA24: Matched | AB24: Passed | AD24: Plan benefits | AE24: R26.2 | AF24: 21 | AG24: 2026-09-21 16:30 | AH24: Synthetic demonstration charge
A25: IPD-CHG-0021 | B25: HAR-202600021 | C25: CSN-IPD-780021 | D25: Inpatient | E25: Demo Regional Medical Center | F25: Physical Therapy | G25: 2026-09-22 | H25: PT-THEREX-15 | I25: Therapeutic Exercise, 15 Minutes | J25: 0420 | K25: 97110 | M25: 6 | N25: 305 | O25: =M25*N25 -> 1830 | P25: 821.7 | Q25: =P25*20% -> 164.34 | R25: =O25-P25 -> 1008.3 | S25: Demo PPO | T25: Gold PPO | V25: Eleanor Brooks, MD | W25: Assigned Department Provider | X25: Therapy | Y25: Note signed | Z25: Posted | AA25: Matched | AB25: Passed | AD25: Timed units | AE25: M62.81 | AF25: 21 | AG25: 2026-09-22 16:30 | AH25: Synthetic demonstration charge
A26: IPD-CHG-0022 | B26: HAR-202600022 | C26: CSN-IPD-780022 | D26: Inpatient | E26: Demo Regional Medical Center | F26: Occupational Therapy | G26: 2026-09-23 | H26: OT-EVAL-LOW | I26: Occupational Therapy Evaluation, Low Complexity | J26: 0430 | K26: 97165 | M26: 1 | N26: 725 | O26: =M26*N26 -> 725 | P26: 488.83 | Q26: =P26*20% -> 97.766 | R26: =O26-P26 -> 236.17 | S26: Demo PPO | T26: Gold PPO | U26: AUTH-700022 | V26: Eleanor Brooks, MD | W26: Assigned Department Provider | X26: Therapy | Y26: Note signed | Z26: Posted | AA26: Matched | AB26: Passed | AD26: Plan benefits | AE26: Z74.09 | AF26: 21 | AG26: 2026-09-23 16:30 | AH26: Synthetic demonstration charge
A27: IPD-CHG-0023 | B27: HAR-202600023 | C27: CSN-IPD-780023 | D27: Inpatient | E27: Demo Regional Medical Center | F27: Nutrition | G27: 2026-09-24 | H27: NUTR-ASSESS | I27: Inpatient Nutrition Assessment | J27: 0942 | K27: 97802 | M27: 1 | N27: 325 | O27: =M27*N27 -> 325 | P27: 195.36 | Q27: =P27*20% -> 39.072 | R27: =O27-P27 -> 129.64 | S27: Demo PPO | T27: Gold PPO | V27: Eleanor Brooks, MD | W27: Assigned Department Provider | X27: Dietary | Y27: Note signed | Z27: Posted | AA27: Matched | AB27: Review | AC27: WQ-NUT-04 | AD27: N/A | AE27: E44.1 | AF27: 21 | AG27: 2026-09-24 16:30 | AH27: Synthetic demonstration charge
A28: IPD-CHG-0024 | B28: HAR-202600024 | C28: CSN-IPD-780024 | D28: Inpatient | E28: Demo Regional Medical Center | F28: Dialysis | G28: 2026-09-25 | H28: DIALYSIS-IP | I28: Inpatient Hemodialysis Treatment | J28: 0801 | K28: 90935 | M28: 1 | N28: 1600 | O28: =M28*N28 -> 1600 | P28: 1059.42 | Q28: =P28*20% -> 211.884 | R28: =O28-P28 -> 540.58 | S28: Demo PPO | T28: Gold PPO | V28: Eleanor Brooks, MD | W28: Assigned Department Provider | X28: Dialysis | Y28: Treatment completed | Z28: Posted | AA28: Matched | AB28: Passed | AD28: Diagnosis/LCD | AE28: N18.6 | AF28: 21 | AG28: 2026-09-25 16:30 | AH28: Synthetic demonstration charge
A29: IPD-CHG-0025 | B29: HAR-202600025 | C29: CSN-IPD-780025 | D29: Inpatient | E29: Demo Regional Medical Center | F29: Accommodation | G29: 2026-09-01 | H29: RM-SEMI-DAY | I29: Semiprivate Medical/Surgical Room | J29: 0120 | M29: 4 | N29: 3500 | O29: =M29*N29 -> 14000 | P29: 8132.16 | Q29: =P29*20% -> 1626.432 | R29: =O29-P29 -> 5867.84 | S29: Demo PPO | T29: Gold PPO | V29: Eleanor Brooks, MD | W29: Assigned Department Provider | X29: ADT | Y29: Midnight census | Z29: Posted | AA29: Matched | AB29: Passed | AD29: N/A | AE29: M17.11 | AF29: 21 | AG29: 2026-09-01 16:30 | AH29: Synthetic demonstration charge
A30: IPD-CHG-0026 | B30: HAR-202600026 | C30: CSN-IPD-780026 | D30: Inpatient | E30: Demo Regional Medical Center | F30: Accommodation | G30: 2026-09-02 | H30: RM-PRIV-DAY | I30: Private Medical/Surgical Room | J30: 0110 | M30: 4 | N30: 4600 | O30: =M30*N30 -> 18400 | P30: 8162.98 | Q30: =P30*20% -> 1632.596 | R30: =O30-P30 -> 10237.02 | S30: Demo PPO | T30: Gold PPO | V30: Eleanor Brooks, MD | W30: Assigned Department Provider | X30: ADT | Y30: Midnight census | Z30: Posted | AA30: Matched | AB30: Passed | AD30: N/A | AE30: M17.11 | AF30: 21 | AG30: 2026-09-02 16:30 | AH30: Synthetic demonstration charge
A31: IPD-CHG-0027 | B31: HAR-202600027 | C31: CSN-IPD-780027 | D31: Inpatient | E31: Demo Regional Medical Center | F31: Intensive Care | G31: 2026-09-03 | H31: ICU-DAY | I31: Intensive Care Unit Room | J31: 0200 | M31: 3 | N31: 8200 | O31: =M31*N31 -> 24600 | P31: 16453.01 | Q31: =P31*20% -> 3290.602 | R31: =O31-P31 -> 8146.99 | S31: Demo PPO | T31: Gold PPO | V31: Eleanor Brooks, MD | W31: Assigned Department Provider | X31: ADT | Y31: Midnight census | Z31: Posted | AA31: Matched | AB31: Passed | AD31: N/A | AE31: J96.01 | AF31: 21 | AG31: 2026-09-03 16:30 | AH31: Synthetic demonstration charge
A32: IPD-CHG-0028 | B32: HAR-202600028 | C32: CSN-IPD-780028 | D32: Inpatient | E32: Demo Regional Medical Center | F32: Operating Room | G32: 2026-09-04 | H32: OR-MAJOR-1H | I32: Major Operating Room, First Hour | J32: 0360 | M32: 3 | N32: 10250 | O32: =M32*N32 -> 30750 | P32: 18241.07 | Q32: =P32*20% -> 3648.214 | R32: =O32-P32 -> 12508.93 | S32: Demo PPO | T32: Gold PPO | V32: Eleanor Brooks, MD | W32: Assigned Department Provider | X32: Perioperative | Y32: Procedure end | Z32: Posted | AA32: Matched | AB32: Passed | AD32: Procedure-specific | AE32: M17.11 | AF32: 21 | AG32: 2026-09-04 16:30 | AH32: Synthetic demonstration charge
A33: IPD-CHG-0029 | B33: HAR-202600029 | C33: CSN-IPD-780029 | D33: Inpatient | E33: Demo Regional Medical Center | F33: Operating Room | G33: 2026-09-05 | H33: OR-ADD-15 | I33: Operating Room, Additional 15 Minutes | J33: 0360 | M33: 2 | N33: 1280 | O33: =M33*N33 -> 2560 | P33: 1110.39 | Q33: =P33*20% -> 222.078 | R33: =O33-P33 -> 1449.61 | S33: Demo PPO | T33: Gold PPO | V33: Eleanor Brooks, MD | W33: Assigned Department Provider | X33: Perioperative | Y33: Procedure end | Z33: Hold | AA33: Exception | AB33: Review | AC33: WQ-OPE-02 | AD33: Procedure-specific | AE33: M17.11 | AF33: 21 | AG33: 2026-09-05 16:30 | AH33: Synthetic demonstration charge
A34: IPD-CHG-0030 | B34: HAR-202600030 | C34: CSN-IPD-780030 | D34: Inpatient | E34: Demo Regional Medical Center | F34: Recovery Room | G34: 2026-09-06 | H34: PACU-1H | I34: Post-Anesthesia Care, First Hour | J34: 0710 | M34: 1 | N34: 2100 | O34: =M34*N34 -> 2100 | P34: 1025.58 | Q34: =P34*20% -> 205.116 | R34: =O34-P34 -> 1074.42 | S34: Demo PPO | T34: Gold PPO | V34: Eleanor Brooks, MD | W34: Assigned Department Provider | X34: Perioperative | Y34: PACU discharge | Z34: Posted | AA34: Matched | AB34: Passed | AD34: N/A | AE34: Z47.1 | AF34: 21 | AG34: 2026-09-06 16:30 | AH34: Synthetic demonstration charge
A35: IPD-CHG-0031 | B35: HAR-202600031 | C35: CSN-IPD-780031 | D35: Inpatient | E35: Demo Regional Medical Center | F35: Surgical Supplies | G35: 2026-09-07 | H35: SUP-MAJOR-PACK | I35: Major Surgery Disposable Supply Pack | J35: 0270 | M35: 1 | N35: 4200 | O35: =M35*N35 -> 4200 | P35: 2128.63 | Q35: =P35*20% -> 425.726 | R35: =O35-P35 -> 2071.37 | S35: Demo PPO | T35: Gold PPO | V35: Eleanor Brooks, MD | W35: Assigned Department Provider | X35: Inventory | Y35: Supply issue | Z35: Posted | AA35: Matched | AB35: Passed | AD35: Contract rule | AE35: Z47.1 | AF35: 21 | AG35: 2026-09-07 16:30 | AH35: Synthetic demonstration charge
A36: IPD-CHG-0032 | B36: HAR-202600032 | C36: CSN-IPD-780032 | D36: Inpatient | E36: Demo Regional Medical Center | F36: Implants | G36: 2026-09-08 | H36: IMP-KNEE-CEM | I36: Cemented Knee Implant System | J36: 0278 | M36: 1 | N36: 20500 | O36: =M36*N36 -> 20500 | P36: 9100.72 | Q36: =P36*20% -> 1820.144 | R36: =O36-P36 -> 11399.28 | S36: Demo PPO | T36: Gold PPO | V36: Eleanor Brooks, MD | W36: Assigned Department Provider | X36: Inventory | Y36: Implant scan | Z36: Posted | AA36: Matched | AB36: Passed | AD36: Contract rule | AE36: M17.11 | AF36: 21 | AG36: 2026-09-08 16:30 | AH36: Synthetic demonstration charge
A37: IPD-CHG-0033 | B37: HAR-202600033 | C37: CSN-IPD-780033 | D37: Inpatient | E37: Demo Regional Medical Center | F37: Implants | G37: 2026-09-09 | H37: IMP-SCREW | I37: Orthopedic Fixation Screw | J37: 0278 | K37: C1713 | M37: 1 | N37: 950 | O37: =M37*N37 -> 950 | P37: 465.35 | Q37: =P37*20% -> 93.07 | R37: =O37-P37 -> 484.65 | S37: Demo PPO | T37: Gold PPO | V37: Eleanor Brooks, MD | W37: Assigned Department Provider | X37: Inventory | Y37: Implant scan | Z37: Posted | AA37: Matched | AB37: Passed | AD37: Contract rule | AE37: M17.11 | AF37: 21 | AG37: 2026-09-09 16:30 | AH37: Synthetic demonstration charge
A38: IPD-CHG-0034 | B38: HAR-202600034 | C38: CSN-IPD-780034 | D38: Inpatient | E38: Demo Regional Medical Center | F38: Pharmacy | G38: 2026-09-10 | H38: DRUG-CEFA-1G | I38: Cefazolin 1 g Injection | J38: 0250 | K38: J0690 | M38: 1 | N38: 500 | O38: =M38*N38 -> 500 | P38: 267.02 | Q38: =P38*20% -> 53.404 | R38: =O38-P38 -> 232.98 | S38: Demo PPO | T38: Gold PPO | V38: Eleanor Brooks, MD | W38: Assigned Department Provider | X38: Pharmacy MAR | Y38: Medication administration | Z38: Posted | AA38: Matched | AB38: Passed | AD38: Dose/frequency | AE38: Z79.2 | AF38: 21 | AG38: 2026-09-10 16:30 | AH38: Synthetic demonstration charge
A39: IPD-CHG-0035 | B39: HAR-202600035 | C39: CSN-IPD-780035 | D39: Inpatient | E39: Demo Regional Medical Center | F39: Pharmacy | G39: 2026-09-11 | H39: DRUG-VANC-500 | I39: Vancomycin 500 mg Injection | J39: 0250 | K39: J3370 | M39: 2 | N39: 680 | O39: =M39*N39 -> 1360 | P39: 830.56 | Q39: =P39*20% -> 166.112 | R39: =O39-P39 -> 529.44 | S39: Demo PPO | T39: Gold PPO | V39: Eleanor Brooks, MD | W39: Assigned Department Provider | X39: Pharmacy MAR | Y39: Medication administration | Z39: Posted | AA39: Matched | AB39: Passed | AD39: Dose/frequency | AE39: Z79.2 | AF39: 21 | AG39: 2026-09-11 16:30 | AH39: Synthetic demonstration charge
A40: IPD-CHG-0036 | B40: HAR-202600036 | C40: CSN-IPD-780036 | D40: Inpatient | E40: Demo Regional Medical Center | F40: Pharmacy | G40: 2026-09-12 | H40: IV-NS-1L | I40: Normal Saline 1,000 mL | J40: 0258 | K40: J7030 | M40: 2 | N40: 90 | O40: =M40*N40 -> 180 | P40: 84.38 | Q40: =P40*20% -> 16.876 | R40: =O40-P40 -> 95.62 | S40: Demo PPO | T40: Gold PPO | V40: Eleanor Brooks, MD | W40: Assigned Department Provider | X40: Pharmacy MAR | Y40: Medication administration | Z40: Posted | AA40: Matched | AB40: Passed | AD40: N/A | AE40: E86.0 | AF40: 21 | AG40: 2026-09-12 16:30 | AH40: Synthetic demonstration charge
A41: IPD-CHG-0037 | B41: HAR-202600037 | C41: CSN-IPD-780037 | D41: Inpatient | E41: Demo Regional Medical Center | F41: Laboratory | G41: 2026-09-13 | H41: LAB-CBC | I41: Complete Blood Count with Differential | J41: 0300 | K41: 85025 | M41: 1 | N41: 155 | O41: =M41*N41 -> 155 | P41: 81.62 | Q41: =P41*20% -> 16.324 | R41: =O41-P41 -> 73.38 | S41: Demo PPO | T41: Gold PPO | V41: Eleanor Brooks, MD | W41: Assigned Department Provider | X41: LIS | Y41: Final result | Z41: Posted | AA41: Matched | AB41: Passed | AD41: Diagnosis/LCD | AE41: D64.9 | AF41: 21 | AG41: 2026-09-13 16:30 | AH41: Synthetic demonstration charge
...

Sheet OPD Charges
A1: Outpatient Charge Detail
A2: 100 original synthetic outpatient charge lines covering emergency, clinic, diagnostics, procedures, therapies, infusion, and ancillary services.
A4: Charge Line ID | B4: Patient Account | C4: Encounter ID | D4: Patient Class | E4: Facility | F4: Department | G4: Service Date | H4: Charge Code | I4: Charge Description | J4: Revenue Code | K4: CPT/HCPCS | L4: Modifier | M4: Quantity | N4: Unit Charge ($) | O4: Extended Gross ($) | P4: Expected Allowed ($) | Q4: Patient Responsibility ($) | R4: Contractual Adjustment ($) | S4: Payer | T4: Plan | U4: Authorization ID | V4: Ordering Provider | W4: Performing Provider | X4: Source System | Y4: Charge Trigger | Z4: Charge Status | AA4: Reconciliation Status | AB4: Claim Edit Status | AC4: Workqueue | AD4: Medical Necessity | AE4: Diagnosis Link | AF4: Place of Service | AG4: Posting Date/Time | AH4: Notes
A5: OPD-CHG-0001 | B5: OP-202600001 | C5: CSN-OPD-780001 | D5: Outpatient | E5: Demo Regional Medical Center | F5: Emergency Department | G5: 2026-09-02 | H5: ED-LEVEL-1 | I5: Emergency Department Visit Level 1 | J5: 0450 | K5: 99281 | M5: 1 | N5: 360 | O5: =M5*N5 -> 360 | P5: 221.39 | Q5: =P5*20% -> 44.278 | R5: =O5-P5 -> 138.61 | S5: Demo PPO | T5: Gold PPO | V5: Eleanor Brooks, MD | W5: Assigned Department Provider | X5: ED | Y5: Encounter close | Z5: Posted | AA5: Matched | AB5: Passed | AD5: Documentation | AE5: R50.9 | AF5: 22 | AG5: 2026-09-02 16:30 | AH5: Synthetic demonstration charge
A6: OPD-CHG-0002 | B6: OP-202600002 | C6: CSN-OPD-780002 | D6: Outpatient | E6: Demo Regional Medical Center | F6: Emergency Department | G6: 2026-09-03 | H6: ED-LEVEL-2 | I6: Emergency Department Visit Level 2 | J6: 0450 | K6: 99282 | M6: 1 | N6: 670 | O6: =M6*N6 -> 670 | P6: 369.46 | Q6: =P6*20% -> 73.892 | R6: =O6-P6 -> 300.54 | S6: Demo PPO | T6: Gold PPO | V6: Eleanor Brooks, MD | W6: Assigned Department Provider | X6: ED | Y6: Encounter close | Z6: Posted | AA6: Matched | AB6: Passed | AD6: Documentation | AE6: R51.9 | AF6: 22 | AG6: 2026-09-03 16:30 | AH6: Synthetic demonstration charge
A7: OPD-CHG-0003 | B7: OP-202600003 | C7: CSN-OPD-780003 | D7: Outpatient | E7: Demo Regional Medical Center | F7: Emergency Department | G7: 2026-09-04 | H7: ED-LEVEL-3 | I7: Emergency Department Visit Level 3 | J7: 0450 | K7: 99283 | M7: 1 | N7: 1280 | O7: =M7*N7 -> 1280 | P7: 736.35 | Q7: =P7*20% -> 147.27 | R7: =O7-P7 -> 543.65 | S7: Demo PPO | T7: Gold PPO | V7: Eleanor Brooks, MD | W7: Assigned Department Provider | X7: ED | Y7: Encounter close | Z7: Posted | AA7: Matched | AB7: Passed | AD7: Documentation | AE7: R10.9 | AF7: 22 | AG7: 2026-09-04 16:30 | AH7: Synthetic demonstration charge
A8: OPD-CHG-0004 | B8: OP-202600004 | C8: CSN-OPD-780004 | D8: Outpatient | E8: Demo Regional Medical Center | F8: Emergency Department | G8: 2026-09-05 | H8: ED-LEVEL-4 | I8: Emergency Department Visit Level 4 | J8: 0450 | K8: 99284 | M8: 1 | N8: 2350 | O8: =M8*N8 -> 2350 | P8: 1072.31 | Q8: =P8*20% -> 214.462 | R8: =O8-P8 -> 1277.69 | S8: Demo PPO | T8: Gold PPO | V8: Eleanor Brooks, MD | W8: Assigned Department Provider | X8: ED | Y8: Encounter close | Z8: Posted | AA8: Matched | AB8: Passed | AD8: Documentation | AE8: R06.02 | AF8: 22 | AG8: 2026-09-05 16:30 | AH8: Synthetic demonstration charge
A9: OPD-CHG-0005 | B9: OP-202600005 | C9: CSN-OPD-780005 | D9: Outpatient | E9: Demo Regional Medical Center | F9: Emergency Department | G9: 2026-09-06 | H9: ED-LEVEL-5 | I9: Emergency Department Visit Level 5 | J9: 0450 | K9: 99285 | M9: 1 | N9: 4300 | O9: =M9*N9 -> 4300 | P9: 2095.86 | Q9: =P9*20% -> 419.172 | R9: =O9-P9 -> 2204.14 | S9: Demo PPO | T9: Gold PPO | V9: Eleanor Brooks, MD | W9: Assigned Department Provider | X9: ED | Y9: Encounter close | Z9: Posted | AA9: Matched | AB9: Passed | AD9: Documentation | AE9: R07.9 | AF9: 22 | AG9: 2026-09-06 16:30 | AH9: Synthetic demonstration charge
A10: OPD-CHG-0006 | B10: OP-202600006 | C10: CSN-OPD-780006 | D10: Outpatient | E10: Demo Regional Medical Center | F10: Hospital Clinic | G10: 2026-09-07 | H10: CLINIC-L2 | I10: Hospital Outpatient Clinic Visit Level 2 | J10: 0510 | K10: 99212 | M10: 1 | N10: 215 | O10: =M10*N10 -> 215 | P10: 112.11 | Q10: =P10*20% -> 22.422 | R10: =O10-P10 -> 102.89 | S10: Demo PPO | T10: Gold PPO | V10: Eleanor Brooks, MD | W10: Assigned Department Provider | X10: Ambulatory | Y10: Visit close | Z10: Posted | AA10: Matched | AB10: Passed | AD10: E/M documentation | AE10: I10 | AF10: 22 | AG10: 2026-09-07 16:30 | AH10: Synthetic demonstration charge
A11: OPD-CHG-0007 | B11: OP-202600007 | C11: CSN-OPD-780007 | D11: Outpatient | E11: Demo Regional Medical Center | F11: Hospital Clinic | G11: 2026-09-08 | H11: CLINIC-L3 | I11: Hospital Outpatient Clinic Visit Level 3 | J11: 0510 | K11: 99213 | M11: 1 | N11: 315 | O11: =M11*N11 -> 315 | P11: 187.9 | Q11: =P11*20% -> 37.58 | R11: =O11-P11 -> 127.1 | S11: Demo PPO | T11: Gold PPO | V11: Eleanor Brooks, MD | W11: Assigned Department Provider | X11: Ambulatory | Y11: Visit close | Z11: Posted | AA11: Matched | AB11: Passed | AD11: E/M documentation | AE11: E11.9 | AF11: 22 | AG11: 2026-09-08 16:30 | AH11: Synthetic demonstration charge
A12: OPD-CHG-0008 | B12: OP-202600008 | C12: CSN-OPD-780008 | D12: Outpatient | E12: Demo Regional Medical Center | F12: Hospital Clinic | G12: 2026-09-09 | H12: CLINIC-L4 | I12: Hospital Outpatient Clinic Visit Level 4 | J12: 0510 | K12: 99214 | M12: 1 | N12: 410 | O12: =M12*N12 -> 410 | P12: 200.5 | Q12: =P12*20% -> 40.1 | R12: =O12-P12 -> 209.5 | S12: Demo PPO | T12: Gold PPO | V12: Eleanor Brooks, MD | W12: Assigned Department Provider | X12: Ambulatory | Y12: Visit close | Z12: Posted | AA12: Matched | AB12: Passed | AD12: E/M documentation | AE12: J45.40 | AF12: 22 | AG12: 2026-09-09 16:30 | AH12: Synthetic demonstration charge
A13: OPD-CHG-0009 | B13: OP-202600009 | C13: CSN-OPD-780009 | D13: Outpatient | E13: Demo Regional Medical Center | F13: Hospital Clinic | G13: 2026-09-10 | H13: CLINIC-L5 | I13: Hospital Outpatient Clinic Visit Level 5 | J13: 0510 | K13: 99215 | M13: 1 | N13: 570 | O13: =M13*N13 -> 570 | P13: 277.06 | Q13: =P13*20% -> 55.412 | R13: =O13-P13 -> 292.94 | S13: Demo PPO | T13: Gold PPO | V13: Eleanor Brooks, MD | W13: Assigned Department Provider | X13: Ambulatory | Y13: Visit close | Z13: Posted | AA13: Matched | AB13: Passed | AD13: E/M documentation | AE13: I50.9 | AF13: 22 | AG13: 2026-09-10 16:30 | AH13: Synthetic demonstration charge
A14: OPD-CHG-0010 | B14: OP-202600010 | C14: CSN-OPD-780010 | D14: Outpatient | E14: Demo Regional Medical Center | F14: Radiology | G14: 2026-09-11 | H14: XR-CHEST-2V | I14: Chest X-ray, 2 Views | J14: 0320 | K14: 71046 | M14: 1 | N14: 185 | O14: =M14*N14 -> 185 | P14: 81.64 | Q14: =P14*20% -> 16.328 | R14: =O14-P14 -> 103.36 | S14: Demo PPO | T14: Gold PPO | V14: Eleanor Brooks, MD | W14: Assigned Department Provider | X14: RIS/PACS | Y14: Exam completed | Z14: Posted | AA14: Matched | AB14: Passed | AD14: Diagnosis/LCD | AE14: R05.9 | AF14: 22 | AG14: 2026-09-11 16:30 | AH14: Synthetic demonstration charge
A15: OPD-CHG-0011 | B15: OP-202600011 | C15: CSN-OPD-780011 | D15: Outpatient | E15: Demo Regional Medical Center | F15: Radiology | G15: 2026-09-12 | H15: CT-HEAD-WO | I15: CT Head Without Contrast | J15: 0350 | K15: 70450 | M15: 1 | N15: 1900 | O15: =M15*N15 -> 1900 | P15: 1157.73 | Q15: =P15*20% -> 231.546 | R15: =O15-P15 -> 742.27 | S15: Demo PPO | T15: Gold PPO | U15: AUTH-700011 | V15: Eleanor Brooks, MD | W15: Assigned Department Provider | X15: RIS/PACS | Y15: Exam completed | Z15: Posted | AA15: Matched | AB15: Passed | AD15: Prior authorization | AE15: R51.9 | AF15: 22 | AG15: 2026-09-12 16:30 | AH15: Synthetic demonstration charge
A16: OPD-CHG-0012 | B16: OP-202600012 | C16: CSN-OPD-780012 | D16: Outpatient | E16: Demo Regional Medical Center | F16: Radiology | G16: 2026-09-13 | H16: CT-CHEST-W | I16: CT Chest With Contrast | J16: 0350 | K16: 71260 | M16: 1 | N16: 2500 | O16: =M16*N16 -> 2500 | P16: 1221.71 | Q16: =P16*20% -> 244.342 | R16: =O16-P16 -> 1278.29 | S16: Demo PPO | T16: Gold PPO | U16: AUTH-700012 | V16: Eleanor Brooks, MD | W16: Assigned Department Provider | X16: RIS/PACS | Y16: Exam completed | Z16: Posted | AA16: Matched | AB16: Passed | AD16: Prior authorization | AE16: R91.1 | AF16: 22 | AG16: 2026-09-13 16:30 | AH16: Synthetic demonstration charge
A17: OPD-CHG-0013 | B17: OP-202600013 | C17: CSN-OPD-780013 | D17: Outpatient | E17: Demo Regional Medical Center | F17: Radiology | G17: 2026-09-14 | H17: MRI-BRAIN-WO | I17: MRI Brain Without Contrast | J17: 0610 | K17: 70551 | M17: 1 | N17: 3250 | O17: =M17*N17 -> 3250 | P17: 2247.78 | Q17: =P17*20% -> 449.556 | R17: =O17-P17 -> 1002.22 | S17: Demo PPO | T17: Gold PPO | U17: AUTH-700013 | V17: Eleanor Brooks, MD | W17: Assigned Department Provider | X17: RIS/PACS | Y17: Exam completed | Z17: Posted | AA17: Matched | AB17: Passed | AD17: Prior authorization | AE17: G43.909 | AF17: 22 | AG17: 2026-09-14 16:30 | AH17: Synthetic demonstration charge
A18: OPD-CHG-0014 | B18: OP-202600014 | C18: CSN-OPD-780014 | D18: Outpatient | E18: Demo Regional Medical Center | F18: Radiology | G18: 2026-09-15 | H18: US-ABD-COMP | I18: Ultrasound Abdomen Complete | J18: 0402 | K18: 76700 | M18: 1 | N18: 875 | O18: =M18*N18 -> 875 | P18: 593.15 | Q18: =P18*20% -> 118.63 | R18: =O18-P18 -> 281.85 | S18: Demo PPO | T18: Gold PPO | V18: Eleanor Brooks, MD | W18: Assigned Department Provider | X18: RIS/PACS | Y18: Exam completed | Z18: Posted | AA18: Matched | AB18: Passed | AD18: Diagnosis/LCD | AE18: R10.84 | AF18: 22 | AG18: 2026-09-15 16:30 | AH18: Synthetic demonstration charge
A19: OPD-CHG-0015 | B19: OP-202600015 | C19: CSN-OPD-780015 | D19: Outpatient | E19: Demo Regional Medical Center | F19: Mammography | G19: 2026-09-16 | H19: MAMMO-SCREEN | I19: Screening Mammography, Bilateral | J19: 0403 | K19: 77067 | M19: 1 | N19: 535 | O19: =M19*N19 -> 535 | P19: 236.07 | Q19: =P19*20% -> 47.214 | R19: =O19-P19 -> 298.93 | S19: Demo PPO | T19: Gold PPO | V19: Eleanor Brooks, MD | W19: Assigned Department Provider | X19: RIS/PACS | Y19: Exam completed | Z19: Posted | AA19: Matched | AB19: Passed | AD19: Preventive rule | AE19: Z12.31 | AF19: 22 | AG19: 2026-09-16 16:30 | AH19: Synthetic demonstration charge
A20: OPD-CHG-0016 | B20: OP-202600016 | C20: CSN-OPD-780016 | D20: Outpatient | E20: Demo Regional Medical Center | F20: Laboratory | G20: 2026-09-17 | H20: CBC-OP | I20: Complete Blood Count with Differential | J20: 0300 | K20: 85025 | M20: 1 | N20: 155 | O20: =M20*N20 -> 155 | P20: 76.17 | Q20: =P20*20% -> 15.234 | R20: =O20-P20 -> 78.83 | S20: Demo PPO | T20: Gold PPO | V20: Eleanor Brooks, MD | W20: Assigned Department Provider | X20: LIS | Y20: Final result | Z20: Posted | AA20: Matched | AB20: Passed | AD20: Diagnosis/LCD | AE20: R53.83 | AF20: 22 | AG20: 2026-09-17 16:30 | AH20: Synthetic demonstration charge
A21: OPD-CHG-0017 | B21: OP-202600017 | C21: CSN-OPD-780017 | D21: Outpatient | E21: Demo Regional Medical Center | F21: Laboratory | G21: 2026-09-18 | H21: BMP-OP | I21: Basic Metabolic Panel | J21: 0301 | K21: 80048 | M21: 1 | N21: 185 | O21: =M21*N21 -> 185 | P21: 114.83 | Q21: =P21*20% -> 22.966 | R21: =O21-P21 -> 70.17 | S21: Demo PPO | T21: Gold PPO | V21: Eleanor Brooks, MD | W21: Assigned Department Provider | X21: LIS | Y21: Final result | Z21: Posted | AA21: Matched | AB21: Passed | AD21: Diagnosis/LCD | AE21: I10 | AF21: 22 | AG21: 2026-09-18 16:30 | AH21: Synthetic demonstration charge
A22: OPD-CHG-0018 | B22: OP-202600018 | C22: CSN-OPD-780018 | D22: Outpatient | E22: Demo Regional Medical Center | F22: Laboratory | G22: 2026-09-19 | H22: A1C-OP | I22: Hemoglobin A1c | J22: 0301 | K22: 83036 | M22: 1 | N22: 110 | O22: =M22*N22 -> 110 | P22: 53.27 | Q22: =P22*20% -> 10.654 | R22: =O22-P22 -> 56.73 | S22: Demo PPO | T22: Gold PPO | V22: Eleanor Brooks, MD | W22: Assigned Department Provider | X22: LIS | Y22: Final result | Z22: Posted | AA22: Matched | AB22: Passed | AD22: Diagnosis/LCD | AE22: E11.9 | AF22: 22 | AG22: 2026-09-19 16:30 | AH22: Synthetic demonstration charge
A23: OPD-CHG-0019 | B23: OP-202600019 | C23: CSN-OPD-780019 | D23: Outpatient | E23: Demo Regional Medical Center | F23: Laboratory | G23: 2026-09-20 | H23: LIPID-OP | I23: Lipid Panel | J23: 0301 | K23: 80061 | M23: 1 | N23: 215 | O23: =M23*N23 -> 215 | P23: 98.83 | Q23: =P23*20% -> 19.766 | R23: =O23-P23 -> 116.17 | S23: Demo PPO | T23: Gold PPO | V23: Eleanor Brooks, MD | W23: Assigned Department Provider | X23: LIS | Y23: Final result | Z23: Posted | AA23: Matched | AB23: Passed | AD23: Diagnosis/LCD | AE23: E78.5 | AF23: 22 | AG23: 2026-09-20 16:30 | AH23: Synthetic demonstration charge
A24: OPD-CHG-0020 | B24: OP-202600020 | C24: CSN-OPD-780020 | D24: Outpatient | E24: Demo Regional Medical Center | F24: Cardiology | G24: 2026-09-21 | H24: ECHO-COMP | I24: Complete Transthoracic Echocardiogram | J24: 0483 | K24: 93306 | M24: 1 | N24: 1550 | O24: =M24*N24 -> 1550 | P24: 1086.01 | Q24: =P24*20% -> 217.202 | R24: =O24-P24 -> 463.99 | S24: Demo PPO | T24: Gold PPO | U24: AUTH-700020 | V24: Eleanor Brooks, MD | W24: Assigned Department Provider | X24: Cardiology | Y24: Test completed | Z24: Posted | AA24: Matched | AB24: Passed | AD24: Prior authorization | AE24: R01.1 | AF24: 22 | AG24: 2026-09-21 16:30 | AH24: Synthetic demonstration charge
A25: OPD-CHG-0021 | B25: OP-202600021 | C25: CSN-OPD-780021 | D25: Outpatient | E25: Demo Regional Medical Center | F25: Cardiology | G25: 2026-09-22 | H25: STRESS-TEST | I25: Cardiovascular Stress Test | J25: 0482 | K25: 93017 | M25: 1 | N25: 1150 | O25: =M25*N25 -> 1150 | P25: 680.01 | Q25: =P25*20% -> 136.002 | R25: =O25-P25 -> 469.99 | S25: Demo PPO | T25: Gold PPO | U25: AUTH-700021 | V25: Eleanor Brooks, MD | W25: Assigned Department Provider | X25: Cardiology | Y25: Test completed | Z25: Posted | AA25: Matched | AB25: Passed | AD25: Prior authorization | AE25: R07.9 | AF25: 22 | AG25: 2026-09-22 16:30 | AH25: Synthetic demonstration charge
A26: OPD-CHG-0022 | B26: OP-202600022 | C26: CSN-OPD-780022 | D26: Outpatient | E26: Demo Regional Medical Center | F26: Endoscopy | G26: 2026-09-23 | H26: COLON-DX | I26: Diagnostic Colonoscopy | J26: 0750 | K26: 45378 | M26: 1 | N26: 3900 | O26: =M26*N26 -> 3900 | P26: 2191.03 | Q26: =P26*20% -> 438.206 | R26: =O26-P26 -> 1708.97 | S26: Demo PPO | T26: Gold PPO | U26: AUTH-700022 | V26: Eleanor Brooks, MD | W26: Assigned Department Provider | X26: Endoscopy | Y26: Procedure completed | Z26: Posted | AA26: Matched | AB26: Passed | AD26: Prior authorization | AE26: Z12.11 | AF26: 22 | AG26: 2026-09-23 16:30 | AH26: Synthetic demonstration charge
A27: OPD-CHG-0023 | B27: OP-202600023 | C27: CSN-OPD-780023 | D27: Outpatient | E27: Demo Regional Medical Center | F27: Endoscopy | G27: 2026-09-24 | H27: EGD-DX | I27: Diagnostic Upper GI Endoscopy | J27: 0750 | K27: 43235 | M27: 1 | N27: 3300 | O27: =M27*N27 -> 3300 | P27: 2162.77 | Q27: =P27*20% -> 432.554 | R27: =O27-P27 -> 1137.23 | S27: Demo PPO | T27: Gold PPO | U27: AUTH-700023 | V27: Eleanor Brooks, MD | W27: Assigned Department Provider | X27: Endoscopy | Y27: Procedure completed | Z27: Posted | AA27: Matched | AB27: Review | AC27: WQ-END-04 | AD27: Prior authorization | AE27: K21.9 | AF27: 22 | AG27: 2026-09-24 16:30 | AH27: Synthetic demonstration charge
A28: OPD-CHG-0024 | B28: OP-202600024 | C28: CSN-OPD-780024 | D28: Outpatient | E28: Demo Regional Medical Center | F28: Physical Therapy | G28: 2026-09-25 | H28: PT-EVAL-OP | I28: Outpatient Physical Therapy Evaluation | J28: 0420 | K28: 97162 | M28: 1 | N28: 860 | O28: =M28*N28 -> 860 | P28: 569.53 | Q28: =P28*20% -> 113.906 | R28: =O28-P28 -> 290.47 | S28: Demo PPO | T28: Gold PPO | U28: AUTH-700024 | V28: Eleanor Brooks, MD | W28: Assigned Department Provider | X28: Therapy | Y28: Note signed | Z28: Posted | AA28: Matched | AB28: Passed | AD28: Plan benefits | AE28: M54.50 | AF28: 22 | AG28: 2026-09-25 16:30 | AH28: Synthetic demonstration charge
A29: OPD-CHG-0025 | B29: OP-202600025 | C29: CSN-OPD-780025 | D29: Outpatient | E29: Demo Regional Medical Center | F29: Physical Therapy | G29: 2026-09-01 | H29: PT-THEREX-OP | I29: Therapeutic Exercise, 15 Minutes | J29: 0420 | K29: 97110 | M29: 3 | N29: 305 | O29: =M29*N29 -> 915 | P29: 410.19 | Q29: =P29*20% -> 82.038 | R29: =O29-P29 -> 504.81 | S29: Demo PPO | T29: Gold PPO | V29: Eleanor Brooks, MD | W29: Assigned Department Provider | X29: Therapy | Y29: Note signed | Z29: Posted | AA29: Matched | AB29: Passed | AD29: Timed units | AE29: M54.50 | AF29: 22 | AG29: 2026-09-01 16:30 | AH29: Synthetic demonstration charge
A30: OPD-CHG-0026 | B30: OP-202600026 | C30: CSN-OPD-780026 | D30: Outpatient | E30: Demo Regional Medical Center | F30: Infusion | G30: 2026-09-02 | H30: INFUSION-1H | I30: Therapeutic Infusion, Initial Hour | J30: 0260 | K30: 96365 | M30: 1 | N30: 780 | O30: =M30*N30 -> 780 | P30: 481.8 | Q30: =P30*20% -> 96.36 | R30: =O30-P30 -> 298.2 | S30: Demo PPO | T30: Gold PPO | U30: AUTH-700026 | V30: Eleanor Brooks, MD | W30: Assigned Department Provider | X30: Infusion | Y30: Administration completed | Z30: Posted | AA30: Matched | AB30: Passed | AD30: Drug policy | AE30: Z51.11 | AF30: 22 | AG30: 2026-09-02 16:30 | AH30: Synthetic demonstration charge
A31: OPD-CHG-0027 | B31: OP-202600027 | C31: CSN-OPD-780027 | D31: Outpatient | E31: Demo Regional Medical Center | F31: Chemotherapy | G31: 2026-09-03 | H31: CHEMO-1H | I31: Chemotherapy Infusion, Initial Hour | J31: 0335 | K31: 96413 | M31: 1 | N31: 1850 | O31: =M31*N31 -> 1850 | P31: 973.64 | Q31: =P31*20% -> 194.728 | R31: =O31-P31 -> 876.36 | S31: Demo PPO | T31: Gold PPO | U31: AUTH-700027 | V31: Eleanor Brooks, MD | W31: Assigned Department Provider | X31: Infusion | Y31: Administration completed | Z31: Posted | AA31: Matched | AB31: Passed | AD31: Drug policy | AE31: C50.919 | AF31: 22 | AG31: 2026-09-03 16:30 | AH31: Synthetic demonstration charge
A32: OPD-CHG-0028 | B32: OP-202600028 | C32: CSN-OPD-780028 | D32: Outpatient | E32: Demo Regional Medical Center | F32: Behavioral Health | G32: 2026-09-04 | H32: BH-INDIVIDUAL | I32: Outpatient Psychotherapy, 45 Minutes | J32: 0914 | K32: 90834 | M32: 1 | N32: 285 | O32: =M32*N32 -> 285 | P32: 154.85 | Q32: =P32*20% -> 30.97 | R32: =O32-P32 -> 130.15 | S32: Demo PPO | T32: Gold PPO | V32: Eleanor Brooks, MD | W32: Assigned Department Provider | X32: Behavioral Health | Y32: Note signed | Z32: Posted | AA32: Matched | AB32: Passed | AD32: Benefits | AE32: F41.1 | AF32: 22 | AG32: 2026-09-04 16:30 | AH32: Synthetic demonstration charge
A33: OPD-CHG-0029 | B33: OP-202600029 | C33: CSN-OPD-780029 | D33: Outpatient | E33: Demo Regional Medical Center | F33: Emergency Department | G33: 2026-09-05 | H33: ED-LEVEL-1 | I33: Emergency Department Visit Level 1 | J33: 0450 | K33: 99281 | M33: 1 | N33: 360 | O33: =M33*N33 -> 360 | P33: 244.49 | Q33: =P33*20% -> 48.898 | R33: =O33-P33 -> 115.51 | S33: Demo PPO | T33: Gold PPO | V33: Eleanor Brooks, MD | W33: Assigned Department Provider | X33: ED | Y33: Encounter close | Z33: Hold | AA33: Exception | AB33: Review | AC33: WQ-EME-02 | AD33: Documentation | AE33: R50.9 | AF33: 22 | AG33: 2026-09-05 16:30 | AH33: Synthetic demonstration charge
A34: OPD-CHG-0030 | B34: OP-202600030 | C34: CSN-OPD-780030 | D34: Outpatient | E34: Demo Regional Medical Center | F34: Emergency Department | G34: 2026-09-06 | H34: ED-LEVEL-2 | I34: Emergency Department Visit Level 2 | J34: 0450 | K34: 99282 | M34: 1 | N34: 670 | O34: =M34*N34 -> 670 | P34: 292.29 | Q34: =P34*20% -> 58.458 | R34: =O34-P34 -> 377.71 | S34: Demo PPO | T34: Gold PPO | V34: Eleanor Brooks, MD | W34: Assigned Department Provider | X34: ED | Y34: Encounter close | Z34: Posted | AA34: Matched | AB34: Passed | AD34: Documentation | AE34: R51.9 | AF34: 22 | AG34: 2026-09-06 16:30 | AH34: Synthetic demonstration charge
A35: OPD-CHG-0031 | B35: OP-202600031 | C35: CSN-OPD-780031 | D35: Outpatient | E35: Demo Regional Medical Center | F35: Emergency Department | G35: 2026-09-07 | H35: ED-LEVEL-3 | I35: Emergency Department Visit Level 3 | J35: 0450 | K35: 99283 | M35: 1 | N35: 1280 | O35: =M35*N35 -> 1280 | P35: 788.53 | Q35: =P35*20% -> 157.706 | R35: =O35-P35 -> 491.47 | S35: Demo PPO | T35: Gold PPO | V35: Eleanor Brooks, MD | W35: Assigned Department Provider | X35: ED | Y35: Encounter close | Z35: Posted | AA35: Matched | AB35: Passed | AD35: Documentation | AE35: R10.9 | AF35: 22 | AG35: 2026-09-07 16:30 | AH35: Synthetic demonstration charge
A36: OPD-CHG-0032 | B36: OP-202600032 | C36: CSN-OPD-780032 | D36: Outpatient | E36: Demo Regional Medical Center | F36: Emergency Department | G36: 2026-09-08 | H36: ED-LEVEL-4 | I36: Emergency Department Visit Level 4 | J36: 0450 | K36: 99284 | M36: 1 | N36: 2350 | O36: =M36*N36 -> 2350 | P36: 1442.56 | Q36: =P36*20% -> 288.512 | R36: =O36-P36 -> 907.44 | S36: Demo PPO | T36: Gold PPO | V36: Eleanor Brooks, MD | W36: Assigned Department Provider | X36: ED | Y36: Encounter close | Z36: Posted | AA36: Matched | AB36: Passed | AD36: Documentation | AE36: R06.02 | AF36: 22 | AG36: 2026-09-08 16:30 | AH36: Synthetic demonstration charge
A37: OPD-CHG-0033 | B37: OP-202600033 | C37: CSN-OPD-780033 | D37: Outpatient | E37: Demo Regional Medical Center | F37: Emergency Department | G37: 2026-09-09 | H37: ED-LEVEL-5 | I37: Emergency Department Visit Level 5 | J37: 0450 | K37: 99285 | M37: 1 | N37: 4300 | O37: =M37*N37 -> 4300 | P37: 1884.19 | Q37: =P37*20% -> 376.838 | R37: =O37-P37 -> 2415.81 | S37: Demo PPO | T37: Gold PPO | V37: Eleanor Brooks, MD | W37: Assigned Department Provider | X37: ED | Y37: Encounter close | Z37: Posted | AA37: Matched | AB37: Passed | AD37: Documentation | AE37: R07.9 | AF37: 22 | AG37: 2026-09-09 16:30 | AH37: Synthetic demonstration charge
A38: OPD-CHG-0034 | B38: OP-202600034 | C38: CSN-OPD-780034 | D38: Outpatient | E38: Demo Regional Medical Center | F38: Hospital Clinic | G38: 2026-09-10 | H38: CLINIC-L2 | I38: Hospital Outpatient Clinic Visit Level 2 | J38: 0510 | K38: 99212 | M38: 1 | N38: 215 | O38: =M38*N38 -> 215 | P38: 137.27 | Q38: =P38*20% -> 27.454 | R38: =O38-P38 -> 77.73 | S38: Demo PPO | T38: Gold PPO | V38: Eleanor Brooks, MD | W38: Assigned Department Provider | X38: Ambulatory | Y38: Visit close | Z38: Posted | AA38: Matched | AB38: Passed | AD38: E/M documentation | AE38: I10 | AF38: 22 | AG38: 2026-09-10 16:30 | AH38: Synthetic demonstration charge
A39: OPD-CHG-0035 | B39: OP-202600035 | C39: CSN-OPD-780035 | D39: Outpatient | E39: Demo Regional Medical Center | F39: Hospital Clinic | G39: 2026-09-11 | H39: CLINIC-L3 | I39: Hospital Outpatient Clinic Visit Level 3 | J39: 0510 | K39: 99213 | M39: 1 | N39: 315 | O39: =M39*N39 -> 315 | P39: 207.96 | Q39: =P39*20% -> 41.592 | R39: =O39-P39 -> 107.04 | S39: Demo PPO | T39: Gold PPO | V39: Eleanor Brooks, MD | W39: Assigned Department Provider | X39: Ambulatory | Y39: Visit close | Z39: Posted | AA39: Matched | AB39: Passed | AD39: E/M documentation | AE39: E11.9 | AF39: 22 | AG39: 2026-09-11 16:30 | AH39: Synthetic demonstration charge
A40: OPD-CHG-0036 | B40: OP-202600036 | C40: CSN-OPD-780036 | D40: Outpatient | E40: Demo Regional Medical Center | F40: Hospital Clinic | G40: 2026-09-12 | H40: CLINIC-L4 | I40: Hospital Outpatient Clinic Visit Level 4 | J40: 0510 | K40: 99214 | M40: 1 | N40: 410 | O40: =M40*N40 -> 410 | P40: 185.64 | Q40: =P40*20% -> 37.128 | R40: =O40-P40 -> 224.36 | S40: Demo PPO | T40: Gold PPO | V40: Eleanor Brooks, MD | W40: Assigned Department Provider | X40: Ambulatory | Y40: Visit close | Z40: Posted | AA40: Matched | AB40: Passed | AD40: E/M documentation | AE40: J45.40 | AF40: 22 | AG40: 2026-09-12 16:30 | AH40: Synthetic demonstration charge
A41: OPD-CHG-0037 | B41: OP-202600037 | C41: CSN-OPD-780037 | D41: Outpatient | E41: Demo Regional Medical Center | F41: Hospital Clinic | G41: 2026-09-13 | H41: CLINIC-L5 | I41: Hospital Outpatient Clinic Visit Level 5 | J41: 0510 | K41: 99215 | M41: 1 | N41: 570 | O41: =M41*N41 -> 570 | P41: 272.16 | Q41: =P41*20% -> 54.432 | R41: =O41-P41 -> 297.84 | S41: Demo PPO | T41: Gold PPO | V41: Eleanor Brooks, MD | W41: Assigned Department Provider | X41: Ambulatory | Y41: Visit close | Z41: Posted | AA41: Matched | AB41: Passed | AD41: E/M documentation | AE41: I50.9 | AF41: 22 | AG41: 2026-09-13 16:30 | AH41: Synthetic demonstration charge
...

Sheet Dashboard
A1: bsolutely original add multiple charges
A2: Executive view of CDM completeness, financial exposure, review status, and charge reconciliation.
A4: Active CDM Records | E4: Gross Charge Value | I4: Expected Allowed
A5: =COUNTIF('CDM Master'!AD:AD,"Active") -> 15 | E5: =SUM('IPD Encounter'!R5:R15) -> 76340 | I5: =SUM('IPD Encounter'!S5:S15) -> 32790
A8: Patient Responsibility | E8: Open Governance | I8: Active Claim Edits
A9: =SUM('IPD Encounter'!T5:T15) -> 6558 | E9: =COUNTIF(Governance!O:O,"<>Closed")-1 -> 1048574 | I9: =COUNTIF('Claim Edits'!L:L,"Active") -> 6
A13: Department | B13: Gross Price Total
A14: Operating Room | B14: =SUMIF('CDM Master'!E:E,A14,'CDM Master'!O:O) -> 11250
A15: Pharmacy | B15: =SUMIF('CDM Master'!E:E,A15,'CDM Master'!O:O) -> 500
A16: Radiology | B16: =SUMIF('CDM Master'!E:E,A16,'CDM Master'!O:O) -> 580
A17: Laboratory | B17: =SUMIF('CDM Master'!E:E,A17,'CDM Master'!O:O) -> 150
A18: Physical Therapy | B18: =SUMIF('CDM Master'!E:E,A18,'CDM Master'!O:O) -> 1000
A19: Surgical Supplies | B19: =SUMIF('CDM Master'!E:E,A19,'CDM Master'!O:O) -> 24000

Sheet CDM Master
A1: Charge Description Master (CDM)
A2: Enterprise master of billable facility items/services, coding, pricing, ownership, and lifecycle controls.
A4: Facility ID | B4: Location | C4: Service Area | D4: Department ID | E4: Department | F4: EAP/CDM Charge Code | G4: Charge Description | H4: Patient-Friendly Description | I4: Charge Type | J4: Revenue Code | K4: CPT/HCPCS | L4: Modifier | M4: NDC / Device ID | N4: Unit Basis | O4: Gross Unit Charge ($) | P4: Cost ($) | Q4: Markup % | R4: HCPCS Units | S4: Bill Area | T4: HB/PB | U4: Charge Trigger | V4: Source System | W4: Orderable/Procedure ID | X4: Price Tier | Y4: Taxable | Z4: Prior Auth Flag | AA4: Medical Necessity Rule | AB4: Effective Date | AC4: Termination Date | AD4: Status | AE4: Owner | AF4: Last Review Date | AG4: Next Review Date | AH4: Review Flag | AI4: Compliance Notes
A5: MAIN | B5: Main Campus | C5: HB | D5: D100 | E5: Inpatient Nursing | F5: RM-SP-001 | G5: Semiprivate Medical/Surgical Room | H5: Semiprivate hospital room | I5: Accommodation | J5: 0120 | N5: Per day | O5: 3500 | P5: 1200 | Q5: =IFERROR((O5-P5)/P5,0) -> 1.9166667 | R5: 1 | S5: HB-NURS | T5: HB | U5: ADT discharge | V5: ADT | W5: BED-SP | X5: Standard | Y5: No | Z5: No | AA5: N/A | AB5: 2026-01-01 | AD5: Active | AE5: Director Revenue Integrity | AF5: 2026-07-15 | AG5: =EDATE(AF5,12) -> 46583 | AH5: =IF(AD5<>"Active","Inactive",IF(AG5<TODAY(),"Overdue",IF(AG5<=TODAY()+60,"Due Soon","Current"))) -> Current
A6: MAIN | B6: Main Campus | C6: HB | D6: D105 | E6: Intensive Care | F6: ICU-DAY-001 | G6: Intensive Care Unit Room | H6: ICU room and monitoring | I6: Accommodation | J6: 0200 | N6: Per day | O6: 8000 | P6: 3500 | Q6: =IFERROR((O6-P6)/P6,0) -> 1.2857143 | R6: 1 | S6: HB-ICU | T6: HB | U6: ADT bed event | V6: ADT | W6: BED-ICU | X6: Standard | Y6: No | Z6: No | AA6: N/A | AB6: 2026-01-01 | AD6: Active | AE6: Director Revenue Integrity | AF6: 2026-07-15 | AG6: =EDATE(AF6,12) -> 46583 | AH6: =IF(AD6<>"Active","Inactive",IF(AG6<TODAY(),"Overdue",IF(AG6<=TODAY()+60,"Due Soon","Current"))) -> Current
A7: MAIN | B7: Main Campus | C7: HB | D7: D200 | E7: Operating Room | F7: OR-MAJOR-01 | G7: Major Operating Room, First Hour | H7: Operating room first hour | I7: Timed Service | J7: 0360 | N7: Per hour | O7: 10000 | P7: 4200 | Q7: =IFERROR((O7-P7)/P7,0) -> 1.3809524 | R7: 1 | S7: HB-OR | T7: HB | U7: Procedure end | V7: OpTime | W7: PROC-OR-MAJ | X7: Standard | Y7: No | Z7: Yes | AA7: Procedure-specific | AB7: 2026-01-01 | AD7: Active | AE7: OR Finance Manager | AF7: 2026-08-01 | AG7: =EDATE(AF7,12) -> 46600 | AH7: =IF(AD7<>"Active","Inactive",IF(AG7<TODAY(),"Overdue",IF(AG7<=TODAY()+60,"Due Soon","Current"))) -> Current
A8: MAIN | B8: Main Campus | C8: HB | D8: D200 | E8: Operating Room | F8: OR-ADD-15 | G8: Operating Room, Additional 15 Minutes | H8: Additional operating room time | I8: Timed Service | J8: 0360 | N8: Per 15 minutes | O8: 1250 | P8: 525 | Q8: =IFERROR((O8-P8)/P8,0) -> 1.3809524 | R8: 1 | S8: HB-OR | T8: HB | U8: Procedure end | V8: OpTime | W8: PROC-OR-15 | X8: Standard | Y8: No | Z8: Yes | AA8: Procedure-specific | AB8: 2026-01-01 | AD8: Active | AE8: OR Finance Manager | AF8: 2026-08-01 | AG8: =EDATE(AF8,12) -> 46600 | AH8: =IF(AD8<>"Active","Inactive",IF(AG8<TODAY(),"Overdue",IF(AG8<=TODAY()+60,"Due Soon","Current"))) -> Current
A9: MAIN | B9: Main Campus | C9: HB | D9: D210 | E9: Recovery Room | F9: RR-HR-001 | G9: Recovery Room, First Hour | H9: Recovery room first hour | I9: Timed Service | J9: 0710 | N9: Per hour | O9: 2000 | P9: 720 | Q9: =IFERROR((O9-P9)/P9,0) -> 1.7777778 | R9: 1 | S9: HB-PACU | T9: HB | U9: PACU discharge | V9: OpTime | W9: PROC-PACU | X9: Standard | Y9: No | Z9: No | AA9: N/A | AB9: 2026-01-01 | AD9: Active | AE9: OR Finance Manager | AF9: 2026-08-01 | AG9: =EDATE(AF9,12) -> 46600 | AH9: =IF(AD9<>"Active","Inactive",IF(AG9<TODAY(),"Overdue",IF(AG9<=TODAY()+60,"Due Soon","Current"))) -> Current
A10: MAIN | B10: Main Campus | C10: HB | D10: D220 | E10: Surgical Supplies | F10: IMP-KNEE-01 | G10: Cemented Knee Implant Package | H10: Knee implant package | I10: Implant | J10: 0278 | M10: DI-088590000001 | N10: Per implant | O10: 20000 | P10: 11500 | Q10: =IFERROR((O10-P10)/P10,0) -> 0.73913043 | R10: 1 | S10: HB-SUP | T10: HB | U10: Implant scan | V10: Inventory | W10: ITEM-KNEE-CEM | X10: Carve-Out | Y10: No | Z10: Yes | AA10: Contract rule | AB10: 2026-01-01 | AD10: Active | AE10: Supply Chain Finance | AF10: 2026-06-30 | AG10: =EDATE(AF10,12) -> 46568 | AH10: =IF(AD10<>"Active","Inactive",IF(AG10<TODAY(),"Overdue",IF(AG10<=TODAY()+60,"Due Soon","Current"))) -> Current
A11: MAIN | B11: Main Campus | C11: HB | D11: D220 | E11: Surgical Supplies | F11: SUP-KNEE-01 | G11: Knee Surgery Supply Pack | H11: Disposable knee surgery supplies | I11: Supply | J11: 0270 | N11: Per pack | O11: 4000 | P11: 1450 | Q11: =IFERROR((O11-P11)/P11,0) -> 1.7586207 | R11: 1 | S11: HB-SUP | T11: HB | U11: Supply issue | V11: Inventory | W11: ITEM-KNEE-PACK | X11: Standard | Y11: No | Z11: No | AA11: N/A | AB11: 2026-01-01 | AD11: Active | AE11: Supply Chain Finance | AF11: 2026-06-30 | AG11: =EDATE(AF11,12) -> 46568 | AH11: =IF(AD11<>"Active","Inactive",IF(AG11<TODAY(),"Overdue",IF(AG11<=TODAY()+60,"Due Soon","Current"))) -> Current
A12: MAIN | B12: Main Campus | C12: HB | D12: D300 | E12: Pharmacy | F12: PH-IV-ABX-01 | G12: Cefazolin 1 g Injection | H12: Cefazolin antibiotic injection | I12: Drug | J12: 0250 | K12: J0690 | M12: 00071-3069-23 | N12: Per 1 g | O12: 500 | P12: 42 | Q12: =IFERROR((O12-P12)/P12,0) -> 10.904762 | R12: 1 | S12: HB-PHAR | T12: HB | U12: Medication administration | V12: Willow/MAR | W12: MED-CEFAZ-1G | X12: Drug | Y12: No | Z12: No | AA12: Dose/frequency | AB12: 2026-01-01 | AD12: Active | AE12: Pharmacy Revenue Integrity | AF12: 2026-09-01 | AG12: =EDATE(AF12,12) -> 46631 | AH12: =IF(AD12<>"Active","Inactive",IF(AG12<TODAY(),"Overdue",IF(AG12<=TODAY()+60,"Due Soon","Current"))) -> Current
A13: MAIN | B13: Main Campus | C13: HB | D13: D400 | E13: Laboratory | F13: LAB-CBC-001 | G13: Complete Blood Count with Automated Differential | H13: Complete blood count test | I13: Lab | J13: 0300 | K13: 85025 | N13: Per test | O13: 150 | P13: 22 | Q13: =IFERROR((O13-P13)/P13,0) -> 5.8181818 | R13: 1 | S13: HB-LAB | T13: HB | U13: Final result | V13: LIS | W13: LAB-CBC | X13: Standard | Y13: No | Z13: No | AA13: Diagnosis/LCD | AB13: 2026-01-01 | AD13: Active | AE13: Lab Finance Manager | AF13: 2026-08-15 | AG13: =EDATE(AF13,12) -> 46614 | AH13: =IF(AD13<>"Active","Inactive",IF(AG13<TODAY(),"Overdue",IF(AG13<=TODAY()+60,"Due Soon","Current"))) -> Current
A14: MAIN | B14: Main Campus | C14: HB | D14: D500 | E14: Radiology | F14: RAD-KNEE-01 | G14: Knee X-ray, 1-2 Views | H14: Knee X-ray | I14: Imaging | J14: 0320 | K14: 73560 | N14: Per study | O14: 400 | P14: 60 | Q14: =IFERROR((O14-P14)/P14,0) -> 5.6666667 | R14: 1 | S14: HB-RAD | T14: HB | U14: Exam completed | V14: RIS/PACS | W14: IMG-KNEE-2V | X14: Standard | Y14: No | Z14: No | AA14: Diagnosis/LCD | AB14: 2026-01-01 | AD14: Active | AE14: Imaging Finance Manager | AF14: 2026-08-15 | AG14: =EDATE(AF14,12) -> 46614 | AH14: =IF(AD14<>"Active","Inactive",IF(AG14<TODAY(),"Overdue",IF(AG14<=TODAY()+60,"Due Soon","Current"))) -> Current
